Workbook
Name Audi: 브랜드!$H$2:$H$16
Name Audi_: 딜러사!$E$5:$E$6
Name AudiA3: 차종!$E$7:$E$10
Name AudiA4: 차종!$E$11:$E$17
Name AudiA5: 차종!$E$18:$E$27
Name AudiA6: 차종!$E$28:$E$38
Name AudiA7: 차종!$E$39:$E$44
Name AudiA8: 차종!$E$45:$E$50
Name Audie_tron: 차종!$E$107:$E$118
Name AudiQ2: 차종!$E$51:$E$52
Name AudiQ3: 차종!$E$53:$E$62
Name AudiQ4: 차종!$E$63:$E$70
Name AudiQ5: 차종!$E$71:$E$81
Name AudiQ6: 차종!$E$82:$E$85
Name AudiQ7: 차종!$E$86:$E$92
Name AudiQ8: 차종!$E$93:$E$106
Name AudiR8: 차종!$E$119
Name Benz: 브랜드!$H$21:$H$41
Name Benz_: 딜러사!$E$7:$E$14
Name BenzA_class: 차종!$E$124:$E$130
Name BenzC_class: 차종!$E$131:$E$157
Name BenzCLA: 차종!$E$158:$E$161
Name BenzCLE: 차종!$E$162:$E$167
Name BenzCLS: 차종!$E$168:$E$174
Name BenzE_class: 차종!$E$175:$E$205
Name BenzEQA: 차종!$E$292:$E$294
Name BenzEQB: 차종!$E$295:$E$296
Name BenzEQC: 차종!$E$297:$E$299
Name BenzEQE: 차종!$E$300:$E$305
Name BenzEQS: 차종!$E$306:$E$313
Name BenzG: 차종!$E$263:$E$267
Name BenzGLA: 차종!$E$206:$E$209
Name BenzGLB: 차종!$E$210:$E$213
Name BenzGLC: 차종!$E$214:$E$242
Name BenzGLE: 차종!$E$243:$E$257
Name BenzGLS: 차종!$E$258:$E$262
Name BenzGT: 차종!$E$268:$E$272
Name BenzS_class: 차종!$E$273:$E$291
Name BenzSL: 차종!$E$314:$E$317
Name BMW: 브랜드!$J$2:$J$19
Name BMW_: 딜러사!$E$27
Name BMW1_series: 차종!$E$327:$E$328
Name BMW2_series: 차종!$E$329:$E$336
Name BMW3_series: 차종!$E$337:$E$354
Name BMW4_series: 차종!$E$355:$E$361
Name BMW5_series: 차종!$E$362:$E$379
Name BMW6_series: 차종!$E$380:$E$387
Name BMW7_series: 차종!$E$388:$E$394
Name BMW8_series: 차종!$E$395:$E$399
Name BMWi: 차종!$E$400:$E$425
Name BMWM: 차종!$E$487:$E$532
Name BMWX1: 차종!$E$429:$E$434
Name BMWX2: 차종!$E$435:$E$442
Name BMWX3: 차종!$E$443:$E$456
Name BMWX4: 차종!$E$457:$E$462
Name BMWX5: 차종!$E$463:$E$473
Name BMWX6: 차종!$E$474:$E$477
Name BMWX7: 차종!$E$478:$E$486
Name BMWZ: 차종!$E$426:$E$428
Name BYD: 브랜드!$P$34

Sheet 25년 9월 운영기준
B2: 수입차 통합 견적
C4: - 운용리스, 금융리스, 할부 견적시트 구분
C5: - 조건비교 3개 가능
B7: 기본사항
C9: 1. 고잔가프로모션 해당견적 반영 / 대상차종 신형 Benz GLC, GLE, BMW 5, 7, X3, X5, X6, X7 / 해당 차종만 10,000~15,000Km 잔가반영
C10: 2. 추가수수료 0.5%
C11: 3. Audi A6 e-tron 반영
C13: * 23~24년 재고차량 견적 산출 가능 (단, 최대할인반영 필수, 미입력시 진행불가)
C14: * 전기차 보조금 딜러사 금액 확인 후 견적 산출
C15: * 신규차종 반영 완료 (견적 내 차종 없을 경우 담당자 문의)

Sheet 전기차보조금액(참고)
B2: 전기차 보조금 참고 자료
F3: 단위 : 만원
B4: 브랜드 | C4: 차량 | D4: 국비보조금 | E4: 리스/렌터 추가보조금 | F4: 합산
B5: 테슬라 | C5: Model 3 Long Range | D5: 202 | E5: 62 | F5: =SUM(D5:E5) -> 264
C6: Model 3 Performance | D6: 187 | E6: 58 | F6: =SUM(D6:E6) -> 245
C7: Model 3 RWD (2025) | D7: 186 | E7: 57 | F7: =SUM(D7:E7) -> 243
C8: New Model Y Long Range | D8: 207 | E8: 64 | F8: =SUM(D8:E8) -> 271
C9: New Model Y RWD | D9: 188 | E9: 58 | F9: =SUM(D9:E9) -> 246
B10: BMW | C10: i4 eDrive40 | D10: 189 | E10: 58 | F10: =SUM(D10:E10) -> 247
C11: i4 M50 | D11: 172 | E11: 53 | F11: =SUM(D11:E11) -> 225
C12: iX1 xDrive30 | D12: 154 | E12: 47 | F12: =SUM(D12:E12) -> 201
C13: i4 eDrive40 LCI | D13: 187 | E13: 58 | F13: =SUM(D13:E13) -> 245
C14: i4 M50 LCI | D14: 177 | E14: 54 | F14: =SUM(D14:E14) -> 231
C15: iX2 eDrive20 | D15: 167 | E15: 51 | F15: =SUM(D15:E15) -> 218
B16: MINI | C16: MINI Country SE ALL4 | D16: 158 | E16: 49 | F16: =SUM(D16:E16) -> 207
C17: MINI Country E | D17: 166 | E17: 51 | F17: =SUM(D17:E17) -> 217
C18: MINI Aceman SE | D18: 306 | E18: 94 | F18: =SUM(D18:E18) -> 400
C19: MINI JCW Aceman E | D19: 151 | E19: 46 | F19: =SUM(D19:E19) -> 197
C20: MINI JCW E | D20: 147 | E20: 45 | F20: =SUM(D20:E20) -> 192
C21: MINI Aceman E | D21: 306 | E21: 94 | F21: =SUM(D21:E21) -> 400
C22: MINI Cooper SE | D22: 303 | E22: 94 | F22: =SUM(D22:E22) -> 397
B23: Benz | C23: EQA250(Facelift) | D23: 190 | E23: 58 | F23: =SUM(D23:E23) -> 248
C24: EQB300 4MATIC(Facelift)(5인승) | D24: 154 | E24: 47 | F24: =SUM(D24:E24) -> 201
C25: EQB300 4MATIC(Facelift)(7인승) | D25: 154 | E25: 47 | F25: =SUM(D25:E25) -> 201
B26: 폭스바겐 | C26: 폭스바겐 ID.4 Pro | D26: 422 | E26: 130 | F26: =SUM(D26:E26) -> 552
B27: 아우디 | C27: 아우디 Q4 Sportback 45 e-tron | D27: 201 | E27: 62 | F27: =SUM(D27:E27) -> 263
C28: 아우디 Q4 45 e-tron | D28: 201 | E28: 62 | F28: =SUM(D28:E28) -> 263
C29: 아우디 Q6 e-tron Performance | D29: 220 | E29: 68 | F29: =SUM(D29:E29) -> 288
B30: 볼보 | C30: EX30 Single Moter ER | D30: 247 | E30: 76 | F30: =SUM(D30:E30) -> 323
B31: 폴스타 | C31: Polestar 4 Long Range Single Motor | D31: 181 | E31: 56 | F31: =SUM(D31:E31) -> 237
C32: Polestar 4 Long Range Dual Motor 22인치 | D32: 141 | E32: 43 | F32: =SUM(D32:E32) -> 184
C33: Polestar 4 Long Range Dual Motor 20, 21인치 | D33: 168 | E33: 52 | F33: =SUM(D33:E33) -> 220
B34: BYD | C34: BYD ATTO 3 | D34: 145 | E34: 45 | F34: =SUM(D34:E34) -> 190
B36: * 2025년 9월 3일 기준
B37: * 상기 내용은 보조금액변동 / 견적차종 보조금 비대상 차량 가능성 있으니 딜러사 확인 필 진행요청 (참고자료)

Sheet 전기자특약필수서류
B5: 특약 사항
B8: 20 년 월 일 체결된 리스 계약에 대한 특약 사항은 아래와 같습니다.
B11: [차량 인도 및 성능 관련] 리스 이용자는 자동차리스 약관 제 8조(자동차의 인수 및 등록) 및 제 9조(자동차의 인도지연 또는 하자)에도 불구하고 단차 및 도장불량 등의 사유가 있다 하더라도 차량제조사가 인정하지 않는 경우 차량인도의 거부 또는 교환이 불가함을 확약합니다. 또한 차량 제조사가 인정하지 않는 배터리, 전자적 장치 등에 대한 교체가 불가하며 이를 사유로 해당 계약에 대해 중도해지 할 수 없음을 확약합니다.
B13: [중도해지 관련] 본 리스 계약은 시의 전기차 보조금 지원금액이 리스 대상 차량가격에 반영되었으며, 해당 보조금이 적용된 차량가격에 대해 리스료가 산정 되었습니다. 이와 같이 보조금을 지원받은 경우 「대기환경보전법규」에 따라 2년간 의무 운행을 하여야 하며, 의무 운행 기간 미이행 시 아래 ‘사용기간별 지원금액 회수기준’에 따라 보조금에 대한 환수조치가 발생될 수 있습니다. 따라서 의무 운행 기간 도과 전 본 리스 계약을 중도해지 하는 경우 차량 매입/반환에 따른 해당 손해배상금 및 이와 별개로 보조금에 대한 환수금액 전액을 부담할 것을 확약합니다. (1) 차량 매입 시 : 자동차리스약관 제 23조(규정손해배상금)에 따라 규정손해배상금율에 따른 규정손해배상금 (2) 차량 반환 시 : 자동차리스약관 제 24조(중도해지손해배상금수수료)에 따라 중도해지요율에 따른 중도해지손해배상금
A17: ※ 리스이용자( 직접 기재 )와 연대보증인( 직접 기재 )은 본 특약 사항에 대해 (충분한 설명을 듣고 이해한 후) 본인 의사에 따라 본 계약을 체결하였음에 동의하며, 계약 내용을 성실히 이행할 것을 확약합니다.
D20: 20 년 월 일
F22: 리스 이용자 : | H22: (인)
F24: 연대 보증인 : | H24: (인)

Sheet 운용리스 견적출력
AW2: ='운용리스 입력'!D2 -> 2025_09_V1
C3: 운 용 리 스 견 적 서 | BQ3: =TODAY() -> 45904
BS4: 담당자 | BW4: ='운용리스 입력'!D25 -> 메리츠캐피탈
AX6: ='운용리스 입력'!D26 -> VIP 고객님 | BL6: 아래 견적서 제안 드립니다.
C7: ▣ 차량정보
C8: 차종 | P8: ='운용리스 입력'!D5 -> Audi | AC8: ='운용리스 입력'!D7 -> A6 e-tron Performance Advanced | BW8: ='운용리스 입력'!D9 -> 0
C9: 기본 가격 | P9: ='운용리스 입력'!D11 -> 65800000 | AP9: 옵션 가격 | BD9: ='운용리스 입력'!D12 -> 0
C10: 할인 가격 | P10: ='운용리스 입력'!D13 -> 0 | AP10: 최종 가격 | BD10: ='운용리스 입력'!D14 -> 65800000
C12: ▣ 등록비용
C13: ="등취득세 "&'운용리스 입력'!C16 -> 등취득세 포함 | P13: ='운용리스 입력'!D16 -> 4187270 | AP13: ="공채비용 "&'운용리스 입력'!C17 -> 공채비용 포함 | BD13: ='운용리스 입력'!F18 -> 0
C14: ="탁송료 "&'운용리스 입력'!C19 -> 탁송료 포함 | P14: ='운용리스 입력'!D19 -> 0 | AP14: ="부대비용 "&'운용리스 입력'!C20 -> 부대비용 포함 | BD14: ='운용리스 입력'!D20 -> 100000
C15: ="등록지역 : 금융사명 - "&'운용리스 입력'!E17&" / 고객명 - 등본지" -> 등록지역 : 금융사명 - 부산 / 고객명 - 등본지 | AP15: 등록비용 총합계 | BD15: ='운용리스 입력'!D21 -> 4287270
C17: ▣ 리스조건
C18: 구분 | R18: 조건 1 | AN18: 조건 2 | BJ18: 조건 3
C19: 취득원가 | R19: ='운용리스 입력'!D23 -> 70087270 | AN19: ='운용리스 입력'!D23 -> 70087270 | BJ19: ='운용리스 입력'!D23 -> 70087270
C20: 리스기간 | R20: ='운용리스 입력'!J4 -> 36 | AN20: ='운용리스 입력'!Q4 -> 48 | BJ20: ='운용리스 입력'!X4 -> 60
C21: 보증금 | R21: ='운용리스 내부'!H6 -> 0 | AA21: ='운용리스 내부'!I6 -> 0 | AN21: ='운용리스 내부'!M6 -> 0 | AW21: ='운용리스 내부'!N6 -> 0 | BJ21: ='운용리스 내부'!R6 -> 0 | BS21: ='운용리스 내부'!S6 -> 0
C22: 장기선수금 | R22: ='운용리스 내부'!H7 -> 0 | AA22: ='운용리스 내부'!I7 -> 0 | AN22: ='운용리스 내부'!M7 -> 0 | AW22: ='운용리스 내부'!N7 -> 0 | BJ22: ='운용리스 내부'!R7 -> 0 | BS22: ='운용리스 내부'!S7 -> 0
C23: 잔가 | R23: ='운용리스 내부'!H8 -> 0.63 | AA23: ='운용리스 내부'!I8 -> 41454000 | AN23: ='운용리스 내부'!M8 -> 0.55 | AW23: ='운용리스 내부'!N8 -> 36190000 | BJ23: ='운용리스 내부'!R8 -> 0.49 | BS23: ='운용리스 내부'!S8 -> 32242000
C24: 납부리스료 | R24: ='운용리스 입력'!J27 -> 1079400 | AN24: ='운용리스 입력'!Q27 -> 971000 | BJ24: ='운용리스 입력'!X27 -> 882700
C25: 차량분 | R25: ='운용리스 입력'!J24 -> 1079400 | AN25: ='운용리스 입력'!Q24 -> 971000 | BJ25: ='운용리스 입력'!X24 -> 882700
C26: 차세분 | R26: ='운용리스 입력'!J25 -> 0 | AN26: ='운용리스 입력'!Q25 -> 0 | BJ26: ='운용리스 입력'!X25 -> 0
C27: 장기선수금 차감분 | R27: ='운용리스 입력'!J26 -> 0 | AN27: ='운용리스 입력'!Q26 -> 0 | BJ27: ='운용리스 입력'!X26 -> 0
C28: 초기 부담금 | R28: =AA21+AA22+IF('운용리스 입력'!C16="미포함",'운용리스 입력'!D16,0)+IF('운용리스 입력'!C17="미포함",'운용리스 입력'!F18,0)+IF('운용리스 입력'!C19="미포함",'운용리스 입력'!D19,0)+IF('운용리스 입력'!C20="미포함",'운용리스 입력'!D20,0) -> 0 | AN28: =AW21+AW22+IF('운용리스 입력'!C16="미포함",'운용리스 입력'!D16,0)+IF('운용리스 입력'!C17="미포함",'운용리스 입력'!F18,0)+IF('운용리스 입력'!C19="미포함",'운용리스 입력'!D19,0)+IF('운용리스 입력'!C20="미포함",'운용리스 입력'!D20,0) -> 0 | BJ28: =BS21+BS22+IF('운용리스 입력'!C16="미포함",'운용리스 입력'!D16,0)+IF('운용리스 입력'!C17="미포함",'운용리스 입력'!F18,0)+IF('운용리스 입력'!C19="미포함",'운용리스 입력'!D19,0)+IF('운용리스 입력'!C20="미포함",'운용리스 입력'!D20,0) -> 0
C29: 약정주행거리 | R29: ='운용리스 입력'!J5 -> 20000 | AN29: ='운용리스 입력'!Q5 -> 20000 | BJ29: ='운용리스 입력'!X5 -> 20000
C30: 차량등록명의 | R30: ='운용리스 입력'!J2 -> 메리츠캐피탈 | AN30: ='운용리스 입력'!Q2 -> 메리츠캐피탈 | BJ30: ='운용리스 입력'!X2 -> 메리츠캐피탈
C31: =IF($R$30="고객명","차량설정금액",IF($AN$30="고객명","차량설정금액",IF($BJ$30="고객명","차량설정금액",""))) | R31: ='운용리스 입력'!D14 -> 65800000 | AN31: ='운용리스 입력'!D14 -> 65800000 | BJ31: ='운용리스 입력'!D14 -> 65800000
C33: 할인반영전 리스료 | AA33: =IF('운용리스 내부'!I35='운용리스 내부'!H27,"해당없음",'운용리스 내부'!I35) -> 해당없음 | AW33: =IF('운용리스 내부'!N35='운용리스 내부'!M27,"해당없음",'운용리스 내부'!N35) -> 해당없음 | BS33: =IF('운용리스 내부'!S35='운용리스 내부'!R27,"해당없음",'운용리스 내부'!S35) -> 해당없음
C34: 보증금 할인금액 | R34: =IF(AA33="해당없음","",'운용리스 내부'!H36) | AA34: =IF(AA33="해당없음","해당없음",'운용리스 내부'!I36) -> 해당없음 | AN34: =IF(AW33="해당없음","",'운용리스 내부'!M36) | AW34: =IF(AW33="해당없음","해당없음",'운용리스 내부'!N36) -> 해당없음 | BJ34: =IF(BS33="해당없음","",'운용리스 내부'!R36) | BS34: =IF(BS33="해당없음","해당없음",'운용리스 내부'!S36) -> 해당없음
C35: 장기선수금 할인금액 | R35: =IF(AA33="해당없음","",'운용리스 내부'!H37) | AA35: =IF(AA33="해당없음","해당없음",'운용리스 내부'!I37) -> 해당없음 | AN35: =IF(AW33="해당없음","",'운용리스 내부'!M37) | AW35: =IF(AW33="해당없음","해당없음",'운용리스 내부'!N37) -> 해당없음 | BJ35: =IF(BS33="해당없음","",'운용리스 내부'!R37) | BS35: =IF(BS33="해당없음","해당없음",'운용리스 내부'!S37) -> 해당없음
C37: 입금계좌
C39: ㆍ지방세법 개정에 따라 취득세는 시가표준액으로 인한 차액 발생될 수 있으며, 차액 금액은 고객 별도 부담입니다.
C40: ㆍ자차보험 및 보험 질권 설정 필수입니다. (차량가 100% / 질권자 메리츠캐피탈 주식회사 107-87-67865)
C41: ㆍ과태료, 범칙금, 정비료, 환경개선부담금, 자동차보험료, 자동차세(리스료 불포함시) 등은 고객 별도 부담이며, 리스 계약 만료시 차량 인수, 반납, 재리스 중 선택 가능합니다.
C42: ㆍ중도 반납 및 중도 인수, 승계 진행 시 일정 수수료가 발생되며, 반납시 주행거리, 차량 상태, 사고 이력, 부위 교체 이력 등에 따라 감가 금액이 발생할 수 있습니다.
C43: ㆍ차량 인수시(소유권 이전) 당사매매대금 또는 구청기준과표로 취득세 발생되며, 고객명의 인수 경우 취득세 자진납부신고 하셔야 합니다.
C44: 서울특별시 영등포구 국제금융로 10, ThreeIFC 23층 메리츠캐피탈 주식회사 / T. 1588-9666 / https://www.meritzcapital.com

Sheet 운용리스 입력
B2: 운용리스 견적 | D2: 2025_09_V1 | F2: 일자 | G2: =TODAY() -> 45904 | I2: 등록명의 | J2: =IF(BB7=TRUE,"메리츠캐피탈","고객명") -> 메리츠캐피탈 | L2: 조건1 | P2: 등록명의 | Q2: =IF(BB14=TRUE,"메리츠캐피탈","고객명") -> 메리츠캐피탈 | S2: 조건2 | W2: 등록명의 | X2: =IF(BB21=TRUE,"메리츠캐피탈","고객명") -> 메리츠캐피탈 | Z2: 조건3 | BA2: 체크박스
BA3: 등취득세 | BB3: TRUE
B4: 제휴사 | D4: 기타 | I4: 기간 | J4: 36 | P4: 기간 | Q4: 48 | W4: 기간 | X4: 60 | BA4: 공채비용 | BB4: TRUE
B5: 브랜드 | D5: Audi | I5: 주행거리 | J5: 20000 | P5: 주행거리 | Q5: 20000 | W5: 주행거리 | X5: 20000 | BA5: 탁송료 | BB5: TRUE
B6: 기본 모델 | D6: e_tron | BA6: 부대비용 | BB6: TRUE | BF6: 차량 연식 | BH6: 25MY
B7: 세부 모델 | D7: A6 e-tron Performance Advanced | I7: 보증금 | J7: 0 | L7: =ROUNDDOWN((D14*J7),-3) -> 0 | P7: 보증금 | Q7: 0 | S7: =ROUNDDOWN((D14*Q7),-3) -> 0 | W7: 보증금 | X7: 0 | Z7: =ROUNDDOWN((D14*X7),-3) -> 0 | BA7: 등록명의1 | BB7: TRUE
B8: 차량 연식 | D8: 25MY | I8: =IF(BB9=TRUE,"% 입력","금액 입력") -> % 입력 | J8: =L8/D14 -> 0.45592705 | L8: 30000000 | P8: =IF(BB16=TRUE,"% 입력","금액 입력") -> % 입력 | Q8: =S8/D14 -> 0.45592705 | S8: 30000000 | W8: =IF(BB23=TRUE,"% 입력","금액 입력") -> % 입력 | X8: =Z8/D14 -> 0.45592705 | Z8: 30000000 | BA8: 조건1 | BB8: FALSE
B9: 배기량 | D9: ='운용리스 내부'!D8 -> 0 | I9: 장기선수금 | J9: 0 | L9: =ROUNDDOWN((D14*J9),-3) -> 0 | P9: 장기선수금 | Q9: 0 | S9: =ROUNDDOWN((D14*Q9),-3) -> 0 | W9: 장기선수금 | X9: 0 | Z9: =ROUNDDOWN((D14*X9),-3) -> 0 | BA9: 보증금1 | BB9: TRUE
B10: =IF(AND(D8="25MY",'운용리스 내부'!X1=1%),"고잔가 프로모션 대상차종 (주행거리 10,000KM, 15,000KM 가능)","") | I10: =IF(BB10=TRUE,"% 입력","금액 입력") -> % 입력 | J10: =L10/D14 -> 0 | L10: 0 | P10: =IF(BB17=TRUE,"% 입력","금액 입력") -> % 입력 | Q10: =S10/D14 -> 0 | S10: 0 | W10: =IF(BB24=TRUE,"% 입력","금액 입력") -> % 입력 | X10: =Z10/D14 -> 0 | Z10: 0 | BA10: 장기선수금1 | BB10: TRUE
B11: 차량 가격 | D11: 65800000 | I11: 잔가 | J11: 0.63 | L11: =ROUNDDOWN((D14*J11),-3) -> 41454000 | P11: 잔가 | Q11: 0.55 | S11: =ROUNDDOWN((D14*Q11),-3) -> 36190000 | W11: 잔가 | X11: 0.49 | Z11: =ROUNDDOWN((D14*X11),-3) -> 32242000 | BA11: 잔가1 | BB11: TRUE
B12: 옵션 가격 | D12: 0 | I12: =IF(BB11=TRUE,"% 입력","금액 입력") -> % 입력 | J12: =L12/D14 -> 0 | L12: 0 | P12: =IF(BB18=TRUE,"% 입력","금액 입력") -> % 입력 | Q12: =S12/D14 -> 0 | S12: 0 | W12: =IF(BB25=TRUE,"% 입력","금액 입력") -> % 입력 | X12: =Z12/D14 -> 0.45592705 | Z12: 30000000 | BA12: 잔가하향1 | BB12: FALSE
B13: 할인 가격 | D13: 0 | I13: 잔가하향 | J13: 0 | L13: =$D$14*J13 -> 0 | P13: 잔가하향 | Q13: 0 | S13: =$D$14*Q13 -> 0 | W13: 잔가하향 | X13: 0 | Z13: =$D$14*X13 -> 0 | BA13: 차세1 | BB13: FALSE
B14: 차량가 최종 | D14: =D11+D12-D13 -> 65800000 | I14: 최대잔가 | J14: ='운용리스 내부'!H9 -> 0.63 | L14: ='운용리스 내부'!I9 -> 41454000 | P14: 최대잔가 | Q14: ='운용리스 내부'!M9 -> 0.55 | S14: ='운용리스 내부'!N9 -> 36190000 | W14: 최대잔가 | X14: ='운용리스 내부'!R9 -> 0.49 | Z14: ='운용리스 내부'!S9 -> 32242000 | BA14: 등록명의2 | BB14: TRUE
B15: =IF(OR(D8="23MY",D8="24MY"),"차량 최대할인 입력필수 / 미입력시 진행 불가","") | I15: 최소잔가 | J15: ='운용리스 내부'!H10 -> 0.3 | L15: ='운용리스 내부'!I10 -> 19740000 | P15: 최소잔가 | Q15: ='운용리스 내부'!M10 -> 0.2 | S15: ='운용리스 내부'!N10 -> 13160000 | W15: 최소잔가 | X15: ='운용리스 내부'!R10 -> 0.15 | Z15: ='운용리스 내부'!S10 -> 9870000 | BA15: 조건2 | BB15: TRUE
B16: 등록비 | C16: =IF(BB3=TRUE,"포함","미포함") -> 포함 | D16: =취득세!C6 -> 4187270 | BA16: 보증금2 | BB16: TRUE
B17: 공채 | C17: =IF(BB4=TRUE,"포함","미포함") -> 포함 | D17: 공채지역 | E17: 부산 | I17: 전기차보조금 | J17: 0 | P17: 전기차보조금 | Q17: 0 | W17: 전기차보조금 | X17: 0 | AD17: =IF(취득세!B6="전기","> 전기차 보조금 딜러사 확인 후 입력","") | BA17: 장기선수금2 | BB17: TRUE
D18: 공채할인 | E18: 0 | F18: ='공채&차세'!F4 -> 0 | I18: 이손금 | J18: 0 | P18: 이손금 | Q18: 0 | W18: 이손금 | X18: 0 | BA18: 잔가2 | BB18: TRUE
B19: 탁송료 | C19: =IF(BB5=TRUE,"포함","미포함") -> 포함 | D19: 0 | I19: 최대수수료 10% | P19: 최대수수료 10% | W19: 최대수수료 10% | BA19: 잔가하향2 | BB19: FALSE
B20: 부대비 | C20: =IF(BB6=TRUE,"포함","미포함") -> 포함 | D20: 100000 | I20: 수수료 Max | J20: ='운용리스 내부'!I14 -> 0.1 | P20: 수수료 Max | Q20: ='운용리스 내부'!N14 -> 0.1 | W20: 수수료 Max | X20: ='운용리스 내부'!S14 -> 0.1 | BA20: 차세2 | BB20: FALSE
B21: 등록비용 합산 | D21: =IF(C16="포함",D16,0)+IF(C17="포함",F18,0)+IF(C19="포함",D19,0)+IF(C20="포함",D20,0) -> 4287270 | I21: CM수수료 | J21: 0 | L21: ='운용리스 내부'!I15 -> 0 | P21: CM수수료 | Q21: 0 | S21: ='운용리스 내부'!N15 -> 0 | W21: CM수수료 | X21: 0 | Z21: ='운용리스 내부'!S15 -> 0 | BA21: 등록명의3 | BB21: TRUE
I22: AG수수료 | J22: 0 | L22: ='운용리스 내부'!I16 -> 0 | P22: AG수수료 | Q22: 0 | S22: ='운용리스 내부'!N16 -> 0 | W22: AG수수료 | X22: 0 | Z22: ='운용리스 내부'!S16 -> 0 | BA22: 조건3 | BB22: TRUE
B23: 취득원가 금액 | D23: =D14+D21 -> 70087270 | BA23: 보증금3 | BB23: TRUE
I24: 리스료 | J24: ='운용리스 내부'!H27 -> 1079400 | P24: 리스료 | Q24: ='운용리스 내부'!M27 -> 971000 | W24: 리스료 | X24: ='운용리스 내부'!R27 -> 882700 | BA24: 장기선수금3 | BB24: TRUE
B25: 담당자 | D25: 메리츠캐피탈 | I25: 차세 | J25: ='운용리스 내부'!H28 -> 0 | P25: 차세 | Q25: ='운용리스 내부'!M28 -> 0 | W25: 차세 | X25: ='운용리스 내부'!R28 -> 0 | BA25: 잔가3 | BB25: TRUE
B26: 고객명 | D26: VIP 고객님 | I26: 선납금차감분 | J26: ='운용리스 내부'!H29 -> 0 | P26: 선납금차감분 | Q26: ='운용리스 내부'!M29 -> 0 | W26: 선납금차감분 | X26: ='운용리스 내부'!R29 -> 0 | BA26: 잔가하향3 | BB26: FALSE
B27: 노란색 부분만 입력하면 됩니다. | I27: 최종리스료 | J27: =IF('운용리스 내부'!H30="",'운용리스 내부'!J30,'운용리스 내부'!H30) -> 1079400 | P27: 최종리스료 | Q27: =IF('운용리스 내부'!M30="",'운용리스 내부'!O30,'운용리스 내부'!M30) -> 971000 | W27: 최종리스료 | X27: =IF('운용리스 내부'!R30="",'운용리스 내부'!T30,'운용리스 내부'!R30) -> 882700 | BA27: 차세3 | BB27: FALSE
B28: 체크 선택시 입력값 변동 됩니다. | I28: 금리 | J28: ='운용리스 내부'!H32 -> 0.060221054 | P28: 금리 | Q28: ='운용리스 내부'!M32 -> 0.058680513 | W28: 금리 | X28: ='운용리스 내부'!R32 -> 0.057712436

Sheet 운용리스 내부
X1: =VLOOKUP(D6,차종!E:Q,12,0) -> 0
B2: ='운용리스 입력'!D2 -> 2025_09_V1 | D2: 견적일자 | E2: =TODAY() -> 45904 | G2: 조건1 | L2: 조건2 | Q2: 조건3
B3: 제휴사 | D3: ='운용리스 입력'!D4 -> 기타 | G3: 기간 | H3: ='운용리스 입력'!J4 -> 36 | L3: 기간 | M3: ='운용리스 입력'!Q4 -> 48 | Q3: 기간 | R3: ='운용리스 입력'!X4 -> 60
B4: 브랜드 | D4: ='운용리스 입력'!D5 -> Audi | G4: 주행거리 | H4: ='운용리스 입력'!J5 -> 20000 | L4: 주행거리 | M4: ='운용리스 입력'!Q5 -> 20000 | Q4: 주행거리 | R4: ='운용리스 입력'!X5 -> 20000
B5: 기본모델 | D5: ='운용리스 입력'!D6 -> e_tron
B6: 세부모델 | D6: ='운용리스 입력'!D7 -> A6 e-tron Performance Advanced | G6: 보증금 | H6: =IF('운용리스 입력'!BB9=TRUE,'운용리스 입력'!J7,'운용리스 내부'!I6/'운용리스 내부'!D13) -> 0 | I6: =IF('운용리스 입력'!BB9=FALSE,'운용리스 입력'!L8,ROUNDDOWN(('운용리스 내부'!D13*'운용리스 내부'!H6),-3)) -> 0 | L6: 보증금 | M6: =IF('운용리스 입력'!BB16=TRUE,'운용리스 입력'!Q7,'운용리스 내부'!N6/'운용리스 내부'!D13) -> 0 | N6: =IF('운용리스 입력'!BB16=FALSE,'운용리스 입력'!S8,ROUNDDOWN(('운용리스 내부'!D13*'운용리스 내부'!M6),-3)) -> 0 | Q6: 보증금 | R6: =IF('운용리스 입력'!BB23=TRUE,'운용리스 입력'!X7,'운용리스 내부'!S6/'운용리스 내부'!D13) -> 0 | S6: =IF('운용리스 입력'!BB23=FALSE,'운용리스 입력'!Z8,ROUNDDOWN(('운용리스 내부'!D13*'운용리스 내부'!R6),-3)) -> 0
B7: 세부모델 | D7: ='운용리스 입력'!D8 -> 25MY | G7: 장기선수금 | H7: =IF('운용리스 입력'!BB10=TRUE,'운용리스 입력'!J9,'운용리스 내부'!I7/'운용리스 내부'!D13) -> 0 | I7: =IF('운용리스 입력'!BB10=FALSE,'운용리스 입력'!L10,ROUNDDOWN(('운용리스 내부'!D13*'운용리스 내부'!H7),-3)) -> 0 | L7: 장기선수금 | M7: =IF('운용리스 입력'!BB17=TRUE,'운용리스 입력'!Q9,'운용리스 내부'!N7/'운용리스 내부'!D13) -> 0 | N7: =IF('운용리스 입력'!BB17=FALSE,'운용리스 입력'!S10,ROUNDDOWN(('운용리스 내부'!D13*'운용리스 내부'!M7),-3)) -> 0 | Q7: 장기선수금 | R7: =IF('운용리스 입력'!BB24=TRUE,'운용리스 입력'!X9,'운용리스 내부'!S7/'운용리스 내부'!D13) -> 0 | S7: =IF('운용리스 입력'!BB24=FALSE,'운용리스 입력'!Z10,ROUNDDOWN(('운용리스 내부'!D13*'운용리스 내부'!R7),-3)) -> 0
B8: 배기량 | D8: =VLOOKUP($D$6,차종!E:G,3,FALSE) -> 0 | G8: 잔가 | H8: =IF('운용리스 입력'!BB11=TRUE,'운용리스 입력'!J11,'운용리스 내부'!I8/'운용리스 내부'!D13) -> 0.63 | I8: =IF('운용리스 입력'!BB11=FALSE,'운용리스 입력'!L12,ROUNDDOWN(('운용리스 내부'!D13*'운용리스 내부'!H8),-3)) -> 41454000 | L8: 잔가 | M8: =IF('운용리스 입력'!BB18=TRUE,'운용리스 입력'!Q11,'운용리스 내부'!N8/'운용리스 내부'!D13) -> 0.55 | N8: =IF('운용리스 입력'!BB18=FALSE,'운용리스 입력'!S12,ROUNDDOWN(('운용리스 내부'!D13*'운용리스 내부'!M8),-3)) -> 36190000 | Q8: 잔가 | R8: =IF('운용리스 입력'!BB25=TRUE,'운용리스 입력'!X11,'운용리스 내부'!S8/'운용리스 내부'!D13) -> 0.49 | S8: =IF('운용리스 입력'!BB25=FALSE,'운용리스 입력'!Z12,ROUNDDOWN(('운용리스 내부'!D13*'운용리스 내부'!R8),-3)) -> 32242000
G9: 최대잔가 | H9: =잔가!E12 -> 0.63 | I9: =ROUNDDOWN((D13*H9),-3) -> 41454000 | L9: 최대잔가 | M9: =잔가!E21 -> 0.55 | N9: =ROUNDDOWN(($D$13*M9),-3) -> 36190000 | Q9: 최대잔가 | R9: =잔가!E30 -> 0.49 | S9: =ROUNDDOWN(($D$13*R9),-3) -> 32242000
B10: 차량가 | D10: ='운용리스 입력'!D11 -> 65800000 | G10: 최소잔가 | H10: =VLOOKUP(H3,잔가!J41:K45,2,0) -> 0.3 | I10: =ROUNDDOWN((D13*H10),-3) -> 19740000 | L10: 최소잔가 | M10: =VLOOKUP(M3,잔가!J41:K45,2,0) -> 0.2 | N10: =ROUNDDOWN(($D$13*M10),-3) -> 13160000 | Q10: 최소잔가 | R10: =VLOOKUP(R3,잔가!J41:K45,2,0) -> 0.15 | S10: =ROUNDDOWN(($D$13*R10),-3) -> 9870000
B11: 옵션 | D11: ='운용리스 입력'!D12 -> 0
B12: 할인가 | D12: ='운용리스 입력'!D13 -> 0 | G12: 전기차보조금 | H12: ='운용리스 입력'!J17 -> 0 | L12: 전기차보조금 | M12: ='운용리스 입력'!Q17 -> 0 | Q12: 전기차보조금 | R12: ='운용리스 입력'!X17 -> 0
B13: 차량가최종 | D13: ='운용리스 입력'!D14 -> 65800000 | G13: 이손금 | I13: ='운용리스 입력'!J18 -> 0 | L13: 이손금 | N13: ='운용리스 입력'!Q18 -> 0 | Q13: 이손금 | S13: ='운용리스 입력'!X18 -> 0
H14: CM/AG 최대 | I14: =IF((I15+I16)/D22>10%,"수수료 초과",10%) -> 0.1 | M14: CM/AG 최대 | N14: =IF((N15+N16)/D22>10%,"수수료 초과",10%) -> 0.1 | R14: CM/AG 최대 | S14: =IF((S15+S16)/D22>10%,"수수료 초과",10%) -> 0.1
B15: 등취득세 | D15: =IF('운용리스 입력'!C16="포함",'운용리스 입력'!D16,0) -> 4187270 | G15: CM수수료 | H15: ='운용리스 입력'!J21 -> 0 | I15: =ROUNDDOWN((H15*$D$22),-1) -> 0 | L15: CM수수료 | M15: ='운용리스 입력'!Q21 -> 0 | N15: =ROUNDDOWN((M15*$D$22),-1) -> 0 | Q15: CM수수료 | R15: ='운용리스 입력'!X21 -> 0 | S15: =ROUNDDOWN((R15*$D$22),-1) -> 0
B16: 공채 | D16: ='운용리스 입력'!E17 -> 부산 | G16: AG수수료 | H16: ='운용리스 입력'!J22 -> 0 | I16: =ROUNDDOWN((H16*$D$22),-1) -> 0 | L16: AG수수료 | M16: ='운용리스 입력'!Q22 -> 0 | N16: =ROUNDDOWN((M16*$D$22),-1) -> 0 | Q16: AG수수료 | R16: ='운용리스 입력'!X22 -> 0 | S16: =ROUNDDOWN((R16*$D$22),-1) -> 0
D17: ='운용리스 입력'!E18 -> 0 | E17: =IF('운용리스 입력'!C17="포함",'운용리스 입력'!F18,0) -> 0 | H17: =IF(H18="APS","70% 지급계좌 ~1867(국민)","") -> 70% 지급계좌 ~1867(국민) | M17: =IF(M18="APS","70% 지급계좌 ~1867(국민)","") -> 70% 지급계좌 ~1867(국민) | R17: =IF(R18="APS","70% 지급계좌 ~1867(국민)","") -> 70% 지급계좌 ~1867(국민)
B18: 탁송료 | D18: =IF('운용리스 입력'!C19="포함",'운용리스 입력'!D19,0) -> 0 | G18: 잔가보장수수료 | H18: =잔가!C11 -> APS | I18: =IF(잔가!C11="AJ",50%,IF(잔가!C11="APS",30%,"")) -> 0.3 | J18: =IF(H18="AJ",잔가!D13*I18,IF(H18="APS",잔가!D13*I18,"")) -> 256620 | L18: 잔가보장수수료 | M18: =잔가!C20 -> APS | N18: =IF(잔가!C20="AJ",50%,IF(잔가!C20="APS",30%,"")) -> 0.3 | O18: =IF(M18="AJ",잔가!D22*N18,IF(M18="APS",잔가!D22*N18,"")) -> 256620 | Q18: 잔가보장수수료 | R18: =잔가!C29 -> APS | S18: =IF(잔가!C29="AJ",50%,IF(잔가!C29="APS",30%,"")) -> 0.3 | T18: =IF(R18="AJ",잔가!D31*S18,IF(R18="APS",잔가!D31*S18,"")) -> 256620
B19: 부대비 | D19: =IF('운용리스 입력'!C20="포함",'운용리스 입력'!D20,0) -> 100000 | I19: =IF(잔가!C11="AJ",50%,IF(잔가!C11="APS",70%,"")) -> 0.7 | J19: =IF(H18="AJ",잔가!D13*I19,IF(H18="APS",잔가!D13*I19,"")) -> 598780 | N19: =IF(잔가!C20="AJ",50%,IF(잔가!C20="APS",70%,"")) -> 0.7 | O19: =IF(M18="AJ",잔가!D22*N19,IF(M18="APS",잔가!D22*N19,"")) -> 598780 | S19: =IF(잔가!C29="AJ",50%,IF(잔가!C29="APS",70%,"")) -> 0.7 | T19: =IF(R18="AJ",잔가!D31*S19,IF(R18="APS",잔가!D31*S19,"")) -> 598780
B20: 등록비합산 | D20: ='운용리스 입력'!D21 -> 4287270 | I20: 토탈 | J20: =잔가!D13 -> 855400 | N20: 토탈 | O20: =잔가!D22 -> 855400 | S20: 토탈 | T20: =잔가!D31 -> 855400
G21: 제휴사 수수료 | H21: =$D$3 -> 기타 | I21: =VLOOKUP($D$3,딜러사!$E$6:$G$25,3,FALSE)-딜러사!E28-딜러사!E29 -> 0 | J21: =ROUNDDOWN(($D$22*I21),-1) -> 0 | L21: 제휴사 수수료 | M21: =$D$3 -> 기타 | N21: =VLOOKUP($D$3,딜러사!$E$6:$G$25,3,FALSE)-딜러사!E28-딜러사!E29 -> 0 | O21: =ROUNDDOWN(($D$22*N21),-1) -> 0 | Q21: 제휴사 수수료 | R21: =$D$3 -> 기타 | S21: =VLOOKUP($D$3,딜러사!$E$6:$G$25,3,FALSE)-딜러사!E28-딜러사!E29 -> 0 | T21: =ROUNDDOWN(($D$22*S21),-1) -> 0
B22: 취득원가 | D22: ='운용리스 입력'!D23 -> 70087270 | H22: =IF(D3="세영모빌리티","1줄추가 별도 입력","") | J22: =IF(D3="세영모빌리티",딜러사!E30,0) -> 0 | M22: =IF(D3="세영모빌리티","1줄추가 별도 입력","") | O22: =IF(D3="세영모빌리티",딜러사!E30,0) -> 0 | R22: =IF(D3="세영모빌리티","1줄추가 별도 입력","") | T22: =IF(D3="세영모빌리티",딜러사!E30,0) -> 0
G23: 본부장 수수료 | H23: =IF(D3="아우토슈타트",D3,IF(D3="브리티시오토",D3,IF(D3="모터원","모터원담당",""))) | I23: =IF(D3="아우토슈타트",0.1%,IF(D3="브리티시오토",0.2%,IF(D3="모터원",0.2%,0))) -> 0 | J23: =ROUNDDOWN(($D$22*I23),-1) -> 0 | L23: 본부장 수수료 | M23: =IF(D3="아우토슈타트",D3,IF(D3="브리티시오토",D3,IF(D3="모터원","모터원담당",""))) | N23: =IF(D3="아우토슈타트",0.1%,IF(D3="브리티시오토",0.2%,IF(D3="모터원",0.2%,0))) -> 0 | O23: =ROUNDDOWN(($D$22*N23),-1) -> 0 | Q23: 본부장 수수료 | R23: =IF(D3="아우토슈타트",D3,IF(D3="브리티시오토",D3,IF(D3="모터원","모터원담당",""))) | S23: =IF(D3="아우토슈타트",0.1%,IF(D3="브리티시오토",0.2%,IF(D3="모터원",0.2%,0))) -> 0 | T23: =ROUNDDOWN(($D$22*S23),-1) -> 0
G24: 추가수수료 | H24: 실행시 입력 | I24: 0.005 | J24: =ROUNDDOWN(($D$22*I24),-1) -> 350430 | L24: 추가수수료 | M24: 실행시 입력 | N24: 0.005 | O24: =ROUNDDOWN(($D$22*N24),-1) -> 350430 | Q24: 추가수수료 | R24: 실행시 입력 | S24: 0.005 | T24: =ROUNDDOWN(($D$22*S24),-1) -> 350430
B25: =IF(OR(D7="23MY",D7="24MY"),"차량 최대할인 입력필수 / 미입력시 진행 불가","") | G25: 설정비 | H25: =IF('운용리스 입력'!BB7=FALSE,'운용리스 입력'!$D$14*0.6%*100%,0) -> 0 | L25: 설정비 | M25: =IF('운용리스 입력'!BB14=FALSE,'운용리스 입력'!$D$14*0.6%*100%,0) -> 0 | Q25: 설정비 | R25: =IF('운용리스 입력'!BB21=FALSE,'운용리스 입력'!$D$14*0.6%*100%,0) -> 0
H26: 토탈 수수료 | I26: =(I15+I16+J20+J21+J23+J24)/D22 -> 0.017204694 | M26: 토탈 수수료 | N26: =(N15+N16+O20+O21+O23+O24)/D22 -> 0.017204694 | R26: 토탈 수수료 | S26: =(S15+S16+T20+T21+T23+T24)/D22 -> 0.017204694
G27: 리스료 | H27: =H42 -> 1079400 | L27: 리스료 | M27: =M42 -> 971000 | Q27: 리스료 | R27: =R42 -> 882700
G28: 차세 | H28: =IF('운용리스 입력'!BB13=FALSE,0,'공채&차세'!$D$50) -> 0 | L28: 차세 | M28: =IF('운용리스 입력'!BB20=FALSE,0,'공채&차세'!$D$50) -> 0 | Q28: 차세 | R28: =IF('운용리스 입력'!BB27=FALSE,0,'공채&차세'!$D$50) -> 0
G29: 선납금차감분 | H29: =ROUNDDOWN((I7/H3),-1) -> 0 | L29: 선납금차감분 | M29: =ROUNDDOWN((N7/M3),-1) -> 0 | Q29: 선납금차감분 | R29: =ROUNDDOWN((S7/R3),-1) -> 0
G30: 최종리스료 | H30: =IF(I9<I8,"잔가 기준 내 가능",IF(I10>I8,"잔가 기준 내 가능",IF(I14="수수료 초과","수수료 초과",IF(H32<2.3%,"담당자 문의",IF(H6+H7>70.1%,"초기비용 70% 초과",IF(H6>50.1%,"보증금 50% 초과",IF(H7>50.1%,"선수금 50% 초과",IF(H6+H7+H8>100.1%,"초기비용+잔가 초과",IF(H43<0,"진행불가",""))))))))) | J30: =IF(H43+H28=H27-H29+H28,H43+H28,H27-H29+H28) -> 1079400 | L30: 최종리스료 | M30: =IF(N9<N8,"잔가 기준 내 가능",IF(N10>N8,"잔가 기준 내 가능",IF(N14="수수료 초과","수수료 초과",IF(M32<2.3%,"담당자 문의",IF(M6+M7>70.1%,"초기비용 70% 초과",IF(M6>50.1%,"보증금 50% 초과",IF(M7>50.1%,"선수금 50% 초과",IF(M6+M7+M8>100.1%,"초기비용+잔가 초과",IF(M43<0,"진행불가",""))))))))) | O30: =IF(M43+M28=M27-M29+M28,M43+M28,M27-M29+M28) -> 971000 | Q30: 최종리스료 | R30: =IF(S9<S8,"잔가 기준 내 가능",IF(S10>S8,"잔가 기준 내 가능",IF(S14="수수료 초과","수수료 초과",IF(R32<2.3%,"담당자 문의",IF(R6+R7>70.1%,"초기비용 70% 초과",IF(R6>50.1%,"보증금 50% 초과",IF(R7>50.1%,"선수금 50% 초과",IF(R6+R7+R8>100.1%,"초기비용+잔가 초과",IF(R43<0,"진행불가",""))))))))) | T30: =IF(R43+R28=R27-R29+R28,R43+R28,R27-R29+R28) -> 882700
G32: 금리 | H32: =RATE(H3,H42,(-$D$22+H12),I8)*12 -> 0.060221054 | L32: 금리 | M32: =RATE(M3,M42,(-$D$22+M12),N8)*12 -> 0.058680513 | Q32: 금리 | R32: =RATE(R3,R42,(-$D$22+R12),S8)*12 -> 0.057712436
G33: IRR | H33: =VLOOKUP($D$4,브랜드!$B$2:$C$29,2,FALSE)+IF(H6+H7>49.9999%,브랜드!C35,0%)+IF(H6+H7>59.9999%,브랜드!C36,0%)+IF(H6+H7>64.9999%,브랜드!C37,0%)+IF(H6+H7<10%,브랜드!C32,0%)+IF(D7="23MY",브랜드!C38,0%)+IF(H25>0,0.2%,0%)+IF(D6="Polestar 4 Long range Dual motor",1.7%,0%) -> 0.0525 | L33: IRR | M33: =VLOOKUP($D$4,브랜드!$B$2:$C$29,2,FALSE)+IF(M6+M7>49.9999%,브랜드!C35,0%)+IF(M6+M7>59.9999%,브랜드!C36,0%)+IF(M6+M7>64.9999%,브랜드!C37,0%)+IF(M6+M7<10%,브랜드!C32,0%)+IF(D7="23MY",브랜드!C38,0%)+IF(M25>0,0.2%,0%)+IF(D6="Polestar 4 Long range Dual motor",1.7%,0%) -> 0.0525 | Q33: IRR | R33: =VLOOKUP($D$4,브랜드!$B$2:$C$29,2,FALSE)+IF(R6+R7>49.9999%,브랜드!C35,0%)+IF(R6+R7>59.9999%,브랜드!C36,0%)+IF(R6+R7>64.9999%,브랜드!C37,0%)+IF(R6+R7<10%,브랜드!C32,0%)+IF(D7="23MY",브랜드!C38,0%)+IF(R25>0,0.2%,0%)+IF(D6="Polestar 4 Long range Dual motor",1.7%,0%) -> 0.0525
G35: 할인반영전리스료 | I35: =ROUNDUP(PMT(H33/12,H3,-$D$22+H12-I15-I16-J20-J21-J22-J23-J24-10000+I13-H25,I8),-2) -> 1079400 | L35: 할인반영전리스료 | N35: =ROUNDUP(PMT(M33/12,M3,-$D$22+M12-N15-N16-O20-O21-O22-O23-O24-10000+N13-M25,N8),-2) -> 971000 | Q35: 할인반영전리스료 | S35: =ROUNDUP(PMT(R33/12,R3,-$D$22+R12-S15-S16-T20-T21-T22-T23-T24-10000+S13-R25,S8),-2) -> 882700
G36: 보증금할인액 | H36: =IF(H12>0,0,I36/I35) -> 0 | I36: =I35-ROUNDUP(PMT(H33/12,H3,-$D$22+H12+I6-I15-I16-J20-J21-J22-J23-J24-10000+I13-H25,I8-I6),-2) -> 0 | L36: 보증금할인액 | M36: =IF(M12>0,0,N36/N35) -> 0 | N36: =N35-ROUNDUP(PMT(M33/12,M3,-$D$22+M12+N6-N15-N16-O20-O21-O22-O23-O24-10000+N13-M25,N8-N6),-2) -> 0 | Q36: 보증금할인액 | R36: =IF(R12>0,0,S36/S35) -> 0 | S36: =S35-ROUNDUP(PMT(R33/12,R3,-$D$22+R12+S6-S15-S16-T20-T21-T22-T23-T24-10000+S13-R25,S8-S6),-2) -> 0
G37: 장기선수금할인액 | H37: =IF(H12>0,0,I37/I35) -> 0 | I37: =I35-ROUNDUP(PMT(H33/12,H3,-$D$22+H12+I7-I15-I16-J20-J21-J22-J23-J24-10000+I13-H25,I8),-2) -> 0 | L37: 장기선수금할인액 | M37: =IF(M12>0,0,N37/N35) -> 0 | N37: =N35-ROUNDUP(PMT(M33/12,M3,-$D$22+M12+N7-N15-N16-O20-O21-O22-O23-O24-10000+N13-M25,N8),-2) -> 0 | Q37: 장기선수금할인액 | R37: =IF(R12>0,0,S37/S35) -> 0 | S37: =S35-ROUNDUP(PMT(R33/12,R3,-$D$22+R12+S7-S15-S16-T20-T21-T22-T23-T24-10000+S13-R25,S8),-2) -> 0
G42: 리스료(선납제외) | H42: =ROUNDDOWN(H43+(I7/H3),-1) -> 1079400 | L42: 리스료(선납제외) | M42: =ROUNDDOWN(M43+(N7/M3),-1) -> 971000 | Q42: 리스료(선납제외) | R42: =ROUNDDOWN(R43+(S7/R3),-1) -> 882700
G43: 리스료 | H43: =ROUNDUP(PMT(H33/12,H3,-$D$22+H12+I6+I7-I15-I16-J20-J21-J22-J23-J24-10000+I13-H25,I8-I6),-2) -> 1079400 | L43: 리스료 | M43: =ROUNDUP(PMT(M33/12,M3,-$D$22+M12+N6+N7-N15-N16-O20-O21-O22-O23-O24-10000+N13-M25,N8-N6),-2) -> 971000 | Q43: 리스료 | R43: =ROUNDUP(PMT(R33/12,R3,-$D$22+R12+S6+S7-S15-S16-T20-T21-T22-T23-T24-10000+S13-R25,S8-S6),-2) -> 882700

Sheet 금융리스 견적출력
AW3: ='금융리스 입력'!D2 -> 2025_09_V1
C4: 금 융 리 스 견 적 서 | BQ4: =TODAY() -> 45904
BS5: 담당자 | BW5: ='금융리스 입력'!D19 -> 메리츠캐피탈
AZ10: ='금융리스 입력'!D20 -> VIP 고객님 | BN10: 아래 견적 제안 드립니다.
C11: ▣ 차량정보
C12: 차종 | P12: ='금융리스 입력'!D4 -> BYD | AC12: ='금융리스 입력'!D6 -> ATTO 3 Plus | BW12: ='금융리스 입력'!D7 -> 0
C13: 기본 가격 | P13: ='금융리스 입력'!D8 -> 40000000 | AP13: 옵션 가격 | BD13: ='금융리스 입력'!D9 -> 0
C14: 할인 가격 | P14: ='금융리스 입력'!D10 -> 0 | AP14: 최종 가격 | BD14: ='금융리스 입력'!D11 -> 40000000
C16: ▣ 등록비용
C17: 등취득세 | P17: ='금융리스 입력'!D13 -> 1145450 | AP17: 공채비용 | BD17: ='금융리스 입력'!F15 -> 0
C18: 탁송료 | P18: ='금융리스 입력'!D16 -> 100000 | AP18: 부대비용 | BD18: ='금융리스 입력'!D17 -> 100000
C19: ="등록지역 "&'금융리스 입력'!E14 -> 등록지역 인천 | AP19: 등록비용 총합계 | BD19: ='금융리스 입력'!D18 -> 1345450
C21: ▣ 리스조건
C22: 구분 | R22: 조건 1 | AN22: 조건 2 | BJ22: 조건 3
C23: 이용 금액 | R23: ='금융리스 입력'!J4 -> 32000000 | AN23: ='금융리스 입력'!Q4 -> 32000000 | BJ23: ='금융리스 입력'!X4 -> 32000000
C24: 리스 기간 | R24: ='금융리스 입력'!J3 -> 36 | AN24: ='금융리스 입력'!Q3 -> 48 | BJ24: ='금융리스 입력'!X3 -> 60
C25: 차량 선수금 | R25: ='금융리스 내부'!H6 -> 0.2 | AA25: ='금융리스 내부'!I6 -> 8000000 | AN25: ='금융리스 내부'!M6 -> 0.2 | AW25: ='금융리스 내부'!N6 -> 8000000 | BJ25: ='금융리스 내부'!R6 -> 0.2 | BS25: ='금융리스 내부'!S6 -> 8000000
C26: 납부리스료 | R26: ='금융리스 입력'!J21 -> 973900 | AN26: ='금융리스 입력'!Q21 -> 751800 | BJ26: ='금융리스 입력'!X21 -> 618900
C27: 차량분 | R27: ='금융리스 입력'!J19 -> 973900 | AN27: ='금융리스 입력'!Q19 -> 751800 | BJ27: ='금융리스 입력'!X19 -> 618900
C28: 차세분 | R28: ='금융리스 입력'!J20 -> 0 | AN28: ='금융리스 입력'!Q20 -> 0 | BJ28: ='금융리스 입력'!X20 -> 0
C29: 초기 부담금 | R29: =AA25+BD19 -> 9345450 | AN29: =AW25+BD19 -> 9345450 | BJ29: =BS25+BD19 -> 9345450
C30: 금리 | R30: ='금융리스 입력'!J22 -> 0.060274464 | AN30: ='금융리스 입력'!Q22 -> 0.060190193 | BJ30: ='금융리스 입력'!X22 -> 0.060168231
C31: =IF('금융리스 입력'!BB8=TRUE,"유예금",IF('금융리스 입력'!BB13=TRUE,"유예금",IF('금융리스 입력'!BB18=TRUE,"유예금",""))) | R31: ='금융리스 내부'!H7 -> 0 | AA31: ='금융리스 내부'!I7 -> 0 | AN31: ='금융리스 내부'!M7 -> 0 | AW31: ='금융리스 내부'!N7 -> 0 | BJ31: ='금융리스 내부'!R7 -> 0 | BS31: ='금융리스 내부'!S7 -> 0
C33: 입금계좌
C35: ㆍ지방세법 개정에 따라 취득세는 시가표준액으로 인한 차액 발생될 수 있으며, 차액 금액은 고객 별도 부담입니다.
C36: ㆍ자차보험 및 보험 질권 설정 필수입니다. (차량가 100% / 질권자 메리츠캐피탈 주식회사 107-87-67865)
C37: ㆍ과태료, 범칙금, 정비료, 환경개선부담금, 자동차보험료, 자동차세(리스료 불포함시) 등은 고객 별도 부담이며, 리스 계약 만료시 차량 인수, 재리스(유예시) 중 선택 가능합니다.
C38: ㆍ중도상환 및 승계 진행 시 일정 수수료가 발생되며, 중도상환시 수수료(미회수원금 * 잔여기간/전체기간 * 3%) 발생합니다.
C39: ㆍ차량 인수시(소유권 이전) 당사매매대금 또는 구청기준과표로 취득세 발생됩니다.
C40: 서울특별시 영등포구 국제금융로 10, ThreeIFC 23층 메리츠캐피탈 주식회사 / T. 1588-9666 / https://www.meritzcapital.com

Sheet 금융리스 입력
B2: 금융리스 견적 | D2: ='운용리스 입력'!D2:G2 -> 2025_09_V1 | F2: 일자 | G2: =TODAY() -> 45904 | I2: 조건1 | P2: 조건2 | W2: 조건3 | BA2: 체크박스
B3: 제휴사 | D3: 기타 | I3: 기간 | J3: 36 | P3: 기간 | Q3: 48 | W3: 기간 | X3: 60 | BA3: 등취득세 | BB3: TRUE
B4: 브랜드 | D4: BYD | I4: 이용금액 | J4: ='금융리스 내부'!H4 -> 32000000 | P4: 이용금액 | Q4: ='금융리스 내부'!M4 -> 32000000 | W4: 이용금액 | X4: ='금융리스 내부'!R4 -> 32000000 | BA4: 공채비용 | BB4: TRUE
B5: 기본 모델 | D5: BYD | BA5: 탁송료 | BB5: TRUE
B6: 세부 모델 | D6: ATTO 3 Plus | I6: 선수금 | J6: 0.2 | L6: =D11*J6 -> 8000000 | P6: 선수금 | Q6: 0.2 | S6: =D11*Q6 -> 8000000 | W6: 선수금 | X6: 0.2 | Z6: =D11*X6 -> 8000000 | BA6: 부대비용 | BB6: TRUE
B7: 배기량 | D7: ='금융리스 내부'!D8:E8 -> 0 | I7: =IF(BB7=TRUE,"% 입력","금액 입력") -> % 입력 | J7: =L7/D11 -> 0.125 | L7: 5000000 | P7: =IF(BB12=TRUE,"% 입력","금액 입력") -> % 입력 | Q7: =S7/D11 -> 0.75 | S7: 30000000 | W7: =IF(BB17=TRUE,"% 입력","금액 입력") -> % 입력 | X7: =Z7/D11 -> 0.75 | Z7: 30000000 | BA7: 선수금1 | BB7: TRUE
B8: 차량 가격 | D8: 40000000 | BA8: 유예1 | BB8: FALSE | BC8: FALSE
B9: 옵션 가격 | D9: 0 | I9: 유예금 | J9: 0.15 | L9: =D11*J9 -> 6000000 | P9: 유예금 | Q9: 0.3 | S9: =D11*Q9 -> 12000000 | W9: 유예금 | X9: 0.3 | Z9: =D11*X9 -> 12000000 | BA9: 유예1-1 | BB9: FALSE
B10: 할인 가격 | D10: 0 | I10: =IF(BB9=TRUE,"% 입력","금액 입력") -> 금액 입력 | J10: =L10/D11 -> 0.25 | L10: 10000000 | P10: =IF(BB14=TRUE,"% 입력","금액 입력") -> 금액 입력 | Q10: =S10/D11 -> 0.75 | S10: 30000000 | W10: =IF(BB19=TRUE,"% 입력","금액 입력") -> 금액 입력 | X10: =Z10/D11 -> 0.75 | Z10: 30000000 | BA10: 차세1 | BB10: FALSE
B11: 차량가 최종 | D11: =D8+D9-D10 -> 40000000 | I11: 유예 최대 | J11: ='금융리스 내부'!H8 -> 0.3 | L11: ='금융리스 내부'!I8 -> 12000000 | P11: 유예 최대 | Q11: ='금융리스 내부'!M8 -> 0.2 | S11: ='금융리스 내부'!N8 -> 8000000 | W11: 유예 최대 | X11: ='금융리스 내부'!R8 -> 0.15 | Z11: ='금융리스 내부'!S8 -> 6000000 | BA11: 조건2 | BB11: TRUE
BA12: 선수금2 | BB12: TRUE
B13: 등록비용 | D13: =취득세!F6 -> 1145450 | I13: 이손금 | J13: 0 | P13: 이손금 | Q13: 0 | W13: 이손금 | X13: 0 | BA13: 유예2 | BB13: FALSE | BC13: FALSE
B14: 공채비용 | D14: 공채지역 | E14: 인천 | BA14: 유예2-2 | BB14: FALSE
D15: 공채할인 | E15: 0.09 | F15: ='공채&차세'!O4 -> 0 | I15: 수수료 Max | J15: ='금융리스 내부'!I12 -> 0.0225 | P15: 수수료 Max | Q15: ='금융리스 내부'!N12 -> 0.0225 | W15: 수수료 Max | X15: ='금융리스 내부'!S12 -> 0.0225 | BA15: 차세2 | BB15: FALSE
B16: 탁송료 | D16: 100000 | I16: CM수수료 | J16: 0 | L16: ='금융리스 내부'!I13 -> 0 | P16: CM수수료 | Q16: 0 | S16: ='금융리스 내부'!N13 -> 0 | W16: CM수수료 | X16: 0 | Z16: ='금융리스 내부'!S13 -> 0 | BA16: 조건3 | BB16: TRUE
B17: 부대비용 | D17: 100000 | I17: AG수수료 | J17: 0 | L17: ='금융리스 내부'!I14 -> 0 | P17: AG수수료 | Q17: 0 | S17: ='금융리스 내부'!N14 -> 0 | W17: AG수수료 | X17: 0 | Z17: ='금융리스 내부'!S14 -> 0 | BA17: 선수금3 | BB17: TRUE
B18: 등록비용 합산 | D18: =SUM(D13+F15+D16+D17) -> 1345450 | BA18: 유예3 | BB18: FALSE | BC18: FALSE
B19: 담당자 | D19: 메리츠캐피탈 | I19: 리스료 | J19: ='금융리스 내부'!H39 -> 973900 | P19: 리스료 | Q19: ='금융리스 내부'!M39 -> 751800 | W19: 리스료 | X19: ='금융리스 내부'!R39 -> 618900 | BA19: 유예3-3 | BB19: FALSE
B20: 고객명 | D20: VIP 고객님 | I20: 차세 | J20: ='금융리스 내부'!I20 -> 0 | P20: 차세 | Q20: ='금융리스 내부'!N20 -> 0 | W20: 차세 | X20: ='금융리스 내부'!S20 -> 0 | BA20: 차세3 | BB20: FALSE
C21: 노란색 부분만 입력하면 됩니다. | I21: 최종리스료 | J21: =IF(J4<20000000,"20,000,000 이하 불가",'금융리스 내부'!I21) -> 973900 | P21: 최종리스료 | Q21: =IF(Q4<20000000,"20,000,000 이하 불가",'금융리스 내부'!N21) -> 751800 | W21: 최종리스료 | X21: =IF(X4<20000000,"20,000,000 이하 불가",'금융리스 내부'!S21) -> 618900
C22: 체크 선택시 입력값 변동 됩니다. | I22: 금리 | J22: ='금융리스 내부'!H23 -> 0.060274464 | P22: 금리 | Q22: ='금융리스 내부'!M23 -> 0.060190193 | W22: 금리 | X22: ='금융리스 내부'!R23 -> 0.060168231

Sheet 금융리스 내부
G2: 조건1 | L2: 조건2 | Q2: 조건3
B3: ='금융리스 입력'!$D$2 -> 2025_09_V1 | D3: 견적일자 | E3: =TODAY() -> 45904 | G3: 기간 | H3: ='금융리스 입력'!J3 -> 36 | L3: 기간 | M3: ='금융리스 입력'!Q3 -> 48 | Q3: 기간 | R3: ='금융리스 입력'!X3 -> 60
B4: 제휴사 | D4: ='금융리스 입력'!D3:G3 -> 기타 | G4: 이용금액 | H4: =IF('금융리스 입력'!BB7=TRUE,D13-H6*D13,D13-I6) -> 32000000 | L4: 이용금액 | M4: =IF('금융리스 입력'!BB12=TRUE,D13-M6*D13,D13-N6) -> 32000000 | Q4: 이용금액 | R4: =IF('금융리스 입력'!BB17=TRUE,D13-R6*D13,D13-S6) -> 32000000
B5: 브랜드 | D5: ='금융리스 입력'!D4:G4 -> BYD
B6: 기본모델 | D6: ='금융리스 입력'!D5:G5 -> BYD | G6: 선수금 | H6: =IF('금융리스 입력'!BB7=TRUE,'금융리스 입력'!J6,'금융리스 입력'!L7/'금융리스 입력'!D11) -> 0.2 | I6: =IF('금융리스 입력'!BB7=FALSE,'금융리스 입력'!L7,D13*H6) -> 8000000 | L6: 선수금 | M6: =IF('금융리스 입력'!BB12=TRUE,'금융리스 입력'!Q6,'금융리스 입력'!S7/'금융리스 입력'!D11) -> 0.2 | N6: =IF('금융리스 입력'!BB12=FALSE,'금융리스 입력'!S7,D13*M6) -> 8000000 | Q6: 선수금 | R6: =IF('금융리스 입력'!BB17=TRUE,'금융리스 입력'!X6,'금융리스 입력'!Z7/'금융리스 입력'!D11) -> 0.2 | S6: =IF('금융리스 입력'!BB17=FALSE,'금융리스 입력'!Z7,D13*R6) -> 8000000
B7: 세부모델 | D7: ='금융리스 입력'!D6:G6 -> ATTO 3 Plus | G7: 유예최종 | H7: =IF('금융리스 입력'!BB8=TRUE,'금융리스 내부'!H9,0) -> 0 | I7: =IF('금융리스 입력'!BB8=TRUE,'금융리스 내부'!I9,0) -> 0 | L7: 유예최종 | M7: =IF('금융리스 입력'!BB13=TRUE,'금융리스 내부'!M9,0) -> 0 | N7: =IF('금융리스 입력'!BB13=TRUE,'금융리스 내부'!N9,0) -> 0 | Q7: 유예최종 | R7: =IF('금융리스 입력'!BB18=TRUE,'금융리스 내부'!R9,0) -> 0 | S7: =IF('금융리스 입력'!BB18=TRUE,'금융리스 내부'!S9,0) -> 0
B8: 배기량 | D8: =VLOOKUP($D$7,차종!E7:G1310,3,FALSE) -> 0 | G8: 유예최대 | H8: =VLOOKUP(H3,잔가!J41:K45,2,0) -> 0.3 | I8: =D13*H8 -> 12000000 | L8: 유예최대 | M8: =VLOOKUP(M3,잔가!J41:K45,2,0) -> 0.2 | N8: =$D$13*M8 -> 8000000 | Q8: 유예최대 | R8: =VLOOKUP(R3,잔가!J41:K45,2,0) -> 0.15 | S8: =$D$13*R8 -> 6000000
G9: 유예금2 | H9: =IF('금융리스 입력'!BB9=TRUE,'금융리스 입력'!J9,'금융리스 입력'!L10/'금융리스 입력'!D11) -> 0.25 | I9: =IF('금융리스 입력'!BB9=FALSE,'금융리스 입력'!L7,D13*H9) -> 5000000 | L9: 유예금2 | M9: =IF('금융리스 입력'!BB14=TRUE,'금융리스 입력'!Q9,'금융리스 입력'!S10/'금융리스 입력'!D11) -> 0.75 | N9: =IF('금융리스 입력'!BB14=FALSE,'금융리스 입력'!S7,D13*M9) -> 30000000 | Q9: 유예금2 | R9: =IF('금융리스 입력'!BB19=TRUE,'금융리스 입력'!X9,'금융리스 입력'!Z10/'금융리스 입력'!D11) -> 0.75 | S9: =IF('금융리스 입력'!BB19=FALSE,'금융리스 입력'!Z7,D13*R9) -> 30000000
B10: 차량가 | D10: ='금융리스 입력'!D8:G8 -> 40000000
B11: 옵션 | D11: ='금융리스 입력'!D9:G9 -> 0 | G11: 이손금 | I11: ='금융리스 입력'!J13 -> 0 | L11: 이손금 | N11: ='금융리스 입력'!Q13 -> 0 | Q11: 이손금 | S11: ='금융리스 입력'!X13 -> 0
B12: 할인가 | D12: ='금융리스 입력'!D10:G10 -> 0 | H12: CM/AG 최대 | I12: =IF((I13+I14+J16+J17)/H4>2.25%,"수수료 초과",2.25%-(J16+J17)/H4) -> 0.0225 | M12: CM/AG 최대 | N12: =IF((N13+N14+O16+O17)/M4>2.25%,"수수료 초과",2.25%-(O16+O17)/M4) -> 0.0225 | R12: CM/AG 최대 | S12: =IF((S13+S14+T16+T17)/R4>2.25%,"수수료 초과",2.25%-(T16+T17)/R4) -> 0.0225
B13: 차량가최종 | D13: ='금융리스 입력'!D11:G11 -> 40000000 | G13: CM수수료 | H13: ='금융리스 입력'!J16 -> 0 | I13: =ROUNDDOWN((H13*$H$4),-1) -> 0 | L13: CM수수료 | M13: ='금융리스 입력'!Q16 -> 0 | N13: =ROUNDDOWN((M13*$M$4),-1) -> 0 | Q13: CM수수료 | R13: ='금융리스 입력'!X16 -> 0 | S13: =ROUNDDOWN((R13*$R$4),-1) -> 0
G14: AG수수료 | H14: ='금융리스 입력'!J17 -> 0 | I14: =ROUNDDOWN((H14*$H$4),-1) -> 0 | L14: AG수수료 | M14: ='금융리스 입력'!Q17 -> 0 | N14: =ROUNDDOWN((M14*$M$4),-1) -> 0 | Q14: AG수수료 | R14: ='금융리스 입력'!X17 -> 0 | S14: =ROUNDDOWN((R14*$R$4),-1) -> 0
B15: 등취득세 | D15: ='금융리스 입력'!D13:G13 -> 1145450
B16: 공채 | D16: ='금융리스 입력'!E14 -> 인천 | G16: 제휴사 수수료 | H16: =$D$4 -> 기타 | I16: =VLOOKUP($D$4,딜러사!$J$6:$L$25,3,FALSE)-딜러사!F28-딜러사!F29 -> 0 | J16: =I16*H4 -> 0 | L16: 제휴사 수수료 | M16: =$D$4 -> 기타 | N16: =VLOOKUP($D$4,딜러사!$J$6:$L$25,3,FALSE)-딜러사!F28-딜러사!F29 -> 0 | O16: =N16*M4 -> 0 | Q16: 제휴사 수수료 | R16: =$D$4 -> 기타 | S16: =VLOOKUP($D$4,딜러사!$J$6:$L$25,3,FALSE)-딜러사!F28-딜러사!F29 -> 0 | T16: =S16*R4 -> 0
D17: ='금융리스 입력'!E15 -> 0.09 | E17: ='금융리스 입력'!F15 -> 0 | G17: 본부장 수수료 | H17: =IF(D4="브리티시오토",D4,IF(D4="모터원","모터원담당","")) | I17: =IF(D4="브리티시오토",0.2%,IF(D4="모터원",0.2%,0)) -> 0 | J17: =I17*H4 -> 0 | L17: 본부장 수수료 | M17: =IF(D4="브리티시오토",D4,IF(D4="모터원","모터원담당","")) | N17: =IF(D4="브리티시오토",0.2%,IF(D4="모터원",0.2%,0)) -> 0 | O17: =N17*M4 -> 0 | Q17: 본부장 수수료 | R17: =IF(D4="브리티시오토",D4,IF(D4="모터원","모터원담당","")) | S17: =IF(D4="브리티시오토",0.2%,IF(D4="모터원",0.2%,0)) -> 0 | T17: =S17*R4 -> 0
B18: 탁송료 | D18: ='금융리스 입력'!D16:G16 -> 100000 | H18: 토탈수수료 | I18: =(I13+I14+J16+J17)/H4 -> 0 | M18: 토탈수수료 | N18: =(N13+N14+O16+O17)/M4 -> 0 | R18: 토탈수수료 | S18: =(S13+S14+T16+T17)/R4 -> 0
B19: 부대비 | D19: ='금융리스 입력'!D17:G17 -> 100000 | G19: 리스료 | I19: =H39 -> 973900 | L19: 리스료 | N19: =M39 -> 751800 | Q19: 리스료 | S19: =R39 -> 618900
B20: 등록비합산 | D20: ='금융리스 입력'!D18:G18 -> 1345450 | G20: 차세 | I20: =IF('금융리스 입력'!BB10=FALSE,0,'공채&차세'!M50) -> 0 | L20: 차세 | N20: =IF('금융리스 입력'!BB15=FALSE,0,'공채&차세'!M50) -> 0 | Q20: 차세 | S20: =IF('금융리스 입력'!BB20=FALSE,0,'공채&차세'!M50) -> 0
G21: 최종리스료 | I21: =I19+I20 -> 973900 | L21: 최종리스료 | N21: =N19+N20 -> 751800 | Q21: 최종리스료 | S21: =S19+S20 -> 618900
G23: 금리 | H23: =RATE(H3,H39,-H4,I7,0,0.00001)*12 -> 0.060274464 | L23: 금리 | M23: =RATE(M3,M39,-M4,N7,0,0.00001)*12 -> 0.060190193 | Q23: 금리 | R23: =RATE(R3,R39,-R4,S7,0,0.00001)*12 -> 0.060168231
G24: IRR | H24: =VLOOKUP($D$5,브랜드!$B$2:$D$29,3,FALSE) -> 0.06 | L24: IRR | M24: =VLOOKUP($D$5,브랜드!$B$2:$D$29,3,FALSE) -> 0.06 | Q24: IRR | R24: =VLOOKUP($D$5,브랜드!$B$2:$D$29,3,FALSE) -> 0.06
G39: 리스료 | H39: =ROUNDUP(PMT(H24/12,H3,-H4-I13-I14-10000-J16-J17+I11,I7),-2) -> 973900 | L39: 리스료 | M39: =ROUNDUP(PMT(M24/12,M3,-M4-N13-N14-10000-O16-O17+N11,N7),-2) -> 751800 | Q39: 리스료 | R39: =ROUNDUP(PMT(R24/12,R3,-R4-S13-S14-T16-10000-T17+S11,S7),-2) -> 618900

Sheet 할부 견적출력
AW4: ='금융리스 입력'!D2 -> 2025_09_V1
C5: 오 토 할 부 견 적 서 | BQ5: =TODAY() -> 45904
BS6: 담당자 | BW6: ='할부 입력'!D19 -> 메리츠캐피탈 담당자
AZ11: ='할부 입력'!D20 -> VIP 고객님 | BN11: 아래 견적 제안 드립니다.
C12: ▣ 차량정보
C13: 차종 | P13: ='할부 입력'!D4 -> BYD | AC13: ='할부 입력'!D6 -> ATTO 3 | BW13: ='할부 입력'!D7 -> 0
C14: 기본 가격 | P14: ='할부 입력'!D8 -> 39000000 | AP14: 옵션 가격 | BD14: ='할부 입력'!D9 -> 0
C15: 할인 가격 | P15: ='할부 입력'!D10 -> 0 | AP15: 최종 가격 | BD15: ='할부 입력'!D11 -> 39000000
C18: ▣ 등록비용
C19: 등취득세 | P19: ='할부 입력'!D13 -> 1081810 | AC19: 공채비용 | AP19: ='할부 입력'!F15 -> 0 | BD19: 등록비용 총합계 | BR19: ='할부 입력'!D18 -> 1281810
C20: 탁송료 | P20: ='할부 입력'!D16 -> 100000 | AC20: 부대비용 | AP20: ='할부 입력'!D17 -> 100000
C23: ▣ 할부조건
C24: 구분 | R24: 조건 1 | AN24: 조건 2 | BJ24: 조건 3
C25: 이용 금액 | R25: ='할부 입력'!J4 -> 35100000 | AN25: ='할부 입력'!Q4 -> 29000000 | BJ25: ='할부 입력'!X4 -> 31200000
C26: 리스 기간 | R26: ='할부 입력'!J3 -> 36 | AN26: ='할부 입력'!Q3 -> 48 | BJ26: ='할부 입력'!X3 -> 60
C27: 차량 선수금 | R27: ='할부 내부'!H6 -> 0.1 | AA27: ='할부 내부'!I6 -> 3900000 | AN27: ='할부 내부'!M6 -> 0.25641026 | AW27: ='할부 내부'!N6 -> 10000000 | BJ27: ='할부 내부'!R6 -> 0.2 | BS27: ='할부 내부'!S6 -> 7800000
C28: 월 납입금 | R28: ='할부 입력'!J19 -> 1074300 | AN28: ='할부 입력'!Q19 -> 685200 | BJ28: ='할부 입력'!X19 -> 606900
C29: 금리 | R29: ='할부 입력'!J20 -> 0.064073228 | AN29: ='할부 입력'!Q20 -> 0.063103599 | BJ29: ='할부 입력'!X20 -> 0.062557024
C30: 초기 부담금 | R30: =AA27+BR19+R32 -> 5181810 | AN30: =AW27+BR19+AN32 -> 11281810 | BJ30: =BS27+BR19+BJ32 -> 9081810
C31: 차량설정금액 | R31: ='할부 입력'!J21 -> 1 | AA31: ='할부 입력'!J21*'할부 입력'!J4 -> 35100000 | AN31: ='할부 입력'!Q21 -> 1 | AW31: ='할부 입력'!Q21*'할부 입력'!Q4 -> 29000000 | BJ31: ='할부 입력'!X21 -> 1 | BS31: ='할부 입력'!X21*'할부 입력'!X4 -> 31200000
C32: 인지세 | R32: ='할부 입력'!J22 -> 0 | AN32: ='할부 입력'!Q22 -> 0 | BJ32: ='할부 입력'!X22 -> 0
C33: =IF('할부 입력'!BB8=TRUE,"잔존가치",IF('할부 입력'!BB11=TRUE,"잔존가치",IF('할부 입력'!BB14=TRUE,"잔존가치",""))) | R33: ='할부 내부'!H7 -> 0 | AA33: ='할부 내부'!I7 -> 0 | AN33: ='할부 내부'!M7 -> 0 | AW33: ='할부 내부'!N7 -> 0 | BJ33: ='할부 내부'!R7 -> 0 | BS33: ='할부 내부'!S7 -> 0
C35: 입금계좌
C37: ㆍ지방세법 개정에 따라 취득세는 시가표준액으로 인한 차액 발생될 수 있으며, 차액 금액은 고객 별도 부담입니다.
C38: ㆍ과태료, 범칙금, 정비료, 환경개선부담금, 자동차보험료, 자동차세 등은 고객 부담입니다.
C39: ㆍ중도상환 진행 시 일정 수수료가 발생되며, 중도상환시 수수료(미회수원금 * 잔여기간/전체기간 * 2%) 발생합니다.
C40: 서울특별시 영등포구 국제금융로 10, ThreeIFC 23층 메리츠캐피탈 주식회사 / T. 1588-9666 / https://www.meritzcapital.com

Sheet 할부 입력
B2: 할부 견적 | D2: ='운용리스 입력'!D2:G2 -> 2025_09_V1 | F2: 일자 | G2: =TODAY() -> 45904 | I2: 조건1 | P2: 조건2 | W2: 조건3 | BA2: 체크박스
B3: 제휴사 | D3: 기타 | I3: 기간 | J3: 36 | P3: 기간 | Q3: 48 | W3: 기간 | X3: 60 | BA3: 등취득세 | BB3: TRUE
B4: 브랜드 | D4: BYD | I4: 이용금액 | J4: ='할부 내부'!H4 -> 35100000 | P4: 이용금액 | Q4: ='할부 내부'!M4 -> 29000000 | W4: 이용금액 | X4: ='할부 내부'!R4 -> 31200000 | BA4: 공채비용 | BB4: TRUE
B5: 기본 모델 | D5: BYD | BA5: 탁송료 | BB5: TRUE
B6: 세부 모델 | D6: ATTO 3 | I6: 선수금 | J6: 0.1 | L6: =D11*J6 -> 3900000 | P6: 선수금 | Q6: 0.5 | S6: =D11*Q6 -> 19500000 | W6: 선수금 | X6: 0.2 | Z6: =D11*X6 -> 7800000 | BA6: 부대비용 | BB6: TRUE
B7: 배기량 | D7: ='할부 내부'!D8:E8 -> 0 | I7: =IF(BB7=TRUE,"% 입력","금액 입력") -> % 입력 | J7: =L7/D11 -> 0.25641026 | L7: 10000000 | P7: =IF(BB10=TRUE,"% 입력","금액 입력") -> 금액 입력 | Q7: =S7/D11 -> 0.25641026 | S7: 10000000 | W7: =IF(BB13=TRUE,"% 입력","금액 입력") -> % 입력 | X7: =Z7/D11 -> 0.76923077 | Z7: 30000000 | BA7: 선수금1 | BB7: TRUE
B8: 차량 가격 | D8: 39000000 | BA8: 잔가1 | BB8: FALSE | BC8: FALSE
B9: 옵션 가격 | D9: 0 | I9: 잔가 | J9: 0.15 | L9: =D11*J9 -> 5850000 | P9: 잔가 | Q9: 0.2 | S9: =D11*Q9 -> 7800000 | W9: 잔가 | X9: 0.3 | Z9: =D11*X9 -> 11700000 | BA9: 잔가1-1 | BB9: FALSE
B10: 할인 가격 | D10: 0 | I10: =IF(BB9=TRUE,"% 입력","금액 입력") -> 금액 입력 | J10: =L10/D11 -> 0.25641026 | L10: 10000000 | P10: =IF(BB12=TRUE,"% 입력","금액 입력") -> 금액 입력 | Q10: =S10/D11 -> 0.76923077 | S10: 30000000 | W10: =IF(BB15=TRUE,"% 입력","금액 입력") -> 금액 입력 | X10: =Z10/D11 -> 0.76923077 | Z10: 30000000 | BA10: 선수금2 | BB10: FALSE
B11: 차량가 최종 | D11: =D8+D9-D10 -> 39000000 | I11: 잔가 최대 | J11: ='할부 내부'!H8 -> 0.3 | L11: ='할부 내부'!I8 -> 11700000 | P11: 잔가 최대 | Q11: ='할부 내부'!M8 -> 0.2 | S11: ='할부 내부'!N8 -> 7800000 | W11: 잔가 최대 | X11: ='할부 내부'!R8 -> 0.15 | Z11: ='할부 내부'!S8 -> 5850000 | BA11: 잔가2 | BB11: FALSE | BC11: FALSE
BA12: 잔가2-2 | BB12: FALSE
B13: 등록비용 | D13: =취득세!I6 -> 1081810 | I13: 이손금 | J13: 0 | P13: 이손금 | Q13: 0 | W13: 이손금 | X13: 0 | BA13: 선수금3 | BB13: TRUE
B14: 공채비용 | D14: 공채지역 | E14: 서울 | BA14: 잔가3 | BB14: FALSE | BC14: FALSE
D15: 공채할인 | E15: 0.09 | F15: ='공채&차세'!X4 -> 0 | I15: 수수료 Max | J15: ='할부 내부'!I12 -> 0.0225 | P15: 수수료 Max | Q15: ='할부 내부'!N12 -> 0.0225 | W15: 수수료 Max | X15: ='할부 내부'!S12 -> 0.0225 | BA15: 잔가3-3 | BB15: FALSE
B16: 탁송료 | D16: 100000 | I16: CM수수료 | J16: 0 | L16: ='할부 내부'!I13 -> 0 | P16: CM수수료 | Q16: 0 | S16: ='할부 내부'!N13 -> 0 | W16: CM수수료 | X16: 0 | Z16: ='할부 내부'!S13 -> 0
B17: 부대비용 | D17: 100000 | I17: AG수수료 | J17: 0 | L17: ='할부 내부'!I14 -> 0 | P17: AG수수료 | Q17: 0 | S17: ='할부 내부'!N14 -> 0 | W17: AG수수료 | X17: 0 | Z17: ='할부 내부'!S14 -> 0
B18: 등록비용 합산 | D18: =SUM(D13+F15+D16+D17) -> 1281810
B19: 담당자 | D19: 메리츠캐피탈 담당자 | I19: 할부금 | J19: =IF(J4<20000000,"20,000,000 이하 불가",'할부 내부'!H25) -> 1074300 | P19: 할부금 | Q19: =IF(Q4<20000000,"20,000,000 이하 불가",'할부 내부'!M25) -> 685200 | W19: 할부금 | X19: =IF(X4<20000000,"20,000,000 이하 불가",'할부 내부'!R25) -> 606900
B20: 고객명 | D20: VIP 고객님 | I20: 금리 | J20: ='할부 내부'!H21 -> 0.064073228 | P20: 금리 | Q20: ='할부 내부'!M21 -> 0.063103599 | W20: 금리 | X20: ='할부 내부'!R21 -> 0.062557024
C21: 노란색 부분만 입력하면 됩니다. | I21: 설정율 | J21: 1 | P21: 설정율 | Q21: 1 | W21: 설정율 | X21: 1
C22: 체크 선택시 입력값 변동 됩니다. | I22: 인지세 | J22: ='할부 내부'!I16 -> 0 | P22: 인지세 | Q22: ='할부 내부'!N16 -> 0 | W22: 인지세 | X22: ='할부 내부'!S16 -> 0

Sheet 할부 내부
G2: 조건1 | L2: 조건2 | Q2: 조건3
B3: ='운용리스 입력'!D2 -> 2025_09_V1 | D3: 견적일자 | E3: =TODAY() -> 45904 | G3: 기간 | H3: ='할부 입력'!J3 -> 36 | L3: 기간 | M3: ='할부 입력'!Q3 -> 48 | Q3: 기간 | R3: ='할부 입력'!X3 -> 60
B4: 제휴사 | D4: ='할부 입력'!D3 -> 기타 | G4: 이용금액 | H4: =IF('할부 입력'!BB7=TRUE,D13-H6*D13,D13-I6) -> 35100000 | L4: 이용금액 | M4: =IF('할부 입력'!BB10=TRUE,D13-M6*D13,D13-N6) -> 29000000 | Q4: 이용금액 | R4: =IF('할부 입력'!BB13=TRUE,D13-R6*D13,D13-S6) -> 31200000
B5: 브랜드 | D5: ='할부 입력'!D4 -> BYD
B6: 기본모델 | D6: ='할부 입력'!D5 -> BYD | G6: 선수금 | H6: =IF('할부 입력'!BB7=TRUE,'할부 입력'!J6,'할부 입력'!L7/'할부 입력'!D11) -> 0.1 | I6: =IF('할부 입력'!BB7=FALSE,'할부 입력'!L7,D13*H6) -> 3900000 | L6: 선수금 | M6: =IF('할부 입력'!BB10=TRUE,'할부 입력'!Q6,'할부 입력'!S7/'할부 입력'!D11) -> 0.25641026 | N6: =IF('할부 입력'!BB10=FALSE,'할부 입력'!S7,D13*M6) -> 10000000 | Q6: 선수금 | R6: =IF('할부 입력'!BB13=TRUE,'할부 입력'!X6,'할부 입력'!Z7/'할부 입력'!D11) -> 0.2 | S6: =IF('할부 입력'!BB13=FALSE,'할부 입력'!Z7,D13*R6) -> 7800000
B7: 세부모델 | D7: ='할부 입력'!D6 -> ATTO 3 | G7: 잔가최종 | H7: =IF('할부 입력'!BB8=TRUE,'할부 내부'!H9,0) -> 0 | I7: =IF('할부 입력'!BB8=TRUE,'할부 내부'!I9,0) -> 0 | L7: 잔가최종 | M7: =IF('할부 입력'!BB11=TRUE,'할부 내부'!M9,0) -> 0 | N7: =IF('할부 입력'!BB11=TRUE,'할부 내부'!N9,0) -> 0 | Q7: 잔가최종 | R7: =IF('할부 입력'!BB14=TRUE,'할부 내부'!R9,0) -> 0 | S7: =IF('할부 입력'!BB14=TRUE,'할부 내부'!S9,0) -> 0
B8: 배기량 | D8: =VLOOKUP($D$7,차종!E7:G1310,3,FALSE) -> 0 | G8: 잔가최대 | H8: =VLOOKUP(H3,잔가!J41:K45,2,0) -> 0.3 | I8: =D13*H8 -> 11700000 | L8: 잔가최대 | M8: =VLOOKUP(M3,잔가!J41:K45,2,0) -> 0.2 | N8: =$D$13*M8 -> 7800000 | Q8: 잔가최대 | R8: =VLOOKUP(R3,잔가!J41:K45,2,0) -> 0.15 | S8: =$D$13*R8 -> 5850000
G9: 잔가2 | H9: =IF('할부 입력'!BB9=TRUE,'할부 입력'!J9,'할부 입력'!L10/'할부 입력'!D11) -> 0.25641026 | I9: =IF('할부 입력'!BB9=FALSE,'할부 입력'!L7,D13*H9) -> 10000000 | L9: 잔가2 | M9: =IF('할부 입력'!BB12=TRUE,'할부 입력'!Q9,'할부 입력'!S10/'할부 입력'!D11) -> 0.76923077 | N9: =IF('할부 입력'!BB12=FALSE,'할부 입력'!S7,D13*M9) -> 10000000 | Q9: 잔가2 | R9: =IF('할부 입력'!BB15=TRUE,'할부 입력'!X9,'할부 입력'!Z10/'할부 입력'!D11) -> 0.76923077 | S9: =IF('할부 입력'!BB15=FALSE,'할부 입력'!Z7,D13*R9) -> 30000000
B10: 차량가 | D10: ='할부 입력'!D8 -> 39000000
B11: 옵션 | D11: ='할부 입력'!D9 -> 0 | G11: 이손금 | I11: ='금융리스 입력'!J13 -> 0 | L11: 이손금 | N11: ='금융리스 입력'!Q13 -> 0 | Q11: 이손금 | S11: ='금융리스 입력'!X13 -> 0
B12: 할인가 | D12: ='할부 입력'!D10 -> 0 | H12: CM/AG 최대 | I12: =IF((I13+I14+J17+J18+I15)/H4>2.25%,"수수료 초과",2.25%-(J17+J18+I15)/H4) -> 0.0225 | M12: CM/AG 최대 | N12: =IF((N13+N14+O17+O18+N15)/M4>2.25%,"수수료 초과",2.25%-(O17+O18+N15)/M4) -> 0.0225 | R12: CM/AG 최대 | S12: =IF((S13+S14+T17+T18+S15)/R4>2.25%,"수수료 초과",2.25%-(T17+T18+S15)/R4) -> 0.0225
B13: 차량가최종 | D13: ='할부 입력'!D11 -> 39000000 | G13: CM수수료 | H13: ='할부 입력'!J16 -> 0 | I13: =ROUNDDOWN((H13*$H$4),-1) -> 0 | L13: CM수수료 | M13: ='할부 입력'!Q16 -> 0 | N13: =ROUNDDOWN((M13*$M$4),-1) -> 0 | Q13: CM수수료 | R13: ='할부 입력'!X16 -> 0 | S13: =ROUNDDOWN((R13*$R$4),-1) -> 0
G14: AG수수료 | H14: ='할부 입력'!J17 -> 0 | I14: =ROUNDDOWN((H14*$H$4),-1) -> 0 | L14: AG수수료 | M14: ='할부 입력'!Q17 -> 0 | N14: =ROUNDDOWN((M14*$M$4),-1) -> 0 | Q14: AG수수료 | R14: ='할부 입력'!X17 -> 0 | S14: =ROUNDDOWN((R14*$R$4),-1) -> 0
B15: 등취득세 | D15: ='할부 입력'!D13 -> 1081810 | G15: 잔가보장수수료 | I15: 0 | L15: 잔가보장수수료 | N15: 0 | Q15: 잔가보장수수료 | S15: 0
B16: 공채 | D16: ='할부 입력'!E14 -> 서울 | G16: 인지세 | I16: =IF(H4<100000001,IF(H4<50000001,0,35000),75000) -> 0 | L16: 인지세 | N16: =IF(M4<100000001,IF(M4<50000001,0,35000),75000) -> 0 | Q16: 인지세 | S16: =IF(R4<100000001,IF(R4<50000001,0,35000),75000) -> 0
D17: ='할부 입력'!E15 -> 0.09 | E17: ='할부 입력'!F15 -> 0 | G17: 제휴사 수수료 | H17: =$D$4 -> 기타 | I17: =VLOOKUP($D$4,딜러사!$J$6:$L$25,3,FALSE)-딜러사!G28-딜러사!G29 -> 0 | J17: =ROUNDDOWN((I17*H4),-1) -> 0 | L17: 제휴사 수수료 | M17: =$D$4 -> 기타 | N17: =VLOOKUP($D$4,딜러사!$J$6:$L$25,3,FALSE)-딜러사!G28-딜러사!G29 -> 0 | O17: =ROUNDDOWN((N17*M4),-1) -> 0 | Q17: 제휴사 수수료 | R17: =$D$4 -> 기타 | S17: =VLOOKUP($D$4,딜러사!$J$6:$L$25,3,FALSE)-딜러사!G28-딜러사!G29 -> 0 | T17: =ROUNDDOWN((S17*R4),-1) -> 0
B18: 탁송료 | D18: ='할부 입력'!D16:G16 -> 100000 | G18: 본부장 수수료 | H18: =IF(D4="브리티시오토",D4,IF(D4="모터원","모터원담당","")) | I18: =IF(D4="브리티시오토",0.2%,IF(D4="모터원",0.2%,0)) -> 0 | J18: =ROUNDDOWN((I18*H4),-1) -> 0 | L18: 본부장 수수료 | M18: =IF(D4="브리티시오토",D4,IF(D4="모터원","모터원담당","")) | N18: =IF(D4="브리티시오토",0.2%,IF(D4="모터원",0.2%,0)) -> 0 | O18: =ROUNDDOWN((N18*M4),-1) -> 0 | Q18: 본부장 수수료 | R18: =IF(D4="브리티시오토",D4,IF(D4="모터원","모터원담당","")) | S18: =IF(D4="브리티시오토",0.2%,IF(D4="모터원",0.2%,0)) -> 0 | T18: =ROUNDDOWN((S18*R4),-1) -> 0
B19: 부대비 | D19: ='할부 입력'!D17:G17 -> 100000 | H19: 토탈수수료 | I19: =(I13+I14+J17+J18)/H4 -> 0 | M19: 토탈수수료 | N19: =(N13+N14+O17+O18)/M4 -> 0 | R19: 토탈수수료 | S19: =(S13+S14+T17+T18)/R4 -> 0
B20: 등록비합산 | D20: ='할부 입력'!D18:G18 -> 1281810 | G20: 할부금 | I20: =H25 -> 1074300 | L20: 할부금 | N20: =M25 -> 685200 | Q20: 할부금 | S20: =R25 -> 606900
G21: 금리 | H21: =RATE(H3,H25,-H4,I7,0,0.00001)*12 -> 0.064073228 | L21: 금리 | M21: =RATE(M3,M25,-M4,N7,0,0.00001)*12 -> 0.063103599 | Q21: 금리 | R21: =RATE(R3,R25,-R4,S7,0,0.00001)*12 -> 0.062557024
G22: IRR | H22: =VLOOKUP($D$5,브랜드!$B$2:$E$29,4,FALSE) -> 0.06 | L22: IRR | M22: =VLOOKUP($D$5,브랜드!$B$2:$E$29,4,FALSE) -> 0.06 | Q22: IRR | R22: =VLOOKUP($D$5,브랜드!$B$2:$E$29,4,FALSE) -> 0.06
G23: 설정율 | H23: ='할부 입력'!J21 -> 1 | I23: =H4*0.6%*H23 -> 210600 | L23: 설정율 | M23: ='할부 입력'!Q21 -> 1 | N23: =M4*0.6%*M23 -> 174000 | Q23: 설정율 | R23: ='할부 입력'!X21 -> 1 | S23: =R4*0.6%*R23 -> 187200
G25: 할부금 | H25: =ROUNDUP(PMT(H22/12,H3,-H4-I13-I14-I16-I15-I23-J17-J18+I11,I7),-2) -> 1074300 | L25: 할부금 | M25: =ROUNDUP(PMT(M22/12,M3,-M4-N13-N14-N16-N15-N23-O17-O18+N11,N7),-2) -> 685200 | Q25: 할부금 | R25: =ROUNDUP(PMT(R22/12,R3,-R4-S13-S14-S16-S15-S23-T17-T18+S11,S7),-2) -> 606900

Sheet 브랜드
B1: 브랜드 | C1: 운용 | D1: 금융 | E1: 할부
B2: Audi | C2: 0.0505 | D2: 0.058 | E2: 0.058 | G2: Audi | H2: A3 | I2: BMW | J2: 1_series | K2: Ford | L2: Mustang | M2: Landrover | N2: Defender | O2: Peugeot | P2: 208 | Q2: Volkswagen | R2: Jetta | S2: Astonmartine | T2: Vantage
B3: Benz | C3: 0.0505 | D3: 0.055 | E3: 0.055 | G3: Audi | H3: A4 | I3: BMW | J3: 2_series | K3: Ford | L3: Explorer | M3: Landrover | N3: Discovery | O3: Peugeot | P3: 308 | Q3: Volkswagen | R3: Arteon | S3: Astonmartine | T3: DB11
B4: BMW | C4: 0.0505 | D4: 0.055 | E4: 0.055 | G4: Audi | H4: A5 | I4: BMW | J4: 3_series | K4: Ford | L4: Expedition | M4: Landrover | N4: Range_Rover_Evoque | O4: Peugeot | P4: 408 | Q4: Volkswagen | R4: Tiguan | S4: Astonmartine | T4: DBS_Superleggera
B5: Cadillac | C5: 0.054 | D5: 0.054 | E5: 0.054 | G5: Audi | H5: A6 | I5: BMW | J5: 4_series | K5: Ford | L5: Bronco | M5: Landrover | N5: Range_Rover_Velar | O5: Peugeot | P5: 508 | Q5: Volkswagen | R5: Touareg | S5: Astonmartine | T5: Rapide_S
B6: Citroen | C6: 0.058 | D6: 0.06 | E6: 0.06 | G6: Audi | H6: A7 | I6: BMW | J6: 5_series | K6: Ford | L6: Corsair | M6: Landrover | N6: Range_Rover_Sport | O6: Peugeot | P6: 2008 | Q6: Volkswagen | R6: T_Roc | S6: Astonmartine | T6: DBX
B7: Ford | C7: 0.058 | D7: 0.06 | E7: 0.06 | G7: Audi | H7: A8 | I7: BMW | J7: 6_series | K7: Ford | L7: MKZ | M7: Landrover | N7: Range_Rover | O7: Peugeot | P7: 3008 | Q7: Volkswagen | R7: Passat
B8: Honda | C8: 0.058 | D8: 0.06 | E8: 0.06 | G8: Audi | H8: Q2 | I8: BMW | J8: 7_series | K8: Ford | L8: Continental | O8: Peugeot | P8: 5008 | Q8: Volkswagen | R8: ID.3
B9: Jaguar | C9: 0.058 | D9: 0.06 | E9: 0.06 | G9: Audi | H9: Q3 | I9: BMW | J9: 8_series | K9: Ford | L9: Navigator | Q9: Volkswagen | R9: Golf | S9: Bentley | T9: Bentayga
B10: Jeep | C10: 0.058 | D10: 0.06 | E10: 0.06 | G10: Audi | H10: Q4 | I10: BMW | J10: X1 | K10: Ford | L10: Mondeo | Q10: Volkswagen | R10: T_Cross | S10: Bentley | T10: FlyingSpur
B11: Landrover | C11: 0.054 | D11: 0.054 | E11: 0.054 | G11: Audi | H11: Q5 | I11: BMW | J11: X2 | K11: Ford | L11: Nautilus | M11: Lexus | N11: CT | O11: Porsche | P11: 718 | Q11: Volkswagen | R11: ID.4 | S11: Bentley | T11: Continental
B12: Lexus | C12: 0.058 | D12: 0.06 | E12: 0.06 | G12: Audi | H12: Q6 | I12: BMW | J12: X3 | K12: Ford | L12: Aviator | M12: Lexus | N12: IS | O12: Porsche | P12: 911 | Q12: Volkswagen | R12: Teramont | S12: Bentley | T12: Mulsanne
B13: Maserati | C13: 0.058 | D13: 0.06 | E13: 0.06 | G13: Audi | H13: Q7 | I13: BMW | J13: X4 | K13: Ford | L13: Ranger | M13: Lexus | N13: ES | O13: Porsche | P13: Panamera | Q13: Volkswagen | R13: ID.ROOMZZ
B14: Mini | C14: 0.058 | D14: 0.06 | E14: 0.06 | G14: Audi | H14: Q8 | I14: BMW | J14: X5 | M14: Lexus | N14: GS | O14: Porsche | P14: Taycan | Q14: Volkswagen | R14: ID.5
B15: Peugeot | C15: 0.058 | D15: 0.06 | E15: 0.06 | G15: Audi | H15: e_tron | I15: BMW | J15: X6 | M15: Lexus | N15: LS | O15: Porsche | P15: Macan | Q15: Volkswagen | R15: Atlas | S15: Ferrari | T15: 488
B16: Polestar | C16: 0.075 | D16: 0.075 | E16: 0.075 | G16: Audi | H16: R8 | I16: BMW | J16: X7 | K16: Honda | L16: Accord | M16: Lexus | N16: RC | O16: Porsche | P16: MacanEV | S16: Ferrari | T16: 812
B17: Porsche | C17: 0.0505 | D17: 0.054 | E17: 0.054 | I17: BMW | J17: M | K17: Honda | L17: Civic | M17: Lexus | N17: LC | O17: Porsche | P17: Cayenne | S17: Ferrari | T17: 296
B18: Tesla | C18: 0.058 | D18: 0.06 | E18: 0.06 | I18: BMW | J18: i | K18: Honda | L18: CR_V | M18: Lexus | N18: UX | S18: Ferrari | T18: F8
B19: Toyota | C19: 0.058 | D19: 0.06 | E19: 0.06 | I19: BMW | J19: Z | K19: Honda | L19: HR_V | M19: Lexus | N19: NX | O19: Tesla | P19: Model_S | Q19: Volvo | R19: S60 | S19: Ferrari | T19: GTC4
B20: Volkswagen | C20: 0.058 | D20: 0.06 | E20: 0.06 | K20: Honda | L20: Odyssey | M20: Lexus | N20: RX | O20: Tesla | P20: Model_X | Q20: Volvo | R20: S90 | S20: Ferrari | T20: Portofino
B21: Volvo | C21: 0.0505 | D21: 0.054 | E21: 0.054 | G21: Benz | H21: A_class | K21: Honda | L21: Pilot | M21: Lexus | N21: RZ | Q21: Volvo | R21: V40 | S21: Ferrari | T21: Roma
B22: BYD | C22: X | D22: 0.06 | E22: 0.06 | G22: Benz | H22: C_class | I22: Cadillac | J22: CT4 | M22: Lexus | N22: LM | Q22: Volvo | R22: V60 | S22: Ferrari | T22: SF90
G23: Benz | H23: E_class | I23: Cadillac | J23: CT5 | M23: Lexus | N23: LX | O23: Toyota | P23: 86 | Q23: Volvo | R23: V90
B24: Astonmartine | C24: 0 | D24: 0 | E24: 0 | G24: Benz | H24: S_class | I24: Cadillac | J24: CT6 | K24: Jaguar | L24: E_Pace | O24: Toyota | P24: Avalon | Q24: Volvo | R24: XC40
B25: Bentley | C25: 0 | D25: 0 | E25: 0 | G25: Benz | H25: CLA | I25: Cadillac | J25: XT4 | K25: Jaguar | L25: F_Pace | M25: Maserati | N25: Ghibli | O25: Toyota | P25: Camry | Q25: Volvo | R25: XC60 | S25: Lamborghini | T25: Aventador
B26: Ferrari | C26: 0 | D26: 0 | E26: 0 | G26: Benz | H26: CLE | I26: Cadillac | J26: XT5 | K26: Jaguar | L26: F_Type | M26: Maserati | N26: Quattroporte | O26: Toyota | P26: Crown | Q26: Volvo | R26: XC90 | S26: Lamborghini | T26: HuracanEVO
B27: Lamborghini | C27: 0 | D27: 0 | E27: 0 | G27: Benz | H27: CLS | I27: Cadillac | J27: XT6 | K27: Jaguar | L27: I_Pace | M27: Maserati | N27: Levante | O27: Toyota | P27: Prius | Q27: Volvo | R27: C40 | S27: Lamborghini | T27: Urus
B28: Mclaren | C28: 0 | D28: 0 | E28: 0 | G28: Benz | H28: GLA | I28: Cadillac | J28: Lyriq | K28: Jaguar | L28: XE | M28: Maserati | N28: Grecale | O28: Toyota | P28: GR | Q28: Volvo | R28: EX30
B29: Rollsroyce | C29: 0 | D29: 0 | E29: 0 | G29: Benz | H29: GLB | I29: Cadillac | J29: Escalade | K29: Jaguar | L29: XF | M29: Maserati | N29: GranTurismo | O29: Toyota | P29: RAV4 | Q29: Volvo | R29: EX40
G30: Benz | H30: GLC | K30: Jaguar | L30: XJ | M30: Maserati | N30: GranCabrio | O30: Toyota | P30: Sienna | S30: Mclaren | T30: 570S
G31: Benz | H31: GLE | M31: Maserati | N31: MC20 | O31: Toyota | P31: Alphard | Q31: Polestar | R31: 2 | S31: Mclaren | T31: 570GT
B32: 저보증금 10% 미만 | C32: 0.002 | G32: Benz | H32: GLS | I32: Citroen | J32: Citroen | R32: 4 | S32: Mclaren | T32: 600LT
B33: 40%이상 | C33: 0 | G33: Benz | H33: G | K33: Jeep | L33: Cherokee | S33: Mclaren | T33: 720S
B34: 45%이상 | C34: 0 | G34: Benz | H34: GT | K34: Jeep | L34: Compass | M34: Mini | N34: Clubman | O34: BYD | P34: BYD | S34: Mclaren | T34: 765LT
B35: 50%이상 | C35: 0.005 | G35: Benz | H35: EQA | K35: Jeep | L35: Renegade | M35: Mini | N35: Hatch | S35: Mclaren | T35: GT
B36: 60%이상 | C36: 0.005 | G36: Benz | H36: EQB | K36: Jeep | L36: Wrangler | M36: Mini | N36: Countryman | S36: Mclaren | T36: Artura
B37: 65%이상 | C37: 0.005 | G37: Benz | H37: EQC | K37: Jeep | L37: Gladiator | M37: Mini | N37: Convertible
B38: 23MY | C38: 0.003 | G38: Benz | H38: EQE | K38: Jeep | L38: Avenger | M38: Mini | N38: Aceman
B39: ='운용리스 입력'!D5&'운용리스 입력'!D6 -> Audie_tron | G39: Benz | H39: EQS | M39: Mini | N39: Electric | S39: Rollsroyce | T39: Cullinan
B40: ='금융리스 입력'!D4&'금융리스 입력'!D5 -> BYDBYD | G40: Benz | H40: SL | S40: Rollsroyce | T40: Dawn
...

Sheet 차종
E3: =VLOOKUP($D$7,차종!E7:G1145,3,FALSE) -> #N/A
E5: 1 | F5: 2 | G5: 3 | H5: 4 | I5: 5 | J5: 6 | K5: 7 | L5: 8 | M5: 9 | N5: 10 | O5: 11 | P5: 12 | Q5: 13
B6: Maker | C6: Model1 | D6: Moder2 | E6: Model3 | F6: 차량가격(원) | G6: 배기량(cc) | H6: 유종 | I6: 취득세 | J6: 웨스트 | K6: 오토준 | L6: APS | M6: VGS | N6: 공채 | O6: 고잔가 여부 | P6: 고잔가추가 15,000 | Q6: 고잔가추가1 10,000 | ZU6: 만든이 박성훈 1989.02.28
B7: Audi | C7: A3 | D7: =+B7&C7 -> AudiA3 | E7: A3 40 TFSI | F7: 41600000 | G7: 1984 | H7: 가솔린 | I7: 승용 | J7: B | L7: K | N7: 승용
B8: Audi | C8: A3 | D8: =+B8&C8 -> AudiA3 | E8: A3 40 TFSI Premium | F8: 45600000 | G8: 1984 | H8: 가솔린 | I8: 승용 | J8: B | L8: K | N8: 승용
B9: Audi | C9: A3 | D9: =+B9&C9 -> AudiA3 | E9: S3 TFSI | F9: 59640000 | G9: 1984 | H9: 가솔린 | I9: 승용 | J9: E | L9: L | N9: 승용
B10: Audi | C10: A3 | D10: =+B10&C10 -> AudiA3 | E10: RS3 Quattro | F10: 76950000 | G10: 2480 | H10: 가솔린 | I10: 승용 | J10: I | L10: T | N10: 승용
B11: Audi | C11: A4 | D11: =+B11&C11 -> AudiA4 | E11: A4 35 TDI | F11: 51318000 | G11: 1968 | H11: 디젤 | I11: 승용 | J11: B | L11: K | N11: 승용
B12: Audi | C12: A4 | D12: =+B12&C12 -> AudiA4 | E12: A4 35 TDI Premium | F12: 59550000 | G12: 1968 | H12: 디젤 | I12: 승용 | J12: B | L12: K | N12: 승용
B13: Audi | C13: A4 | D13: =+B13&C13 -> AudiA4 | E13: A4 40 TDI Qu. Premium | F13: 65440000 | G13: 1968 | H13: 디젤 | I13: 승용 | J13: B | L13: K | N13: 승용
B14: Audi | C14: A4 | D14: =+B14&C14 -> AudiA4 | E14: A4 40 TFSI | F14: 53170000 | G14: 1984 | H14: 가솔린 | I14: 승용 | J14: B | L14: K | N14: 승용
B15: Audi | C15: A4 | D15: =+B15&C15 -> AudiA4 | E15: A4 40 TFSI Premium | F15: 58570000 | G15: 1984 | H15: 가솔린 | I15: 승용 | J15: B | L15: K | N15: 승용
B16: Audi | C16: A4 | D16: =+B16&C16 -> AudiA4 | E16: A4 45 TFSI Qu. Premium | F16: 65930000 | G16: 1984 | H16: 가솔린 | I16: 승용 | J16: B | L16: K | N16: 승용
B17: Audi | C17: A4 | D17: =+B17&C17 -> AudiA4 | E17: S4 TFSI | F17: 81830000 | G17: 2995 | H17: 가솔린 | I17: 승용 | J17: E | L17: L | N17: 승용
B18: Audi | C18: A5 | D18: =+B18&C18 -> AudiA5 | E18: A5 35 TDI Premium Sportback | F18: 60940000 | G18: 1968 | H18: 디젤 | I18: 승용 | J18: B | L18: K | N18: 승용
... B81: Audi | C81: Q5 | D81: =+B81&C81 -> AudiQ5 | E81: SQ5 TFSI Sportback | F81: 95580000 | G81: 2995 | H81: 가솔린 | I81: RV(5인이하) | J81: D | L81: L | N81: RV(5인이하)
B82: Audi | C82: Q6 | D82: =+B82&C82 -> AudiQ6 | E82: Q6 e-tron Performance | F82: 82900000 | G82: 0 | H82: 전기 | I82: 전기 | L82: K | N82: RV(5인이하)
B83: Audi | C83: Q6 | D83: =+B83&C83 -> AudiQ6 | E83: Q6 e-tron Performance Premium | F83: 89900000 | G83: 0 | H83: 전기 | I83: 전기 | L83: K | N83: RV(5인이하)
B84: Audi | C84: Q6 | D84: =+B84&C84 -> AudiQ6 | E84: Q6 e-tron Qu. Performance | F84: 106900000 | G84: 0 | H84: 전기 | I84: 전기 | L84: K | N84: RV(5인이하)
B85: Audi | C85: Q6 | D85: =+B85&C85 -> AudiQ6 | E85: SQ6 e-tron | F85: 115900000 | G85: 0 | H85: 전기 | I85: 전기 | L85: L | N85: RV(5인이하)
B86: Audi | C86: Q7 | D86: =+B86&C86 -> AudiQ7 | E86: Q7 45 TDI Qu. | F86: 98970000 | G86: 2967 | H86: 디젤 | I86: RV(5인이하) | J86: D | K86: F | L86: H | N86: RV(7-10인)
B87: Audi | C87: Q7 | D87: =+B87&C87 -> AudiQ7 | E87: Q7 45 TDI Qu. Premium | F87: 104720000 | G87: 2967 | H87: 디젤 | I87: RV(5인이하) | J87: D | K87: F | L87: H | N87: RV(7-10인)
B88: Audi | C88: Q7 | D88: =+B88&C88 -> AudiQ7 | E88: Q7 50 TDI Qu. | F88: 118600000 | G88: 2967 | H88: 디젤 | I88: RV(5인이하) | J88: D | K88: F | L88: H | N88: RV(7-10인)
B89: Audi | C89: Q7 | D89: =+B89&C89 -> AudiQ7 | E89: Q7 50 TDI Qu. Premium | F89: 124000000 | G89: 2967 | H89: 디젤 | I89: RV(5인이하) | J89: D | K89: F | L89: H | N89: RV(7-10인)
