Workbook
Name ASTON_MARTIN: 차량DB!$F$626:$F$631
Name Audi: 차량DB!$F$6:$F$89
Name Audi_잔가보장: #REF!
Name Bentley: 차량DB!$F$220:$F$224
Name Benz: 차량DB!$F$391:$F$477
Name BMW: 차량DB!$F$90:$F$219
Name Brand: 견적관리자용!$E$9:$E$33
Name Cadillac: 차량DB!$F$225:$F$237
Name Chevrolet: 차량DB!$F$455:$F$457
Name Citroen: 차량DB!$F$385:$F$389
Name Ferrari: 차량DB!$F$238:$F$240
Name Ford: 차량DB!$F$243:$F$252
Name Honda: 차량DB!$F$253:$F$260
Name Jaguar_Landrover: 차량DB!$F$261:$F$307
Name Jeep: 차량DB!$F$308:$F$328
Name Lamborghini: 차량DB!$F$330:$F$337
Name Lexus: 차량DB!$F$338:$F$361
Name Lincoln: 차량DB!$F$363:$F$370
Name Maserati: 차량DB!$F$371:$F$390
Name McLaren: 차량DB!$F$632:$F$634
Name MINI: 차량DB!$F$478:$F$506
Name Peugeot: 차량DB!$F$509:$F$525
Name Porsche: 차량DB!$F$529:$F$578
Name Rolls_Royce: 차량DB!$F$655
Name Tesla: 차량DB!$F$579:$F$585
Name Toyota: 차량DB!$F$588:$F$603
Name Volkswagen: 차량DB!$F$604:$F$625
Name Volvo: 차량DB!$F$635:$F$654
Name 병행수입: 차량DB!#REF!
Name 부가서비스: 견적관리자용!$L$25:$L$27
Name 약정주행거리: 견적관리자용!$O$43:$O$45
Name 제휴사: 견적관리자용!$F$54:$F$55
Name 제휴사_Audi: 견적관리자용!$F$58:$F$61
Name 제휴사_vw: 견적관리자용!$F$62:$F$64
Name 제휴사_잔가보장: 견적관리자용!$F$54:$F$61
Name 주행거리_보장: 견적관리자용!$O$42:$O$45
Name 차종구분: 견적관리자용!$S$8:$S$17
Name 차종구분10: [1]견적관리자용!$S$8:$S$17
Name 차종구분2: [2]견적관리자용!$S$8:$S$17
Name 차종구분3: [3]견적관리자용!$S$8:$S$17
Name 프로모브랜드: 잔가map!#REF!

Sheet 에이전트수수료입력

Sheet 펀딩신청서
B4: 운용리스 펀딩 신청서
C8: 모집 법인 소속 | Q8: ㈜겟차
C9: 모집인 | E9: □ 이름 | H9: □ 연락처 | Q9: 주식회사 리렌컴퍼니
C10: 고객명 | Q10: 주식회사 모딜카
C11: 결제일 / 이메일 | E11: □ 결제일 | H11: □ E-mail | Q11: 주식회사 성문네트웍스
C12: 차종 | Q12: 주식회사 슈어카
C13: 차량 상세 옵션 | Q13: 주식회사 스마트다이렉트카
C14: 외장색 | Q14: 주식회사 스타오토모빌
C15: 내장색 | Q15: 주식회사 시현신차장기렌터카
C16: 총 차량 가격 (세금계산서 금액 VAT포함) / 세금계산서 금액(VAT포함) 과 동일 해야함 | Q16: 주식회사 씨에스카
J17: 원 (VAT 포함) | Q17: 주식회사 에스아이그룹
C18: 보증금 / 선수금 | E18: □ 당사 입금 | H18: □ 차감 지급 | Q18: 주식회사 에이원오토
C19: 송금시 표기 (EX : 엠지캐김영태 / 김영태 / 엠지캐피탈 / 최대 7글자까지만 설정 가능) | Q19: 주식회사 엘리더
Q20: 주식회사 오토다이렉트카
Q21: 주식회사 카베이
B22: 전자 약정 (개인/개인사업자) 만 진행 가능 전자 약정 진행건도 유입경로 확인서 작성 필수 | Q22: 주식회사 카이엠
Q23: 주식회사 트리플에이네트웍스
Q24: 차봇모빌리티 주식회사

Sheet 운용리스
X2: =IF($BD$30>$BP$30,"CM수수료율 상한 확인필요","") | DM2: ■ 펀딩시 꼭 확인후 접수 바랍니다 ① 차량 가격 (딜러사 확인 필수,VAT포함된 세금계산서 발행금액) ② 기타 부대비용 입력불가 ③ 탁송료 (세금계산서 발행할수 있는 금액만 입력) ④ 펀딩신청서 및 유입경로 확인서 징구 필수 ⑤ 최대 담보율은 40% (보증금+선수금) 추가 입력건은 담당자와 별도 협의 ⑥ 모집인 당사 등록여부 필수 확인 ⑦ KCC오토 취급건은 추가 수수료 지급 불가 ⑧ 등록은 "함안" 필수 입니다
C3: 운용리스 견적서 | AT3: 2025.10.16_Vol 3 | CS3: 보증금없다면 | CT3: 선납금없다면 | CW3: 공채 (비사업용)
AT4: 고객명 | BD4: VVIP | CD4: 공채비용 포함여부 | CE4: TRUE | CH4: 등록지 | CI4: =IF($BD$15="당사명의","부산",$BN$15) -> 부산 | CL4: 실제IRR | CM4: =IRR($CM$5:$CM$65,0)*12 -> 0.047996212 | CO4: 리스기간 | CP4: =$CI$24 -> 60 | CQ4: =$CP$4 -> 60 | CS4: =$CQ$4 -> 60 | CT4: =$CQ$4 -> 60 | CW4: 배기량 → | CY4: 0 | CZ4: 1000 | DA4: 1500 | DB4: 1600 | DC4: 2000 | DE4: 1
D5: =IF($BD$4="","VVIP 고객님",$BD$4&" 고객님") -> VVIP 고객님 | Z5: 견적발행일 | AI5: =TODAY() -> 45946 | AT5: Brand | BD5: BMW | BY5: 비제휴사 | CD5: 부대비 포함여부 | CE5: TRUE | CH5: 차종구분 | CI5: =IF($BQ$7="DB자동연결",$BD$7,$BQ$7) -> 승용SUV(7~10인) | CL5: 0 | CM5: =-$CP$17+$CP$22 -> -171873080 | CO5: IRR | CP5: =$CI$25 -> 0.048 | CQ5: =$CP$5 -> 0.048 | CS5: =$CQ$5 -> 0.048 | CT5: =$CQ$5 -> 0.048 | DE5: 2 | DG5: =IF($CI$4="서울",$DG$6,IF($CI$4="부산",$DG$16,IF($CI$4="대구",$DG$26,IF($CI$4="인천",$DG$36,IF($CI$4="대전",$DG$46,IF($CI$4="광주",$DG$56,IF($CI$4="울산/강원/전남",$DG$66,IF($CI$4="제주",$DG$76,IF($CI$4="세종/경북",$DG$86,IF($CI$4="경기",$DG$96,IF($CI$4="충남",$DG$106,IF($CI$4="충북",$DG$116,IF($CI$4="전북",$DG$126,IF($CI$4="경남",$DG$136,0)))))))))))))) -> 0
Z6: 견적유효기간 | AI6: =AI5+7 -> 45953 | AT6: Model | BD6: X5 30d M Sport xDrive (7인승) | CD6: 탁송료 포함여부 | CE6: TRUE | CH6: 배기량 | CI6: =IF($BQ$8>0,$BQ$8,$BD$8) -> 2993 | CL6: 1 | CM6: =IF(CL6<$CP$4,$CQ$32-$CQ$31,IF(CL6=$CP$4,$CQ$32-$CQ$31+$CQ$24-$CQ$20,0)) -> 1859558 | CW6: 서울 | CX6: =견적관리자용!$S$8 -> 승용일반 | CY6: 0 | CZ6: 0.09 | DA6: 0.09 | DB6: 0.12 | DC6: 0.2 | DD6: =HLOOKUP($CI$6,$CY$4:$DC$145,DE6,TRUE) -> 0.2 | DE6: 3 | DF6: =IF($CI$5=CX6,DD6,0) -> 0 | DG6: =SUM(DF6:DF15) -> 390000 | DI6: 현가율 → | DJ6: =(DK9-DK8)/CP8 -> 0.58329258 | DK6: (Y-Z)/취득원가
Z7: 영업담당자 | AF7: =BD36 -> OOO | AJ7: =BM36 -> 010-0000-0000 | AT7: 차종구분 | BD7: =VLOOKUP($BD$6,차량DB!$F$5:$P$88845,3,FALSE) -> 승용SUV(7~10인) | BK7: 직접선택→ | BQ7: DB자동연결 | BY7: 차종직접입력 | CD7: 모델명 수기입력여부 | CE7: FALSE | CH7: 하이브리드여부 | CI7: =+VLOOKUP(BD6,차량DB!F:Q,12,0) -> 0 | CL7: 2 | CM7: =IF(CL7<$CP$4,$CQ$32-$CQ$31,IF(CL7=$CP$4,$CQ$32-$CQ$31+$CQ$24-$CQ$20,0)) -> 1859558 | CP7: 실제값 | CQ7: IRR 반영값 | CX7: =견적관리자용!$S$9 -> 승용SUV(~5인) | CY7: 0 | CZ7: 0.05 | DA7: 0.05 | DB7: 0.05 | DC7: 0.05 | DD7: =HLOOKUP($CI$6,$CY$4:$DC$145,DE7,TRUE) -> 0.05 | DE7: 4 | DF7: =IF($CI$5=CX7,DD7,0) -> 0 | DK7: =+CQ24 -> 92568000 | DL7: 무보증잔가
D8: =IF(CE7=FALSE,$BD$6,BZ7) -> X5 30d M Sport xDrive (7인승) | Z8: =IF(BZ36="현가율미체크","",IF(BZ36>=90%,"현가율 초과 취급불가","")) | AT8: 배기량 | BD8: =VLOOKUP($BD$6,차량DB!$F$5:$P$88845,2,FALSE) -> 2993 | BK8: 직접입력→ | BY8: ↑ 모델 없을시 직접입력(잔가군 문의 요망) | CD8: 제휴수수료면제여부 | CE8: FALSE | CH8: 고잔가가능 | CI8: =IFERROR(IF($CJ$8="모두가능","Y",IF($CJ$8="모두불가","",VLOOKUP($BD$6,차량DB!$F$5:$P$88845,11,FALSE))),"") -> Y | CJ8: =견적관리자용!$Q$30 -> DB적용 | CL8: 3 | CM8: =IF(CL8<$CP$4,$CQ$32-$CQ$31,IF(CL8=$CP$4,$CQ$32-$CQ$31+$CQ$24-$CQ$20,0)) -> 1859558 | CO8: 취득원가 | CP8: =IF(BD15="이용자명의",$CI$23-$CI$22,$CI$23) -> 169756360 | CQ8: =$CP$8 -> 169756360 | CS8: =$CP$8 -> 169756360 | CT8: =$CP$8 -> 169756360 | CX8: =견적관리자용!$S$10 -> 승용SUV(7~10인) | CY8: 0 | CZ8: 390000 | DA8: 390000 | DB8: 390000 | DC8: 390000 | DD8: =HLOOKUP($CI$6,$CY$4:$DC$145,DE8,TRUE) -> 390000 | DE8: 5 | DF8: =IF($CI$5=CX8,DD8,0) -> 390000 | DI8: 내재이자율(월) | DJ8: =IRR(DJ10:DJ70,0) -> 0.0040013736 | DK8: =DK7/(1+DJ8)^CP4 -> 72845455 | DL8: 잔가할인(Z)
D9: 배기량 | K9: =$CI$6 -> 2993 | Z9: 리스기간 | AG9: =$CI$24 -> 60 | AT9: 기본차량가(직접입력) | BD9: 159600000 | BY9: 24MY는 담당자 별도 문의 | CH9: 차량가격(계산서가) | CI9: =$BD$14 -> 159600000 | CL9: 4 | CM9: =IF(CL9<$CP$4,$CQ$32-$CQ$31,IF(CL9=$CP$4,$CQ$32-$CQ$31+$CQ$24-$CQ$20,0)) -> 1859558 | CO9: AG수수료 | CP9: =$CI$56 -> 0 | CQ9: =$CP$9 -> 0 | CS9: =$CQ$9 -> 0 | CT9: =$CQ$9 -> 0 | CX9: =견적관리자용!$S$11 -> 승합(11~15인) | CY9: 0 | CZ9: 390000 | DA9: 390000 | DB9: 390000 | DC9: 390000 | DD9: =HLOOKUP($CI$6,$CY$4:$DC$145,DE9,TRUE) -> 390000 | DE9: 6 | DF9: =IF($CI$5=CX9,DD9,0) -> 0 | DI9: 1~만기 | DJ9: =SUM(DJ11:DJ70) -> 204144000 | DK9: =SUM(DK11:DK70) -> 1.7186308e+08 | DL9: 할인SUM(Y)
F10: 기본 | K10: =$BD$10 -> 159600000 | AA10: 리스료 | AG10: =ROUNDUP($CQ$32,-2) -> 1859600 | AU10: 기본차량가 | BD10: =BD9 -> 159600000 | CH10: 공채매입액 | CI10: =IF($DG$5>1,$DG$5,$CI$9/1.1*$DG$5) -> 0 | CL10: 5 | CM10: =IF(CL10<$CP$4,$CQ$32-$CQ$31,IF(CL10=$CP$4,$CQ$32-$CQ$31+$CQ$24-$CQ$20,0)) -> 1859558 | CO10: CM수수료 | CP10: =$CI$57 -> 0 | CQ10: =$CP$10 -> 0 | CS10: =$CQ$10 -> 0 | CT10: =$CQ$10 -> 0 | CX10: =견적관리자용!$S$12 -> 화물(1000cc 미만) | CY10: 0 | CZ10: 0 | DA10: 0 | DB10: 0 | DC10: 0 | DD10: =HLOOKUP($CI$6,$CY$4:$DC$145,DE10,TRUE) -> 0 | DE10: 7 | DF10: =IF($CI$5=CX10,DD10,0) -> 0 | DI10: 0 | DJ10: =-CI23-CI55-CI56-CI62-CI71-CI80-CI84+CP19 -> -171863080
F11: 옵션 | K11: =$BD$11 -> 0 | AA11: 선납리스료 | AG11: =-$CQ$31 -> 0 | AU11: 옵션 | BD11: 0 | CD11: 할인비율 | CE11: =IF($BD$12="비율입력",TRUE,FALSE) -> FALSE | CH11: 공채비용 | CI11: =IF($BQ$16>0,$BQ$16,ROUNDDOWN($CI$10*$BD$16,-2)) -> 0 | CL11: 6 | CM11: =IF(CL11<$CP$4,$CQ$32-$CQ$31,IF(CL11=$CP$4,$CQ$32-$CQ$31+$CQ$24-$CQ$20,0)) -> 1859558 | CO11: 제휴수수료 | CP11: =$CI$71 -> 0 | CQ11: =IF(견적관리자용!$M$9="반영",$CP$11,0) -> 0 | CS11: =$CQ$11 -> 0 | CT11: =$CQ$11 -> 0 | CX11: =견적관리자용!$S$13 -> 화물(0.6톤 미만) | CY11: 0 | CZ11: 195000 | DA11: 195000 | DB11: 195000 | DC11: 195000 | DD11: =HLOOKUP($CI$6,$CY$4:$DC$145,DE11,TRUE) -> 195000 | DE11: 8 | DF11: =IF($CI$5=CX11,DD11,0) -> 0 | DI11: 1 | DJ11: =IF(DI11<$CP$4,$AG$10,IF(DI11=$CP$4,$AG$10+$CI$42,0)) -> 1859600 | DK11: =DJ11/(1+$DJ$8)^DI11 -> 1852188.7
F12: 할인 | K12: =-$CE$13 -> 0 | AA12: 자동차세 | AG12: =$CQ$30 -> 0 | AU12: 할인 | BD12: 금액입력 | BK12: 0 | BQ12: 0 | CD12: 할인금액 | CE12: =IF($BD$12="금액입력",TRUE,FALSE) -> TRUE | CH12: 차종구분(대) | CI12: =LEFT($CI$5,2) -> 승용 | CL12: 7 | CM12: =IF(CL12<$CP$4,$CQ$32-$CQ$31,IF(CL12=$CP$4,$CQ$32-$CQ$31+$CQ$24-$CQ$20,0)) -> 1859558 | CO12: 기타비용 | CP12: =$CI$80 -> 0 | CQ12: =IF(견적관리자용!$M$17="반영",$CP$12,0) -> 0 | CS12: =$CQ$12 -> 0 | CT12: =$CQ$12 -> 0 | CX12: =견적관리자용!$S$14 -> 화물(0.6~1톤 미만) | CY12: 0 | CZ12: 195000 | DA12: 195000 | DB12: 195000 | DC12: 195000 | DD12: =HLOOKUP($CI$6,$CY$4:$DC$145,DE12,TRUE) -> 195000 | DE12: 9 | DF12: =IF($CI$5=CX12,DD12,0) -> 0 | DI12: 2 | DJ12: =IF(DI12<$CP$4,$AG$10,IF(DI12=$CP$4,$AG$10+$CI$42,0)) -> 1859600 | DK12: =DJ12/(1+$DJ$8)^DI12 -> 1844806.9
F13: =IF($BD$13>0,"탁송료","") | K13: =IF($BD$13>0,$BD$13,"") | AA13: =IF(BD33>0,"보험료","") | AG13: =CQ33 -> 0 | AU13: (계산서포함)탁송료 | BD13: 0 | BY13: - 차량가 내 포함되는 탁송료만 입력 | CD13: 최종할인금액 | CE13: =IF($BD$12="금액입력",$BQ$12,TRUNC(($BD$10+$BD$11)*$BK$12,-1)) -> 0 | CH13: 취득세율 | CI13: =IF($CI$12="승용",7%,IF($CI$12="승합",5%,IF($CI$12="화물",5%,7%))) -> 0.07 | CL13: 8 | CM13: =IF(CL13<$CP$4,$CQ$32-$CQ$31,IF(CL13=$CP$4,$CQ$32-$CQ$31+$CQ$24-$CQ$20,0)) -> 1859558 | CO13: 용품/서비스비용 | CP13: =$CI$85 -> 0 | CQ13: =$CP$13 -> 0 | CS13: =$CQ$13 -> 0 | CT13: =$CQ$13 -> 0 | CX13: =견적관리자용!$S$15 -> 화물(1~2.5톤 미만) | CY13: 0 | CZ13: 390000 | DA13: 390000 | DB13: 390000 | DC13: 390000 | DD13: =HLOOKUP($CI$6,$CY$4:$DC$145,DE13,TRUE) -> 390000 | DE13: 10 | DF13: =IF($CI$5=CX13,DD13,0) -> 0 | DI13: 3 | DJ13: =IF(DI13<$CP$4,$AG$10,IF(DI13=$CP$4,$AG$10+$CI$42,0)) -> 1859600 | DK13: =DJ13/(1+$DJ$8)^DI13 -> 1837454.6
E14: 차량가격 | K14: =$CI$9 -> 159600000 | Z14: 月납입금 | AG14: =IF(BD37>19.5%,"금리기준초과",$AG$10+$AG$11+$AG$12+$AG$13) -> 1859600 | AT14: 차량가격(계산서가) | BD14: =$BD$10+$BD$11-$CE$13+$BD$13 -> 159600000 | CD14: 리스사명의 | CE14: =IF($BD$15="당사명의",TRUE,FALSE) -> TRUE | CH14: 자동반영(1) | CI14: =ROUNDDOWN($CI$9/1.1*$CI$13,-1) -> 10156360 | CL14: 9 | CM14: =IF(CL14<$CP$4,$CQ$32-$CQ$31,IF(CL14=$CP$4,$CQ$32-$CQ$31+$CQ$24-$CQ$20,0)) -> 1859558 | CO14: 잔가보장수수료 | CP14: =$CI$55 -> 2106720 | CQ14: =$CP$14 -> 2106720 | CS14: =$CQ$14 -> 2106720 | CT14: =$CQ$14 -> 2106720 | CX14: =견적관리자용!$S$16 -> 화물(2.5~4.6톤 미만) | CY14: 0 | CZ14: 390000 | DA14: 390000 | DB14: 390000 | DC14: 390000 | DD14: =HLOOKUP($CI$6,$CY$4:$DC$145,DE14,TRUE) -> 390000 | DE14: 11 | DF14: =IF($CI$5=CX14,DD14,0) -> 0 | DI14: 4 | DJ14: =IF(DI14<$CP$4,$AG$10,IF(DI14=$CP$4,$AG$10+$CI$42,0)) -> 1859600 | DK14: =DJ14/(1+$DJ$8)^DI14 -> 1830131.6
E15: 취득세 | K15: =$CI$21 -> 10156360 | Z15: 약정주행거리 | AG15: =$BD$26 -> 20000 | AT15: 차량명의 | BD15: 당사명의 | BN15: 서울 | BY15: - 이용자명의 이용불가 | CD15: 이용자명의 | CE15: =IF($BD$15="이용자명의",TRUE,FALSE) -> FALSE | CH15: 경차 75만초과분 부담 | CI15: =IF($CI$14<750000,0,$CI$14) -> 10156360 | CJ15: 1000CC이하제거 | CL15: 10 | CM15: =IF(CL15<$CP$4,$CQ$32-$CQ$31,IF(CL15=$CP$4,$CQ$32-$CQ$31+$CQ$24-$CQ$20,0)) -> 1859558 | CO15: 이용자명의리스설정료 | CP15: =$CI$84 -> 0 | CQ15: =IF(견적관리자용!$Q$25="반영",$CP$15,0) -> 0 | CS15: =$CQ$15 -> 0 | CT15: =$CQ$15 -> 0 | CX15: =견적관리자용!$S$17 -> 화물(4.6톤 이상) | CY15: 0 | CZ15: 650000 | DA15: 650000 | DB15: 650000 | DC15: 650000 | DD15: =HLOOKUP($CI$6,$CY$4:$DC$145,DE15,TRUE) -> 650000 | DE15: 12 | DF15: =IF($CI$5=CX15,DD15,0) -> 0 | DI15: 5 | DJ15: =IF(DI15<$CP$4,$AG$10,IF(DI15=$CP$4,$AG$10+$CI$42,0)) -> 1859600 | DK15: =DJ15/(1+$DJ$8)^DI15 -> 1822837.7
E16: 공채비용 | K16: =$CI$11 -> 0 | Z16: 잔존가치 | AG16: =IF($CE$40=TRUE,$CI$42/$CI$9,$CI$42/$CP$8) -> 0.58 | AJ16: =$CI$42 -> 92568000 | AT16: 공채 | AZ16: =+IF($CE$4=TRUE, "포함","미포함") -> 포함 | BD16: 0 | BK16: 직접입력→ | CH16: 자동반영 (하이브리드) | CL16: 11 | CM16: =IF(CL16<$CP$4,$CQ$32-$CQ$31,IF(CL16=$CP$4,$CQ$32-$CQ$31+$CQ$24-$CQ$20,0)) -> 1859558 | CO16: 인지세 | CP16: =$CI$81 -> 10000 | CQ16: =IF(견적관리자용!$Q$24="반영",$CP$16,0) -> 10000 | CS16: =$CQ$16 -> 10000 | CT16: =$CQ$16 -> 10000 | CW16: 부산 | CX16: =견적관리자용!$S$8 -> 승용일반 | CY16: 0 | CZ16: 0 | DA16: 0 | DB16: 0 | DC16: 0.05 | DD16: =HLOOKUP($CI$6,$CY$4:$DC$145,DE16,TRUE) -> 0.05 | DE16: 13 | DF16: =IF($CI$5=CX16,DD16,0) -> 0 | DG16: =SUM(DF16:DF25) -> 0 | DI16: 6 | DJ16: =IF(DI16<$CP$4,$AG$10,IF(DI16=$CP$4,$AG$10+$CI$42,0)) -> 1859600 | DK16: =DJ16/(1+$DJ$8)^DI16 -> 1815572.9
E17: 기타부대비 | K17: =$BD$17 -> 0 | AA17: 보증금 | AG17: =IF($CE$40=TRUE,$CI$28/$CI$9,$CI$28/$CP$8) -> 0 | AJ17: =$CI$28 -> 0 | AT17: 기타부대비 | AZ17: =+IF($CE$5=TRUE, "포함","미포함") -> 포함 | BD17: 0 | BN17: ≤ | BP17: =견적관리자용!$T$35 -> 0 | CH17: 자동반영 | CI17: =IF($CI$6<1000,$CI$15,IF(CI7="하이브리드",CI16,$CI$14)) -> 10156360 | CL17: 12 | CM17: =IF(CL17<$CP$4,$CQ$32-$CQ$31,IF(CL17=$CP$4,$CQ$32-$CQ$31+$CQ$24-$CQ$20,0)) -> 1859558 | CO17: MINUS | CP17: =SUM($CP$8:$CP$16) -> 171873080 | CQ17: =SUM($CQ$8:$CQ$16) -> 171873080 | CS17: =$CQ$17 -> 171873080 | CT17: =$CQ$17 -> 171873080 | CX17: =견적관리자용!$S$9 -> 승용SUV(~5인) | CY17: 0 | CZ17: 0 | DA17: 0 | DB17: 0 | DC17: 0 | DD17: =HLOOKUP($CI$6,$CY$4:$DC$145,DE17,TRUE) -> 0 | DE17: 14 | DF17: =IF($CI$5=CX17,DD17,0) -> 0 | DI17: 7 | DJ17: =IF(DI17<$CP$4,$AG$10,IF(DI17=$CP$4,$AG$10+$CI$42,0)) -> 1859600 | DK17: =DJ17/(1+$DJ$8)^DI17 -> 1808337.1
E18: =IF($BD$18>0,"탁송료","") | K18: =IF($BD$18>0,$BD$18,"") | AA18: 장기선수금 | AG18: =IF($CE$40=TRUE,$CI$26/$CI$9,$CI$26/$CP$8) -> 0 | AJ18: =$CI$26 -> 0 | AT18: 탁송료 | AZ18: =+IF($CE$6=TRUE, "포함","미포함") -> 포함 | BD18: 0 | BN18: ≤ | BP18: =견적관리자용!$T$36 -> 500000 | CD18: 취득세 비율입력 | CE18: =IF($BD$19="비율입력",TRUE,FALSE) -> FALSE | CH18: 비율입력 | CI18: =ROUNDDOWN($CI$9/1.1*$BK$19,-1) -> 10156360 | CL18: 13 | CM18: =IF(CL18<$CP$4,$CQ$32-$CQ$31,IF(CL18=$CP$4,$CQ$32-$CQ$31+$CQ$24-$CQ$20,0)) -> 1859558 | CX18: =견적관리자용!$S$10 -> 승용SUV(7~10인) | CY18: 0 | CZ18: 0 | DA18: 0 | DB18: 0 | DC18: 0 | DD18: =HLOOKUP($CI$6,$CY$4:$DC$145,DE18,TRUE) -> 0 | DE18: 15 | DF18: =IF($CI$5=CX18,DD18,0) -> 0 | DI18: 8 | DJ18: =IF(DI18<$CP$4,$AG$10,IF(DI18=$CP$4,$AG$10+$CI$42,0)) -> 1859600 | DK18: =DJ18/(1+$DJ$8)^DI18 -> 1801130.1
D19: 취득원가 | K19: =$CI$23 -> 169756360 | AA19: =+IF(AND($BD$15="이용자명의",$CE$5=FALSE),"부가세+등록비", IF(AND($BD$15="이용자명의",$CE$6=FALSE),"부가세+등록비",IF(BD15="당사명의","등록비","부가세"))) -> 등록비 | AG19: =+IF(CE4=FALSE,CI11,0)+IF(CE5=FALSE,BD17,0)+IF(CE6=FALSE,BD18,0)+IF(BD15="이용자명의",CI22,0) -> 0 | AT19: 취득세 (직접입력시만 사용) | BD19: 자동반영 | BK19: 0.07 | BQ19: 0 | BY19: - 하이브리드, 전기차, 경차 등 특례해당건 취득세 재확인 요망 | CD19: 취득세 감면액입력 | CE19: =IF($BD$19="감면액입력",TRUE,FALSE) -> FALSE | CH19: 감면액입력 | CI19: =$CI$17-$BQ$19 -> 10156360 | CL19: 14 | CM19: =IF(CL19<$CP$4,$CQ$32-$CQ$31,IF(CL19=$CP$4,$CQ$32-$CQ$31+$CQ$24-$CQ$20,0)) -> 1859558 | CO19: 선납금 | CP19: =$CI$26 -> 0 | CQ19: =$CP$19 -> 0 | CS19: =$CQ$19 -> 0 | CT19: 0 | CX19: =견적관리자용!$S$11 -> 승합(11~15인) | CY19: 0 | CZ19: 0 | DA19: 0 | DB19: 0 | DC19: 0 | DD19: =HLOOKUP($CI$6,$CY$4:$DC$145,DE19,TRUE) -> 0 | DE19: 16 | DF19: =IF($CI$5=CX19,DD19,0) -> 0 | DI19: 9 | DJ19: =IF(DI19<$CP$4,$AG$10,IF(DI19=$CP$4,$AG$10+$CI$42,0)) -> 1859600 | DK19: =DJ19/(1+$DJ$8)^DI19 -> 1793951.8
Z20: 초기납입금 | AG20: =$AJ$17+$AJ$18+$AG$19 -> 0 | CD20: 취득세 금액입력 | CE20: =IF($BD$19="금액입력",TRUE,FALSE) -> FALSE | CH20: 금액입력 | CI20: =$BK$20 -> 0 | CL20: 15 | CM20: =IF(CL20<$CP$4,$CQ$32-$CQ$31,IF(CL20=$CP$4,$CQ$32-$CQ$31+$CQ$24-$CQ$20,0)) -> 1859558 | CO20: 보증금 | CP20: =$CI$28 -> 0 | CQ20: =$CP$20 -> 0 | CS20: 0 | CT20: =$CQ$20 -> 0 | CX20: =견적관리자용!$S$12 -> 화물(1000cc 미만) | CY20: 0 | CZ20: 0 | DA20: 0 | DB20: 0 | DC20: 0 | DD20: =HLOOKUP($CI$6,$CY$4:$DC$145,DE20,TRUE) -> 0 | DE20: 17 | DF20: =IF($CI$5=CX20,DD20,0) -> 0 | DI20: 10 | DJ20: =IF(DI20<$CP$4,$AG$10,IF(DI20=$CP$4,$AG$10+$CI$42,0)) -> 1859600 | DK20: =DJ20/(1+$DJ$8)^DI20 -> 1786802.2
Z21: * 보증/선납금납입에 따른 리스료할인내역 | CH21: 최종 취득세 | CI21: =VLOOKUP($BD$19,$CH$17:$CI$20,2,FALSE) -> 10156360 | CL21: 16 | CM21: =IF(CL21<$CP$4,$CQ$32-$CQ$31,IF(CL21=$CP$4,$CQ$32-$CQ$31+$CQ$24-$CQ$20,0)) -> 1859558 | CO21: 이손액 | CP21: =$CI$88 -> 0 | CQ21: =$CP$21 -> 0 | CS21: =$CQ$21 -> 0 | CT21: =$CQ$21 -> 0 | CX21: =견적관리자용!$S$13 -> 화물(0.6톤 미만) | CY21: 0 | CZ21: 0 | DA21: 0 | DB21: 0 | DC21: 0 | DD21: =HLOOKUP($CI$6,$CY$4:$DC$145,DE21,TRUE) -> 0 | DE21: 18 | DF21: =IF($CI$5=CX21,DD21,0) -> 0 | DI21: 11 | DJ21: =IF(DI21<$CP$4,$AG$10,IF(DI21=$CP$4,$AG$10+$CI$42,0)) -> 1859600 | DK21: =DJ21/(1+$DJ$8)^DI21 -> 1779681
AA22: 보증금 | AD22: =CS36 -> 0 | AG22: =CS35 -> 0 | AT22: 리스기간(개월) | BD22: 60 | CH22: 부가세 | CI22: =ROUND((CI9/1.1)/10,0) -> 14509091 | CL22: 17 | CM22: =IF(CL22<$CP$4,$CQ$32-$CQ$31,IF(CL22=$CP$4,$CQ$32-$CQ$31+$CQ$24-$CQ$20,0)) -> 1859558 | CO22: PLUS | CP22: =SUM($CP$19:$CP$21) -> 0 | CQ22: =SUM($CQ$19:$CQ$21) -> 0 | CS22: =SUM($CS$19:$CS$21) -> 0 | CT22: =SUM($CT$19:$CT$21) -> 0 | CX22: =견적관리자용!$S$14 -> 화물(0.6~1톤 미만) | CY22: 0 | CZ22: 0 | DA22: 0 | DB22: 0 | DC22: 0 | DD22: =HLOOKUP($CI$6,$CY$4:$DC$145,DE22,TRUE) -> 0 | DE22: 19 | DF22: =IF($CI$5=CX22,DD22,0) -> 0 | DI22: 12 | DJ22: =IF(DI22<$CP$4,$AG$10,IF(DI22=$CP$4,$AG$10+$CI$42,0)) -> 1859600 | DK22: =DJ22/(1+$DJ$8)^DI22 -> 1772588.2
AA23: 선납금 | AD23: =CT36 -> 0 | AG23: =CT35 -> 0 | AT23: 장기선수금 | BD23: 0 | CD23: 보증금 금액입력 | CE23: =IF($BD$24="금액입력",TRUE,FALSE) -> FALSE | CF23: =IF($CE$23=TRUE,FALSE,TRUE) -> TRUE | CH23: 취득원가 | CI23: =$CI$9+$CI$21+IF($CE$4=TRUE, $CI$11,0)+IF($CE$5=TRUE,$BD$17,0)+IF($CE$6=TRUE,$BD$18,0) -> 169756360 | CL23: 18 | CM23: =IF(CL23<$CP$4,$CQ$32-$CQ$31,IF(CL23=$CP$4,$CQ$32-$CQ$31+$CQ$24-$CQ$20,0)) -> 1859558 | CX23: =견적관리자용!$S$15 -> 화물(1~2.5톤 미만) | CY23: 0 | CZ23: 0 | DA23: 0 | DB23: 0 | DC23: 0 | DD23: =HLOOKUP($CI$6,$CY$4:$DC$145,DE23,TRUE) -> 0 | DE23: 20 | DF23: =IF($CI$5=CX23,DD23,0) -> 0 | DI23: 13 | DJ23: =IF(DI23<$CP$4,$AG$10,IF(DI23=$CP$4,$AG$10+$CI$42,0)) -> 1859600 | DK23: =DJ23/(1+$DJ$8)^DI23 -> 1765523.7
D24: ▷계약시 유의사항 | AT24: 보증금 | BD24: 차량가비율 | BK24: 0 | BQ24: 0 | CD24: 보증보험 금액입력 | CE24: =IF($BD$25="금액입력",TRUE,FALSE) -> FALSE | CF24: =IF($CE$24=TRUE,FALSE,TRUE) -> TRUE | CH24: 리스기간 | CI24: =$BD$22 -> 60 | CL24: 19 | CM24: =IF(CL24<$CP$4,$CQ$32-$CQ$31,IF(CL24=$CP$4,$CQ$32-$CQ$31+$CQ$24-$CQ$20,0)) -> 1859558 | CO24: 잔가 | CP24: =$CI$42 -> 92568000 | CQ24: =$CP$24 -> 92568000 | CS24: =$CQ$24 -> 92568000 | CT24: =$CQ$24 -> 92568000 | CX24: =견적관리자용!$S$16 -> 화물(2.5~4.6톤 미만) | CY24: 0 | CZ24: 0 | DA24: 0 | DB24: 0 | DC24: 0 | DD24: =HLOOKUP($CI$6,$CY$4:$DC$145,DE24,TRUE) -> 0 | DE24: 21 | DF24: =IF($CI$5=CX24,DD24,0) -> 0 | DI24: 14 | DJ24: =IF(DI24<$CP$4,$AG$10,IF(DI24=$CP$4,$AG$10+$CI$42,0)) -> 1859600 | DK24: =DJ24/(1+$DJ$8)^DI24 -> 1758487.3
D25: * 지방세법 제10조 개정(시행 '23.1.1)에 따라 취득세 과세표준을 취득가액과 시가표준액 중 높은 금액을 | AT25: 보증보험 | BD25: 차량가비율 | BK25: 0 | BQ25: 0 | CH25: IRR | CI25: =IF($BD$15="당사명의",VLOOKUP($BD$5,견적관리자용!$E$9:$K$36,2,FALSE),VLOOKUP($BD$5,견적관리자용!$E$9:$K$36,3,FALSE))+CJ25 -> 0.048 | CJ25: =IF(BZ33="KCC오토",1.5%,IF(BZ33="KCC면제",1.5%,0)) -> 0 | CL25: 20 | CM25: =IF(CL25<$CP$4,$CQ$32-$CQ$31,IF(CL25=$CP$4,$CQ$32-$CQ$31+$CQ$24-$CQ$20,0)) -> 1859558 | CX25: =견적관리자용!$S$17 -> 화물(4.6톤 이상) | CY25: 0 | CZ25: 0 | DA25: 0 | DB25: 0 | DC25: 0 | DD25: =HLOOKUP($CI$6,$CY$4:$DC$145,DE25,TRUE) -> 0 | DE25: 22 | DF25: =IF($CI$5=CX25,DD25,0) -> 0 | DI25: 15 | DJ25: =IF(DI25<$CP$4,$AG$10,IF(DI25=$CP$4,$AG$10+$CI$42,0)) -> 1859600 | DK25: =DJ25/(1+$DJ$8)^DI25 -> 1751479
D26: 과세표준으로 하도록 규정되어 견적서 상의 취득세와 상이할 수 있습니다. 이와 같은 경우, 고객님께서 | AT26: 약정주행거리 | BD26: 20000 | CD26: 잔가 금액입력 | CE26: =IF($BD$27="금액입력",TRUE,FALSE) -> FALSE | CF26: =IF($CE$26=TRUE,FALSE,TRUE) -> TRUE | CH26: 선납금 | CI26: =$BD$23 -> 0 | CJ26: 보증+선납비율 | CL26: 21 | CM26: =IF(CL26<$CP$4,$CQ$32-$CQ$31,IF(CL26=$CP$4,$CQ$32-$CQ$31+$CQ$24-$CQ$20,0)) -> 1859558 | CO26: PMT(1) | CQ26: =PMT($CQ$5/12,$CQ$4,-$CQ$17+$CQ$22,$CQ$24-$CQ$20) -> 1859600.9 | CS26: =PMT($CS$5/12,$CS$4,-$CS$17+$CS$22,$CS$24-$CS$20) -> 1859600.9 | CT26: =PMT($CT$5/12,$CT$4,-$CT$17+$CT$22,$CT$24-$CT$20) -> 1859600.9 | CW26: 대구 | CX26: =견적관리자용!$S$8 -> 승용일반 | CY26: 0 | CZ26: 0.04 | DA26: 0.04 | DB26: 0.04 | DC26: 0.05 | DD26: =HLOOKUP($CI$6,$CY$4:$DC$145,DE26,TRUE) -> 0.05 | DE26: 23 | DF26: =IF($CI$5=CX26,DD26,0) -> 0 | DG26: =SUM(DF26:DF35) -> 390000 | DI26: 16 | DJ26: =IF(DI26<$CP$4,$AG$10,IF(DI26=$CP$4,$AG$10+$CI$42,0)) -> 1859600 | DK26: =DJ26/(1+$DJ$8)^DI26 -> 1744498.6
D27: 취등록세 차액분을 직접 납부해주셔야 하며, 영업담당자는 반드시 과세표준 확인 후 견적부탁드립니다. | AT27: 잔가 | BD27: 차량가비율 | BK27: 0.58 | CH27: 보증금 | CI27: =IF($BD$24="취득원가비율",$CI$23*$BK$24,IF($BD$24="차량가비율",$CI$9*$BK$24,$BQ$24)) -> 0 | CJ27: =+(CI28+CI26)/CI9 -> 0 | CL27: 22 | CM27: =IF(CL27<$CP$4,$CQ$32-$CQ$31,IF(CL27=$CP$4,$CQ$32-$CQ$31+$CQ$24-$CQ$20,0)) -> 1859558 | CO27: RATE(1) | CQ27: =RATE($CQ$4,$CQ$26,-$CQ$8+$CQ$19,$CQ$24)*12 -> 0.051533744 | CS27: =ROUND(RATE($CS$4,$CS$26,-$CS$8+$CS$19,$CS$24)*12,5) -> 0.05153 | CT27: =RATE($CT$4,$CT$26,-$CT$8+$CT$19,$CT$24)*12 -> 0.051533744 | CX27: =견적관리자용!$S$9 -> 승용SUV(~5인) | CY27: 0 | CZ27: 0.04 | DA27: 0.04 | DB27: 0.04 | DC27: 0.04 | DD27: =HLOOKUP($CI$6,$CY$4:$DC$145,DE27,TRUE) -> 0.04 | DE27: 24 | DF27: =IF($CI$5=CX27,DD27,0) -> 0 | DI27: 17 | DJ27: =IF(DI27<$CP$4,$AG$10,IF(DI27=$CP$4,$AG$10+$CI$42,0)) -> 1859600 | DK27: =DJ27/(1+$DJ$8)^DI27 -> 1737546
D28: * 리스차량 명의는 엠지캐피탈㈜ 이며, 리스기간 만료시 차량의 반환 / 매입 / 재리스 중 택일이 가능합니다." | BD28: 최소잔가→ | BK28: =IF($BD$27="취득원가비율",$CI$38,$CI$36) -> 0.15 | BQ28: =$CI$37 -> 23940000 | BY28: 잔가보장사 | BZ28: =CO62 -> 에스앤케이모터스 | CI28: =ROUNDDOWN($CI$27,-3) -> 0 | CL28: 23 | CM28: =IF(CL28<$CP$4,$CQ$32-$CQ$31,IF(CL28=$CP$4,$CQ$32-$CQ$31+$CQ$24-$CQ$20,0)) -> 1859558 | CO28: RATE(2) | CQ28: =ROUND(CQ27,5) -> 0.05153 | CS28: =ROUND(CS27,5) -> 0.05153 | CT28: =ROUND(CT27,5) -> 0.05153 | CX28: =견적관리자용!$S$10 -> 승용SUV(7~10인) | CY28: 0 | CZ28: 390000 | DA28: 390000 | DB28: 390000 | DC28: 390000 | DD28: =HLOOKUP($CI$6,$CY$4:$DC$145,DE28,TRUE) -> 390000 | DE28: 25 | DF28: =IF($CI$5=CX28,DD28,0) -> 390000 | DI28: 18 | DJ28: =IF(DI28<$CP$4,$AG$10,IF(DI28=$CP$4,$AG$10+$CI$42,0)) -> 1859600 | DK28: =DJ28/(1+$DJ$8)^DI28 -> 1730621.2
D29: * 계약종결 후 소유권 이전 시 당사매매대금 또는 구청기준과표로 취득세 발생됩니다. | BD29: 최대잔가→ | BK29: =IF($BD$27="취득원가비율",$CI$35,$CI$33) -> 0.58 | BQ29: =$CI$34 -> 92568000 | BY29: 잔가GAP | BZ29: =CI44 -> 0 | CD29: 선납+보증금율 | CE29: =($CI$28+$CI$26)/$CI$9 -> 0 | CH29: 보증보험 | CI29: =IF($BD$25="취득원가비율",$CI$23*$BK$25,IF($BD$25="차량가비율",$CI$9*$BK$25,$BQ$25)) -> 0 | CL29: 24 | CM29: =IF(CL29<$CP$4,$CQ$32-$CQ$31,IF(CL29=$CP$4,$CQ$32-$CQ$31+$CQ$24-$CQ$20,0)) -> 1859558 | CO29: PMT(2) | CQ29: =ROUNDDOWN(PMT(CQ28/12,CQ4,-CQ8,CQ24),0) -> 1859558 | CS29: =ROUNDDOWN(PMT(CS28/12,CS4,-CS8,CS24),0) -> 1859558 | CT29: =ROUNDDOWN(PMT(CT28/12,CT4,-CT8,CT24),0) -> 1859558 | CX29: =견적관리자용!$S$11 -> 승합(11~15인) | CY29: 0 | CZ29: 390000 | DA29: 390000 | DB29: 390000 | DC29: 390000 | DD29: =HLOOKUP($CI$6,$CY$4:$DC$145,DE29,TRUE) -> 390000 | DE29: 26 | DF29: =IF($CI$5=CX29,DD29,0) -> 0 | DI29: 19 | DJ29: =IF(DI29<$CP$4,$AG$10,IF(DI29=$CP$4,$AG$10+$CI$42,0)) -> 1859600 | DK29: =DJ29/(1+$DJ$8)^DI29 -> 1723723.9
D30: * 보험은 자차 질권설정(차량가 100%) 후 증권사본 송부 부탁드립니다.(엠지캐피탈㈜, 105-81-87072) | AT30: AG수수료율 | BD30: 0 | BN30: ≤ | BP30: =ROUNDDOWN(IF($BD$15="리스사명의(부산등록)",MIN(견적관리자용!$F$41-운용리스!$CG$62,견적관리자용!$F$40),MIN(견적관리자용!$G$41-운용리스!$CG$62,견적관리자용!$G$40)),4) -> 0.132 | BY30: 잔가수수료율 | BZ30: =CI54 -> 0.0132 | CD30: MAX | CE30: =견적관리자용!$T$21 -> 0.5 | CI30: =ROUNDDOWN($CI$29,-3) -> 0 | CL30: 25 | CM30: =IF(CL30<$CP$4,$CQ$32-$CQ$31,IF(CL30=$CP$4,$CQ$32-$CQ$31+$CQ$24-$CQ$20,0)) -> 1859558 | CO30: 월차세 | CQ30: =$CP$54 -> 0 | CS30: =$CP$54 -> 0 | CT30: =$CP$54 -> 0 | CX30: =견적관리자용!$S$12 -> 화물(1000cc 미만) | CY30: 0 | CZ30: 0 | DA30: 0 | DB30: 0 | DC30: 0 | DD30: =HLOOKUP($CI$6,$CY$4:$DC$145,DE30,TRUE) -> 0 | DE30: 27 | DF30: =IF($CI$5=CX30,DD30,0) -> 0 | DI30: 20 | DJ30: =IF(DI30<$CP$4,$AG$10,IF(DI30=$CP$4,$AG$10+$CI$42,0)) -> 1859600 | DK30: =DJ30/(1+$DJ$8)^DI30 -> 1716854.1
D31: * 운행중 발생하는 범칙금 및 과태료는 이용자 부담이며, 중도상환시 약정에 따른 수수료가 발생합니다. | AT31: CM수수료율 | BD31: 0 | BN31: ≤ | BY31: 잔가보장수수료 | BZ31: =CI55 -> 2106720 | CH31: 잔가율 | CI31: =CP62 -> 0.5 | CL31: 26 | CM31: =IF(CL31<$CP$4,$CQ$32-$CQ$31,IF(CL31=$CP$4,$CQ$32-$CQ$31+$CQ$24-$CQ$20,0)) -> 1859558 | CO31: 월선납 | CQ31: =ROUNDDOWN($CQ$19/$CQ$4,0) -> 0 | CS31: =ROUNDUP($CQ$19/$CQ$4,0) -> 0 | CT31: =ROUNDUP($CQ$19/$CQ$4,0) -> 0 | CX31: =견적관리자용!$S$13 -> 화물(0.6톤 미만) | CY31: 0 | CZ31: 195000 | DA31: 195000 | DB31: 195000 | DC31: 195000 | DD31: =HLOOKUP($CI$6,$CY$4:$DC$145,DE31,TRUE) -> 195000 | DE31: 28 | DF31: =IF($CI$5=CX31,DD31,0) -> 0 | DI31: 21 | DJ31: =IF(DI31<$CP$4,$AG$10,IF(DI31=$CP$4,$AG$10+$CI$42,0)) -> 1859600 | DK31: =DJ31/(1+$DJ$8)^DI31 -> 1710011.7
D32: =IF(AT10=2,"* 이용자명의 리스차량에 대한 승계는 불가능 합니다.","* 승계시 [미회수원금 * 2%] 의 변경수수료가 부과됩니다.(최소 300,000원, 최대 1,500,000원)") -> * 승계시 [미회수원금 * 2%] 의 변경수수료가 부과됩니다.(최소 300,000원, 최대 1,500,000원) | AT32: 자동차세 | BD32: 미포함(별도청구) | BK32: 직접입력→ | BQ32: 0 | BY32: 일반잔가 | BZ32: =CI32 -> 0.5 | CD32: 선납+보증+잔가율 | CE32: =($CI$26+$CI$28+$CI$42)/$CI$23 -> 0.54529916 | CH32: 주행거리 가감 | CI32: =CQ62 -> 0.5 | CL32: 27 | CM32: =IF(CL32<$CP$4,$CQ$32-$CQ$31,IF(CL32=$CP$4,$CQ$32-$CQ$31+$CQ$24-$CQ$20,0)) -> 1859558 | CO32: 순리스료(최종) | CQ32: =IF(CQ19>0,CQ26+CQ31,CQ29) -> 1859558 | CS32: =IF(CS19>0,CS26+CS31,CS29) -> 1859558 | CT32: =IF(CT19>0,CT26+CT31,CT29) -> 1859558 | CX32: =견적관리자용!$S$14 -> 화물(0.6~1톤 미만) | CY32: 0 | CZ32: 195000 | DA32: 195000 | DB32: 195000 | DC32: 195000 | DD32: =HLOOKUP($CI$6,$CY$4:$DC$145,DE32,TRUE) -> 195000 | DE32: 29 | DF32: =IF($CI$5=CX32,DD32,0) -> 0 | DI32: 22 | DJ32: =IF(DI32<$CP$4,$AG$10,IF(DI32=$CP$4,$AG$10+$CI$42,0)) -> 1859600 | DK32: =DJ32/(1+$DJ$8)^DI32 -> 1703196.6
D33: * 초기 납입 입급계좌 : 우리은행 1006-500-203980 엠지캐피탈㈜ (계약자 명의로 입금 바랍니다) | AT33: 보험료(年) | BY33: 제휴사 | BZ33: =BY5&IF(CE8=TRUE,"(제휴면제)","") -> 비제휴사 | CD33: MAX | CE33: =견적관리자용!T22 -> 1 | CH33: 최대 잔가율 | CI33: =CR62 -> 0.58 | CL33: 28 | CM33: =IF(CL33<$CP$4,$CQ$32-$CQ$31,IF(CL33=$CP$4,$CQ$32-$CQ$31+$CQ$24-$CQ$20,0)) -> 1859558 | CO33: 월보험 | CQ33: =$CI$87 -> 0 | CS33: =$CI$87 -> 0 | CT33: =$CI$87 -> 0 | CX33: =견적관리자용!$S$15 -> 화물(1~2.5톤 미만) | CY33: 0 | CZ33: 195000 | DA33: 195000 | DB33: 195000 | DC33: 195000 | DD33: =HLOOKUP($CI$6,$CY$4:$DC$145,DE33,TRUE) -> 195000 | DE33: 30 | DF33: =IF($CI$5=CX33,DD33,0) -> 0 | DI33: 23 | DJ33: =IF(DI33<$CP$4,$AG$10,IF(DI33=$CP$4,$AG$10+$CI$42,0)) -> 1859600 | DK33: =DJ33/(1+$DJ$8)^DI33 -> 1696408.6
D34: * 상기 견적의 유효기간은 7일 이며, 7일 이후에는 당사 기준금리 및 당사 기준의 변동으로 인하여 변동 될수 있습니다. | AT34: 이손액(수입수수료) | BD34: 0 | BY34: 취득원가 | BZ34: =K19 -> 169756360 | CD34: 4대 중요 에러 | CE34: =SUM(CE35:CE38) -> 0 | CH34: 최대 잔가액 | CI34: =ROUNDDOWN($CI$9*$CI$33,-1) -> 92568000 | CL34: 29 | CM34: =IF(CL34<$CP$4,$CQ$32-$CQ$31,IF(CL34=$CP$4,$CQ$32-$CQ$31+$CQ$24-$CQ$20,0)) -> 1859558 | CO34: RATE(3) (최종금리) | CQ34: =IF(CQ19>0,RATE(CQ4,CQ32,-CQ8,CQ24)*12,CQ28) -> 0.05153 | CS34: =IF(CS19>0,RATE(CS4,CS32,-CS8,CS24)*12,CS28) -> 0.05153 | CT34: =IF(CT19>0,RATE(CT4,CT32,-CT8,CT24)*12,CT28) -> 0.05153 | CX34: =견적관리자용!$S$16 -> 화물(2.5~4.6톤 미만) | CY34: 0 | CZ34: 390000 | DA34: 390000 | DB34: 390000 | DC34: 390000 | DD34: =HLOOKUP($CI$6,$CY$4:$DC$145,DE34,TRUE) -> 390000 | DE34: 31 | DF34: =IF($CI$5=CX34,DD34,0) -> 0 | DI34: 24 | DJ34: =IF(DI34<$CP$4,$AG$10,IF(DI34=$CP$4,$AG$10+$CI$42,0)) -> 1859600 | DK34: =DJ34/(1+$DJ$8)^DI34 -> 1689647.7
D35: ▷필요서류 (발행기간 3개월내) | AT35: 부가서비스 | BD35: - | CE35: =IF(C2="",0,1) -> 0 | CH35: 최대 잔가율 (취득원가비) | CI35: =ROUNDDOWN($CI$34/$CI$23,4) -> 0.5452 | CL35: 30 | CM35: =IF(CL35<$CP$4,$CQ$32-$CQ$31,IF(CL35=$CP$4,$CQ$32-$CQ$31+$CQ$24-$CQ$20,0)) -> 1859558 | CS35: =CS32-CQ32 -> 0 | CT35: =CT32-CQ32+CQ31 -> 0 | CU35: 리스료할인액 | CX35: =견적관리자용!$S$17 -> 화물(4.6톤 이상) | CY35: 0 | CZ35: 650000 | DA35: 650000 | DB35: 650000 | DC35: 650000 | DD35: =HLOOKUP($CI$6,$CY$4:$DC$145,DE35,TRUE) -> 650000 | DE35: 32 | DF35: =IF($CI$5=CX35,DD35,0) -> 0 | DI35: 25 | DJ35: =IF(DI35<$CP$4,$AG$10,IF(DI35=$CP$4,$AG$10+$CI$42,0)) -> 1859600 | DK35: =DJ35/(1+$DJ$8)^DI35 -> 1682913.8
D36: 개인(사업자) | J36: ㆍ사업자등록증 사본 ㆍ운전면허증사본 ㆍ주민등록등본 ㆍ인감증명서 ㆍ소득/재산 증빙서류 | AT36: 영업담당자 | BD36: OOO | BM36: 010-0000-0000 | BY36: 제휴수수료율 | BZ36: =BZ37/BZ34 -> 0 | CE36: =IF(X2="",0,1) -> 0 | CH36: 최소 잔가율 | CI36: =IF($CI$24=12,견적관리자용!$Q$35,IF($CI$24=24,견적관리자용!$Q$36,IF($CI$24=36,견적관리자용!$Q$37,IF($CI$24=48,견적관리자용!$Q$38,IF($CI$24=60,견적관리자용!$Q$39,20%))))) -> 0.15 | CL36: 31 | CM36: =IF(CL36<$CP$4,$CQ$32-$CQ$31,IF(CL36=$CP$4,$CQ$32-$CQ$31+$CQ$24-$CQ$20,0)) -> 1859558 | CS36: =CS35/CS32 -> 0 | CT36: =CT35/CT32 -> 0 | CU36: 리스료할인율 | CW36: 인천 | CX36: =견적관리자용!$S$8 -> 승용일반 | CY36: 0 | CZ36: 0 | DA36: 0.04 | DB36: 0.04 | DC36: 0.05 | DD36: =HLOOKUP($CI$6,$CY$4:$DC$145,DE36,TRUE) -> 0.05 | DE36: 33 | DF36: =IF($CI$5=CX36,DD36,0) -> 0 | DG36: =SUM(DF36:DF45) -> 390000 | DI36: 26 | DJ36: =IF(DI36<$CP$4,$AG$10,IF(DI36=$CP$4,$AG$10+$CI$42,0)) -> 1859600 | DK36: =DJ36/(1+$DJ$8)^DI36 -> 1676206.6
J37: ㆍ자동이체 통장 사본 ※ 전문직종사자는 자격/면허증 사본 필수 | AT37: 적용금리 | BD37: =$CQ$34 -> 0.05153 | BY37: 제휴수수료 | BZ37: =ROUNDDOWN(CI71,0) -> 0 | CE37: =IF(C3="",0,1)-1 -> 0 | CH37: 최소 잔가액 | CI37: =ROUNDDOWN($CI$9*$CI$36,-1) -> 23940000 | CL37: 32 | CM37: =IF(CL37<$CP$4,$CQ$32-$CQ$31,IF(CL37=$CP$4,$CQ$32-$CQ$31+$CQ$24-$CQ$20,0)) -> 1859558 | CO37: 차세 | CX37: =견적관리자용!$S$9 -> 승용SUV(~5인) | CY37: 0 | CZ37: 0 | DA37: 0.04 | DB37: 0.04 | DC37: 0.05 | DD37: =HLOOKUP($CI$6,$CY$4:$DC$145,DE37,TRUE) -> 0.05 | DE37: 34 | DF37: =IF($CI$5=CX37,DD37,0) -> 0 | DI37: 27 | DJ37: =IF(DI37<$CP$4,$AG$10,IF(DI37=$CP$4,$AG$10+$CI$42,0)) -> 1859600 | DK37: =DJ37/(1+$DJ$8)^DI37 -> 1669526.2
D38: 법인사업자 | J38: ㆍ사업자등록증 사본 ㆍ법인등기부등본 ㆍ법인인감증명서 ㆍ최근2개년 재무제표 ㆍ주주명부 | AT38: 보증금률 표시기준 | BD38: 차량가 기준 | CE38: =IF(X3="",0,1) -> 0 | CH38: 최소 잔가율 (취득원가비) | CI38: =ROUNDDOWN($CI$37/$CI$23,4) -> 0.141 | CL38: 33 | CM38: =IF(CL38<$CP$4,$CQ$32-$CQ$31,IF(CL38=$CP$4,$CQ$32-$CQ$31+$CQ$24-$CQ$20,0)) -> 1859558 | CO38: 0 | CP38: 104 | CX38: =견적관리자용!$S$10 -> 승용SUV(7~10인) | CY38: 0 | CZ38: 390000 | DA38: 390000 | DB38: 390000 | DC38: 390000 | DD38: =HLOOKUP($CI$6,$CY$4:$DC$145,DE38,TRUE) -> 390000 | DE38: 35 | DF38: =IF($CI$5=CX38,DD38,0) -> 390000 | DI38: 28 | DJ38: =IF(DI38<$CP$4,$AG$10,IF(DI38=$CP$4,$AG$10+$CI$42,0)) -> 1859600 | DK38: =DJ38/(1+$DJ$8)^DI38 -> 1662872.5
J39: ㆍ자동이체 통장 사본 ※ 대표이사 연대보증 필수 (신분증/주민등록등본/인감증명서/소득,재산증빙 서류) | AT39: ="* CM수수료(실수령기준):" -> * CM수수료(실수령기준): | BD39: =ROUNDDOWN($CI$23*$BD$31*0.967,-2) -> 0 | CD39: 금리표시체크 | CE39: TRUE | CH39: 취득원가비율 | CI39: =ROUNDDOWN($CI$23*$BK$27,-3) -> 98458000 | CL39: 34 | CM39: =IF(CL39<$CP$4,$CQ$32-$CQ$31,IF(CL39=$CP$4,$CQ$32-$CQ$31+$CQ$24-$CQ$20,0)) -> 1859558 | CO39: 1000 | CP39: 182 | CX39: =견적관리자용!$S$11 -> 승합(11~15인) | CY39: 0 | CZ39: 0.015 | DA39: 0.015 | DB39: 0.015 | DC39: 0.015 | DD39: =HLOOKUP($CI$6,$CY$4:$DC$145,DE39,TRUE) -> 0.015 | DE39: 36 | DF39: =IF($CI$5=CX39,DD39,0) -> 0 | DI39: 29 | DJ39: =IF(DI39<$CP$4,$AG$10,IF(DI39=$CP$4,$AG$10+$CI$42,0)) -> 1859600 | DK39: =DJ39/(1+$DJ$8)^DI39 -> 1656245.2
CD40: 보증잔가율기준체크 | CE40: =IF(BD38="차량가 기준",TRUE,FALSE) -> TRUE | CH40: 차량가비율 | CI40: =ROUNDDOWN($CI$9*$BK$27,-3) -> 92568000 | CL40: 35 | CM40: =IF(CL40<$CP$4,$CQ$32-$CQ$31,IF(CL40=$CP$4,$CQ$32-$CQ$31+$CQ$24-$CQ$20,0)) -> 1859558 | CO40: 1601 | CP40: 260 | CX40: =견적관리자용!$S$12 -> 화물(1000cc 미만) | CY40: 0 | CZ40: 0 | DA40: 0 | DB40: 0 | DC40: 0 | DD40: =HLOOKUP($CI$6,$CY$4:$DC$145,DE40,TRUE) -> 0 | DE40: 37 | DF40: =IF($CI$5=CX40,DD40,0) -> 0 | DI40: 30 | DJ40: =IF(DI40<$CP$4,$AG$10,IF(DI40=$CP$4,$AG$10+$CI$42,0)) -> 1859600 | DK40: =DJ40/(1+$DJ$8)^DI40 -> 1649644.4
CD41: 설정금액표시체크 | CE41: FALSE | CH41: 금액입력 | CI41: =$BQ$27 -> 0 | CL41: 36 | CM41: =IF(CL41<$CP$4,$CQ$32-$CQ$31,IF(CL41=$CP$4,$CQ$32-$CQ$31+$CQ$24-$CQ$20,0)) -> 1859558 | CO41: 2001 | CP41: 260 | CX41: =견적관리자용!$S$13 -> 화물(0.6톤 미만) | CY41: 0 | CZ41: 0.015 | DA41: 0.015 | DB41: 0.015 | DC41: 0.015 | DD41: =HLOOKUP($CI$6,$CY$4:$DC$145,DE41,TRUE) -> 0.015 | DE41: 38 | DF41: =IF($CI$5=CX41,DD41,0) -> 0 | DI41: 31 | DJ41: =IF(DI41<$CP$4,$AG$10,IF(DI41=$CP$4,$AG$10+$CI$42,0)) -> 1859600 | DK41: =DJ41/(1+$DJ$8)^DI41 -> 1643069.8
...

Sheet 금융리스
C3: 금융리스 견적서 | CW3: 공채 (비사업용)
AI4: =운용리스!AJ4 -> 0 | AT4: 고객명 | BD4: VVIP | CH4: 등록지 | CI4: =IF($BD$15="당사명의","부산",$BN$15) -> 부산 | CL4: 실제IRR | CM4: =IRR($CM$5:$CM$65,0)*12 -> #VALUE! | CO4: 리스기간 | CP4: =$CI$24 -> 36 | CQ4: =$CP$4 -> 36 | CW4: 배기량 → | CY4: 0 | CZ4: 1000 | DA4: 1500 | DB4: 1600 | DC4: 2000 | DE4: 1
D5: =IF($BD$4="","VVIP 고객님",$BD$4&" 고객님") -> VVIP 고객님 | Z5: 견적발행일 | AI5: =TODAY() -> 45946 | AT5: Brand | BD5: BENZ | BY5: 비제휴사 | CH5: 차종구분 | CI5: =IF($BQ$7="DB자동연결",$BD$7,$BQ$7) -> 승용일반 | CL5: 0 | CM5: =-$CP$17+$CP$22 -> #N/A | CO5: IRR | CP5: =$CI$25 -> 0.1 | CQ5: =$CP$5 -> 0.1 | DE5: 2 | DG5: =IF($CI$4="서울",$DG$6,IF($CI$4="부산",$DG$16,IF($CI$4="대구",$DG$26,IF($CI$4="인천",$DG$36,IF($CI$4="대전",$DG$46,IF($CI$4="광주",$DG$56,IF($CI$4="울산/강원/전남",$DG$66,IF($CI$4="제주",$DG$76,IF($CI$4="세종/경북",$DG$86,IF($CI$4="경기",$DG$96,IF($CI$4="충남",$DG$106,IF($CI$4="충북",$DG$116,IF($CI$4="전북",$DG$126,IF($CI$4="경남",$DG$136,0)))))))))))))) -> 0
Z6: 견적유효기간 | AI6: =AI5+7 -> 45953 | AT6: Model | BD6: A 250 4Matic Sedan | BY6: ↑ KCC오토 진행시 필수 선택 | CH6: 배기량 | CI6: =IF($BQ$8>0,$BQ$8,$BD$8) -> 1991 | CL6: 1 | CM6: =IF(CL6<$CQ$4,$CQ$28,IF(CL6=$CQ$4,$CQ$28+$CQ$24,0)) -> #N/A | CW6: 서울 | CX6: =견적관리자용!$S$8 -> 승용일반 | CY6: 0 | CZ6: 0.09 | DA6: 0.09 | DB6: 0.12 | DC6: 0.2 | DD6: =HLOOKUP($CI$6,$CY$4:$DC$145,DE6,TRUE) -> 0.12 | DE6: 3 | DF6: =IF($CI$5=CX6,DD6,0) -> 0.12 | DG6: =SUM(DF6:DF15) -> 0.12
Z7: 영업담당자 | AF7: =IF(BD30=0,"",BD30) -> OOO | AJ7: =BM30 -> 010-0000-0000 | AT7: 차종구분 | BD7: =VLOOKUP($BD$6,차량DB!$F$5:$P$88845,3,FALSE) -> 승용일반 | BK7: 직접선택→ | BQ7: DB자동연결 | BY7: 차종직접입력 | CD7: 모델명수기입력 | CE7: FALSE | CH7: 하이브리드여부 | CI7: =+VLOOKUP(BD6,차량DB!F:Q,12,0) -> 0 | CL7: 2 | CM7: =IF(CL7<$CQ$4,$CQ$28,IF(CL7=$CQ$4,$CQ$28+$CQ$24,0)) -> #N/A | CP7: 실제값 | CQ7: IRR 반영값 | CX7: =견적관리자용!$S$9 -> 승용SUV(~5인) | CY7: 0 | CZ7: 0.05 | DA7: 0.05 | DB7: 0.05 | DC7: 0.05 | DD7: =HLOOKUP($CI$6,$CY$4:$DC$145,DE7,TRUE) -> 0.05 | DE7: 4 | DF7: =IF($CI$5=CX7,DD7,0) -> 0
D8: =IF(CE7=FALSE,$BD$6,BZ7) -> A 250 4Matic Sedan | AT8: 배기량 | BD8: =VLOOKUP($BD$6,차량DB!$F$5:$P$88845,2,FALSE) -> 1991 | BK8: 직접입력→ | BQ8: 0 | BY8: ↑ 모델 없을시 직접입력(잔가군 문의 요망) | CD8: 제휴수수료면제여부 | CE8: FALSE | CH8: 고잔가가능 | CI8: =IFERROR(IF($CJ$8="모두가능","Y",IF($CJ$8="모두불가","",VLOOKUP($BD$6,차량DB!$F$5:$P$88845,11,FALSE))),"") -> Y | CJ8: =견적관리자용!$Q$30 -> DB적용 | CL8: 3 | CM8: =IF(CL8<$CQ$4,$CQ$28,IF(CL8=$CQ$4,$CQ$28+$CQ$24,0)) -> #N/A | CO8: 리스원금 | CP8: =$CI$23 -> 53381810 | CQ8: =$CP$8 -> 53381810 | CX8: =견적관리자용!$S$10 -> 승용SUV(7~10인) | CY8: 0 | CZ8: 390000 | DA8: 390000 | DB8: 390000 | DC8: 390000 | DD8: =HLOOKUP($CI$6,$CY$4:$DC$145,DE8,TRUE) -> 390000 | DE8: 5 | DF8: =IF($CI$5=CX8,DD8,0) -> 0
D9: 배기량 | K9: =$CI$6 -> 1991 | Z9: 리스원금 | AG9: =$CI$23 -> 53381810 | AT9: 기본차량가(직접입력) | BD9: 50000000 | CH9: 차량가격(계산서가) | CI9: =$BD$14 -> 50000000 | CL9: 4 | CM9: =IF(CL9<$CQ$4,$CQ$28,IF(CL9=$CQ$4,$CQ$28+$CQ$24,0)) -> #N/A | CO9: AG수수료 | CP9: =$CI$56 -> #N/A | CQ9: =$CP$9 -> #N/A | CX9: =견적관리자용!$S$11 -> 승합(11~15인) | CY9: 0 | CZ9: 390000 | DA9: 390000 | DB9: 390000 | DC9: 390000 | DD9: =HLOOKUP($CI$6,$CY$4:$DC$145,DE9,TRUE) -> 390000 | DE9: 6 | DF9: =IF($CI$5=CX9,DD9,0) -> 0
F10: 기본 | K10: =$BD$10 -> 50000000 | Z10: 리스기간 | AG10: =$CI$24 -> 36 | AU10: 기본차량가 | BD10: =BD9 -> 50000000 | CH10: 공채매입액 | CI10: =IF($DG$5>1,$DG$5,$CI$9/1.1*$DG$5) -> 0 | CL10: 5 | CM10: =IF(CL10<$CQ$4,$CQ$28,IF(CL10=$CQ$4,$CQ$28+$CQ$24,0)) -> #N/A | CO10: CM수수료 | CP10: =$CI$61 -> 0 | CQ10: =$CP$10 -> 0 | CX10: =견적관리자용!$S$12 -> 화물(1000cc 미만) | CY10: 0 | CZ10: 0 | DA10: 0 | DB10: 0 | DC10: 0 | DD10: =HLOOKUP($CI$6,$CY$4:$DC$145,DE10,TRUE) -> 0 | DE10: 7 | DF10: =IF($CI$5=CX10,DD10,0) -> 0
F11: 옵션 | K11: =$BD$11 -> 0 | AA11: 리스료 | AG11: =ROUNDUP(IF($CE$34>0,"ERROR",$CQ$28),-2) -> #N/A | AU11: 옵션 | BD11: 0 | CD11: 할인비율 | CE11: =IF($BD$12="비율입력",TRUE,FALSE) -> TRUE | CH11: 공채비용 | CI11: =IF($BQ$16>0,$BQ$16,ROUNDDOWN($CI$10*$BD$16,-2)) -> 0 | CL11: 6 | CM11: =IF(CL11<$CQ$4,$CQ$28,IF(CL11=$CQ$4,$CQ$28+$CQ$24,0)) -> #N/A | CO11: 제휴수수료 | CP11: =$CI$70 -> 0 | CQ11: =IF(견적관리자용!$O$9="반영",$CP$11,0) -> 0 | CX11: =견적관리자용!$S$13 -> 화물(0.6톤 미만) | CY11: 0 | CZ11: 195000 | DA11: 195000 | DB11: 195000 | DC11: 195000 | DD11: =HLOOKUP($CI$6,$CY$4:$DC$145,DE11,TRUE) -> 195000 | DE11: 8 | DF11: =IF($CI$5=CX11,DD11,0) -> 0
F12: 할인 | K12: =-$CE$13 -> 0 | AA12: 자동차세 | AG12: =$CQ$30 -> 0 | AU12: 할인 | BD12: 비율입력 | BK12: 0 | BQ12: 0 | CD12: 할인금액 | CE12: =IF($BD$12="금액입력",TRUE,FALSE) -> FALSE | CH12: 차종구분(대) | CI12: =LEFT($CI$5,2) -> 승용 | CL12: 7 | CM12: =IF(CL12<$CQ$4,$CQ$28,IF(CL12=$CQ$4,$CQ$28+$CQ$24,0)) -> #N/A | CO12: 기타비용 | CP12: =$CI$79 -> 0 | CQ12: =IF(견적관리자용!$O$17="반영",$CP$12,0) -> 0 | CX12: =견적관리자용!$S$14 -> 화물(0.6~1톤 미만) | CY12: 0 | CZ12: 195000 | DA12: 195000 | DB12: 195000 | DC12: 195000 | DD12: =HLOOKUP($CI$6,$CY$4:$DC$145,DE12,TRUE) -> 195000 | DE12: 9 | DF12: =IF($CI$5=CX12,DD12,0) -> 0
F13: =IF($BD$13>0,"탁송료","") | K13: =IF($BD$13>0,$BD$13,"") | AA13: 보험료 | AG13: =$CI$86 -> 0 | AU13: (계산서포함)탁송료 | BD13: 0 | CD13: 최종할인금액 | CE13: =IF($BD$12="금액입력",$BQ$12,TRUNC(($BD$10+$BD$11)*$BK$12,-1)) -> 0 | CH13: 취득세율 | CI13: =IF($CI$12="승용",7%,IF($CI$12="승합",5%,IF($CI$12="화물",5%,7%))) -> 0.07 | CL13: 8 | CM13: =IF(CL13<$CQ$4,$CQ$28,IF(CL13=$CQ$4,$CQ$28+$CQ$24,0)) -> #N/A | CO13: 용품/서비스비용 | CP13: =$CI$84 -> 0 | CQ13: =$CP$13 -> 0 | CX13: =견적관리자용!$S$15 -> 화물(1~2.5톤 미만) | CY13: 0 | CZ13: 390000 | DA13: 390000 | DB13: 390000 | DC13: 390000 | DD13: =HLOOKUP($CI$6,$CY$4:$DC$145,DE13,TRUE) -> 390000 | DE13: 10 | DF13: =IF($CI$5=CX13,DD13,0) -> 0
E14: 차량가격 | K14: =$CI$9 -> 50000000 | Z14: 月납입금 | AG14: =IF(BD31>19.5%,"금리기준초과",$AG$11+$AG$12+$AG$13) -> #N/A | AT14: 차량가격(계산서가) | BD14: =$BD$10+$BD$11-$CE$13+$BD$13 -> 50000000 | CD14: 리스사명의 | CE14: =IF($BD$15="당사명의",TRUE,FALSE) -> TRUE | CH14: 자동반영(1) | CI14: =ROUNDDOWN($CI$9/1.1*$CI$13,-1) -> 3181810 | CL14: 9 | CM14: =IF(CL14<$CQ$4,$CQ$28,IF(CL14=$CQ$4,$CQ$28+$CQ$24,0)) -> #N/A | CX14: =견적관리자용!$S$16 -> 화물(2.5~4.6톤 미만) | CY14: 0 | CZ14: 390000 | DA14: 390000 | DB14: 390000 | DC14: 390000 | DD14: =HLOOKUP($CI$6,$CY$4:$DC$145,DE14,TRUE) -> 390000 | DE14: 11 | DF14: =IF($CI$5=CX14,DD14,0) -> 0
E15: 취득세 | K15: =$CI$21 -> 3181810 | Z15: 만기유예금 | AG15: =CI36 -> 0 | AT15: 차량명의/등록지 | BD15: 당사명의 | BN15: 인천 | CD15: 이용자명의 | CE15: =IF($BD$15="이용자명의",TRUE,FALSE) -> FALSE | CH15: 경차 75만초과분 부담 | CI15: =IF($CI$14<750000,0,$CI$14-750000) -> 2431810 | CL15: 10 | CM15: =IF(CL15<$CQ$4,$CQ$28,IF(CL15=$CQ$4,$CQ$28+$CQ$24,0)) -> #N/A | CO15: 이용자명의리스설정료 | CP15: =$CI$83 -> 0 | CQ15: =IF(견적관리자용!$Q$25="반영",$CP$15,0) -> 0 | CX15: =견적관리자용!$S$17 -> 화물(4.6톤 이상) | CY15: 0 | CZ15: 650000 | DA15: 650000 | DB15: 650000 | DC15: 650000 | DD15: =HLOOKUP($CI$6,$CY$4:$DC$145,DE15,TRUE) -> 650000 | DE15: 12 | DF15: =IF($CI$5=CX15,DD15,0) -> 0
E16: 공채비용 | K16: =$CI$11 -> 0 | Z16: 초기납입금 | AG16: =$CI$31 -> 0 | AT16: 공채 | BD16: 0.05 | BK16: 직접입력→ | CH16: 자동반영 (하이브리드) | CI16: =+IF(AND(CI7="하이브리드",CI14>=400000),CI14-400000,0) -> 0 | CL16: 11 | CM16: =IF(CL16<$CQ$4,$CQ$28,IF(CL16=$CQ$4,$CQ$28+$CQ$24,0)) -> #N/A | CO16: 인지세 | CP16: =$CI$80 -> 10000 | CQ16: =IF(견적관리자용!$Q$24="반영",$CP$16,0) -> 10000 | CW16: 부산 | CX16: =견적관리자용!$S$8 -> 승용일반 | CY16: 0 | CZ16: 0 | DA16: 0 | DB16: 0 | DC16: 0.05 | DD16: =HLOOKUP($CI$6,$CY$4:$DC$145,DE16,TRUE) -> 0 | DE16: 13 | DF16: =IF($CI$5=CX16,DD16,0) -> 0 | DG16: =SUM(DF16:DF25) -> 0
E17: 기타부대비 | K17: =$BD$17 -> 100000 | AT17: 기타부대비 | BD17: 100000 | BN17: ≤ | BP17: =견적관리자용!$T$35 -> 0 | CH17: 자동반영 | CI17: =IF($CI$6<1000,$CI$15,IF(CI7="하이브리드",CI16,$CI$14)) -> 3181810 | CL17: 12 | CM17: =IF(CL17<$CQ$4,$CQ$28,IF(CL17=$CQ$4,$CQ$28+$CQ$24,0)) -> #N/A | CO17: MINUS | CP17: =SUM($CP$8:$CP$16) -> #N/A | CQ17: =SUM($CQ$8:$CQ$16) -> #N/A | CX17: =견적관리자용!$S$9 -> 승용SUV(~5인) | CY17: 0 | CZ17: 0 | DA17: 0 | DB17: 0 | DC17: 0 | DD17: =HLOOKUP($CI$6,$CY$4:$DC$145,DE17,TRUE) -> 0 | DE17: 14 | DF17: =IF($CI$5=CX17,DD17,0) -> 0
E18: =IF($BD$18>0,"탁송료","") -> 탁송료 | K18: =IF($BD$18>0,$BD$18,"") -> 100000 | AT18: 탁송료 | BD18: 100000 | BN18: ≤ | BP18: =견적관리자용!$T$36 -> 500000 | CD18: 취득세 비율입력 | CE18: =IF($BD$19="비율입력",TRUE,FALSE) -> FALSE | CH18: 비율입력 | CI18: =ROUNDDOWN($CI$9/1.1*$BK$19,-1) -> 3181810 | CL18: 13 | CM18: =IF(CL18<$CQ$4,$CQ$28,IF(CL18=$CQ$4,$CQ$28+$CQ$24,0)) -> #N/A | CX18: =견적관리자용!$S$10 -> 승용SUV(7~10인) | CY18: 0 | CZ18: 0 | DA18: 0 | DB18: 0 | DC18: 0 | DD18: =HLOOKUP($CI$6,$CY$4:$DC$145,DE18,TRUE) -> 0 | DE18: 15 | DF18: =IF($CI$5=CX18,DD18,0) -> 0
D19: 취득원가 | K19: =$CI$22 -> 53381810 | Y19: =IF(BD29="신차보상보험(1년)"," ※ 신차보상보험 1년 제공",IF(BD29="신차보상보험(3년)"," ※ 신차보상보험 3년 제공","")) | AT19: 취득세 (직접입력시만 사용) | BD19: 자동반영 | BK19: 0.07 | BQ19: 0 | BY19: - 하이브리드, 전기차, 경차 등 특례해당건 취득세 재확인 요망 | CD19: 취득세 감면액입력 | CE19: =IF($BD$19="감면액입력",TRUE,FALSE) -> FALSE | CH19: 감면액입력 | CI19: =$CI$17-$BQ$19 -> 3181810 | CL19: 14 | CM19: =IF(CL19<$CQ$4,$CQ$28,IF(CL19=$CQ$4,$CQ$28+$CQ$24,0)) -> #N/A | CX19: =견적관리자용!$S$11 -> 승합(11~15인) | CY19: 0 | CZ19: 0 | DA19: 0 | DB19: 0 | DC19: 0 | DD19: =HLOOKUP($CI$6,$CY$4:$DC$145,DE19,TRUE) -> 0 | DE19: 16 | DF19: =IF($CI$5=CX19,DD19,0) -> 0
BK20: 0 | CD20: 취득세 금액입력 | CE20: =IF($BD$19="금액입력",TRUE,FALSE) -> FALSE | CH20: 금액입력 | CI20: =$BK$20 -> 0 | CL20: 15 | CM20: =IF(CL20<$CQ$4,$CQ$28,IF(CL20=$CQ$4,$CQ$28+$CQ$24,0)) -> #N/A | CX20: =견적관리자용!$S$12 -> 화물(1000cc 미만) | CY20: 0 | CZ20: 0 | DA20: 0 | DB20: 0 | DC20: 0 | DD20: =HLOOKUP($CI$6,$CY$4:$DC$145,DE20,TRUE) -> 0 | DE20: 17 | DF20: =IF($CI$5=CX20,DD20,0) -> 0
CH21: 최종 취득세 | CI21: =VLOOKUP($BD$19,$CH$17:$CI$20,2,FALSE) -> 3181810 | CL21: 16 | CM21: =IF(CL21<$CQ$4,$CQ$28,IF(CL21=$CQ$4,$CQ$28+$CQ$24,0)) -> #N/A | CO21: 이손액 | CP21: =$CI$87 -> 0 | CQ21: =$CP$21 -> 0 | CX21: =견적관리자용!$S$13 -> 화물(0.6톤 미만) | CY21: 0 | CZ21: 0 | DA21: 0 | DB21: 0 | DC21: 0 | DD21: =HLOOKUP($CI$6,$CY$4:$DC$145,DE21,TRUE) -> 0 | DE21: 18 | DF21: =IF($CI$5=CX21,DD21,0) -> 0
AT22: 리스기간(개월) | BD22: 36 | CH22: 총구매비용 | CI22: =$CI$9+$CI$11+$CI$21+$BD$17+$BD$18 -> 53381810 | CL22: 17 | CM22: =IF(CL22<$CQ$4,$CQ$28,IF(CL22=$CQ$4,$CQ$28+$CQ$24,0)) -> #N/A | CO22: PLUS | CP22: =SUM($CP$19:$CP$21) -> 0 | CQ22: =SUM($CQ$19:$CQ$21) -> 0 | CX22: =견적관리자용!$S$14 -> 화물(0.6~1톤 미만) | CY22: 0 | CZ22: 0 | DA22: 0 | DB22: 0 | DC22: 0 | DD22: =HLOOKUP($CI$6,$CY$4:$DC$145,DE22,TRUE) -> 0 | DE22: 19 | DF22: =IF($CI$5=CX22,DD22,0) -> 0
AT23: 선수금(리스원금) | BD23: 차량가비율 | BK23: 0 | BY23: - 리스원금 차량가격 이상 취급 불가 | CD23: 선수금 금액입력 | CE23: =IF(OR($BD$23="총구매비용비율",$BD$23="차량가비율"),TRUE,FALSE) -> TRUE | CF23: =IF($CE$23=TRUE,FALSE,TRUE) -> FALSE | CH23: 리스원금 | CI23: =CI22-CI31 -> 53381810 | CL23: 18 | CM23: =IF(CL23<$CQ$4,$CQ$28,IF(CL23=$CQ$4,$CQ$28+$CQ$24,0)) -> #N/A | CX23: =견적관리자용!$S$15 -> 화물(1~2.5톤 미만) | CY23: 0 | CZ23: 0 | DA23: 0 | DB23: 0 | DC23: 0 | DD23: =HLOOKUP($CI$6,$CY$4:$DC$145,DE23,TRUE) -> 0 | DE23: 20 | DF23: =IF($CI$5=CX23,DD23,0) -> 0
D24: ▷계약시 유의사항 | AT24: 유예 | BD24: 리스원금비율 | BK24: 0 | BQ24: 0 | BZ24: =AN18 -> 0 | CH24: 리스기간 | CI24: =$BD$22 -> 36 | CL24: 19 | CM24: =IF(CL24<$CQ$4,$CQ$28,IF(CL24=$CQ$4,$CQ$28+$CQ$24,0)) -> #N/A | CO24: 유예 | CP24: =$CI$36 -> 0 | CQ24: =$CP$24 -> 0 | CX24: =견적관리자용!$S$16 -> 화물(2.5~4.6톤 미만) | CY24: 0 | CZ24: 0 | DA24: 0 | DB24: 0 | DC24: 0 | DD24: =HLOOKUP($CI$6,$CY$4:$DC$145,DE24,TRUE) -> 0 | DE24: 21 | DF24: =IF($CI$5=CX24,DD24,0) -> 0
D25: * 지방세법 제10조 개정(시행 '23.1.1)에 따라 취득세 과세표준을 취득가액과 시가표준액 중 높은 금액을 | AT25: CM수수료율 | BD25: 0 | BN25: ≤ | BP25: =CI92 -> #N/A | CH25: IRR | CI25: =IF($BD$15="당사명의",VLOOKUP($BD$5,견적관리자용!$E$9:$K$36,4,FALSE),VLOOKUP($BD$5,견적관리자용!$E$9:$K$36,5,FALSE)) -> 0.1 | CL25: 20 | CM25: =IF(CL25<$CQ$4,$CQ$28,IF(CL25=$CQ$4,$CQ$28+$CQ$24,0)) -> #N/A | CX25: =견적관리자용!$S$17 -> 화물(4.6톤 이상) | CY25: 0 | CZ25: 0 | DA25: 0 | DB25: 0 | DC25: 0 | DD25: =HLOOKUP($CI$6,$CY$4:$DC$145,DE25,TRUE) -> 0 | DE25: 22 | DF25: =IF($CI$5=CX25,DD25,0) -> 0
D26: 과세표준으로 하도록 규정되어 견적서 상의 취득세와 상이할 수 있습니다. 이와 같은 경우, 고객님께서 | AT26: 자동차세 | BD26: 미포함(별도청구) | BK26: 직접입력→ | BQ26: 0 | BY26: 제휴사 | BZ26: =BY5&IF(CE8=TRUE,"(제휴면제)","") -> 비제휴사 | CD26: 유예 금액입력 | CE26: =IF($BD$24="금액입력",TRUE,FALSE) -> FALSE | CF26: =IF($CE$26=TRUE,FALSE,TRUE) -> TRUE | CL26: 21 | CM26: =IF(CL26<$CQ$4,$CQ$28,IF(CL26=$CQ$4,$CQ$28+$CQ$24,0)) -> #N/A | CO26: PMT(1) | CQ26: =ROUNDDOWN(PMT($CQ$5/12,$CQ$4,-$CQ$17+$CQ$22,$CQ$24-$CQ$20),0) -> #N/A | CW26: 대구 | CX26: =견적관리자용!$S$8 -> 승용일반 | CY26: 0 | CZ26: 0.04 | DA26: 0.04 | DB26: 0.04 | DC26: 0.05 | DD26: =HLOOKUP($CI$6,$CY$4:$DC$145,DE26,TRUE) -> 0.04 | DE26: 23 | DF26: =IF($CI$5=CX26,DD26,0) -> 0.04 | DG26: =SUM(DF26:DF35) -> 0.04
D27: 취등록세 차액분을 직접 납부해주셔야 하며, 영업담당자는 반드시 과세표준 확인 후 견적부탁드립니다. | AT27: 보험료(年) | BD27: 0 | BY27: 리스원금 | BZ27: =CI23 -> 53381810 | CL27: 22 | CM27: =IF(CL27<$CQ$4,$CQ$28,IF(CL27=$CQ$4,$CQ$28+$CQ$24,0)) -> #N/A | CO27: RATE(1) | CQ27: =RATE($CQ$4,$CQ$26,-$CQ$8+$CQ$19,$CQ$24)*12 -> #N/A | CX27: =견적관리자용!$S$9 -> 승용SUV(~5인) | CY27: 0 | CZ27: 0.04 | DA27: 0.04 | DB27: 0.04 | DC27: 0.04 | DD27: =HLOOKUP($CI$6,$CY$4:$DC$145,DE27,TRUE) -> 0.04 | DE27: 24 | DF27: =IF($CI$5=CX27,DD27,0) -> 0
D28: =IF(BD18="당사명의","* 리스차량 명의는 엠캐피탈㈜ 등록입니다.","* 리스차량 명의는 이용자 등록입니다.") -> * 리스차량 명의는 이용자 등록입니다. | AT28: 이손액(수입수수료) | BD28: 0 | BY28: 제휴수수료율 | BZ28: =BZ29/BZ27 -> 0 | CL28: 23 | CM28: =IF(CL28<$CQ$4,$CQ$28,IF(CL28=$CQ$4,$CQ$28+$CQ$24,0)) -> #N/A | CO28: PMT(2) 최종 순리스료 | CQ28: =PMT(CQ29/12,CQ4,-CQ8,CQ24) -> #N/A | CX28: =견적관리자용!$S$10 -> 승용SUV(7~10인) | CY28: 0 | CZ28: 390000 | DA28: 390000 | DB28: 390000 | DC28: 390000 | DD28: =HLOOKUP($CI$6,$CY$4:$DC$145,DE28,TRUE) -> 390000 | DE28: 25 | DF28: =IF($CI$5=CX28,DD28,0) -> 0
D29: * 보험은 자차 질권설정(차량가 100%) 후 증권사본 송부 부탁드립니다.(엠캐피탈㈜, 105-81-87072) | AT29: 부가서비스 | BD29: - | BY29: 제휴수수료 | BZ29: =ROUNDDOWN(CI70,0) -> 0 | CL29: 24 | CM29: =IF(CL29<$CQ$4,$CQ$28,IF(CL29=$CQ$4,$CQ$28+$CQ$24,0)) -> #N/A | CO29: RATE(2) 최종금리 | CQ29: =ROUND(CQ27,5) -> #N/A | CX29: =견적관리자용!$S$11 -> 승합(11~15인) | CY29: 0 | CZ29: 390000 | DA29: 390000 | DB29: 390000 | DC29: 390000 | DD29: =HLOOKUP($CI$6,$CY$4:$DC$145,DE29,TRUE) -> 390000 | DE29: 26 | DF29: =IF($CI$5=CX29,DD29,0) -> 0
D30: * 운행중 발생하는 범칙금 및 과태료는 이용자 부담이며, 중도상환시 약정에 따른 수수료가 발생합니다. | AT30: 차량상담 | BD30: OOO | BM30: 010-0000-0000 | BY30: 근저당설정 | BZ30: =IF(BD15="당사명의","해당없음","100%") -> 해당없음 | CL30: 25 | CM30: =IF(CL30<$CQ$4,$CQ$28,IF(CL30=$CQ$4,$CQ$28+$CQ$24,0)) -> #N/A | CO30: 차세 | CQ30: =$CP$54 -> 0 | CX30: =견적관리자용!$S$12 -> 화물(1000cc 미만) | CY30: 0 | CZ30: 0 | DA30: 0 | DB30: 0 | DC30: 0 | DD30: =HLOOKUP($CI$6,$CY$4:$DC$145,DE30,TRUE) -> 0 | DE30: 27 | DF30: =IF($CI$5=CX30,DD30,0) -> 0
D31: * 중도상환수수료는 "잔여미회수원금 X 최대 2% * (잔여기간 월수/리스기간 전체월수)" 입니다. | AT31: 적용금리 | BD31: =$CQ$29 -> #N/A | BY31: (설정지원금) | BZ31: =CI83 -> 0 | CH31: 선수금 | CI31: =VLOOKUP($BD$23,$CH$32:$CI$35,2,FALSE) -> 0 | CL31: 26 | CM31: =IF(CL31<$CQ$4,$CQ$28,IF(CL31=$CQ$4,$CQ$28+$CQ$24,0)) -> #N/A | CX31: =견적관리자용!$S$13 -> 화물(0.6톤 미만) | CY31: 0 | CZ31: 195000 | DA31: 195000 | DB31: 195000 | DC31: 195000 | DD31: =HLOOKUP($CI$6,$CY$4:$DC$145,DE31,TRUE) -> 195000 | DE31: 28 | DF31: =IF($CI$5=CX31,DD31,0) -> 0
D32: * 상기 견적의 유효기간은 7일 이며, 7일 이후에는 당사 기준금리 및 당사 기준의 변동으로 인하여 변동 될수 있습니다. | AT32: ="* CM수수료(실수령기준):" -> * CM수수료(실수령기준): | BD32: =ROUNDDOWN($CI$22*$BD$25*0.967,-2) -> 0 | CH32: 총구매비용비율 | CI32: =ROUNDDOWN($CI$22*$BK$23,-3) -> 0 | CL32: 27 | CM32: =IF(CL32<$CQ$4,$CQ$28,IF(CL32=$CQ$4,$CQ$28+$CQ$24,0)) -> #N/A | CO32: PMT(3) 최종납입금 | CQ32: =$CQ$28+$CQ$30-$CQ$31 -> #N/A | CX32: =견적관리자용!$S$14 -> 화물(0.6~1톤 미만) | CY32: 0 | CZ32: 195000 | DA32: 195000 | DB32: 195000 | DC32: 195000 | DD32: =HLOOKUP($CI$6,$CY$4:$DC$145,DE32,TRUE) -> 195000 | DE32: 29 | DF32: =IF($CI$5=CX32,DD32,0) -> 0
D33: ▷필요서류 (발행기간 3개월내) | CH33: 차량가비율 | CI33: =ROUNDDOWN($CI$9*$BK$23,-3) -> 0 | CL33: 28 | CM33: =IF(CL33<$CQ$4,$CQ$28,IF(CL33=$CQ$4,$CQ$28+$CQ$24,0)) -> #N/A | CX33: =견적관리자용!$S$15 -> 화물(1~2.5톤 미만) | CY33: 0 | CZ33: 195000 | DA33: 195000 | DB33: 195000 | DC33: 195000 | DD33: =HLOOKUP($CI$6,$CY$4:$DC$145,DE33,TRUE) -> 195000 | DE33: 30 | DF33: =IF($CI$5=CX33,DD33,0) -> 0
D34: 개인(사업자) | J34: ㆍ사업자등록증 사본 ㆍ운전면허증사본 ㆍ주민등록등본 ㆍ인감증명서 ㆍ소득/재산 증빙서류 | CD34: 4대 중요 에러 | CE34: =SUM(CE35:CE38) -> 0 | CH34: 선수금액입력 | CI34: =$BQ$23 -> 0 | CL34: 29 | CM34: =IF(CL34<$CQ$4,$CQ$28,IF(CL34=$CQ$4,$CQ$28+$CQ$24,0)) -> #N/A | CX34: =견적관리자용!$S$16 -> 화물(2.5~4.6톤 미만) | CY34: 0 | CZ34: 390000 | DA34: 390000 | DB34: 390000 | DC34: 390000 | DD34: =HLOOKUP($CI$6,$CY$4:$DC$145,DE34,TRUE) -> 390000 | DE34: 31 | DF34: =IF($CI$5=CX34,DD34,0) -> 0
J35: ㆍ자동이체 통장 사본 ※ 전문직종사자는 자격/면허증 사본 필수 | CE35: =IF(C2="",0,1) -> 0 | CH35: 리스원금입력 | CI35: =$CI$22-$BQ$23 -> 53381810 | CL35: 30 | CM35: =IF(CL35<$CQ$4,$CQ$28,IF(CL35=$CQ$4,$CQ$28+$CQ$24,0)) -> #N/A | CX35: =견적관리자용!$S$17 -> 화물(4.6톤 이상) | CY35: 0 | CZ35: 650000 | DA35: 650000 | DB35: 650000 | DC35: 650000 | DD35: =HLOOKUP($CI$6,$CY$4:$DC$145,DE35,TRUE) -> 650000 | DE35: 32 | DF35: =IF($CI$5=CX35,DD35,0) -> 0
D36: 법인사업자 | J36: ㆍ사업자등록증 사본 ㆍ법인등기부등본 ㆍ법인인감증명서 ㆍ최근2개년 재무제표 ㆍ주주명부 | CE36: =IF(X2="",0,1) -> 0 | CH36: 유예금 | CI36: =VLOOKUP($BD$24,$CH$37:$CI$38,2,FALSE) -> 0 | CL36: 31 | CM36: =IF(CL36<$CQ$4,$CQ$28,IF(CL36=$CQ$4,$CQ$28+$CQ$24,0)) -> #N/A | CW36: 인천 | CX36: =견적관리자용!$S$8 -> 승용일반 | CY36: 0 | CZ36: 0 | DA36: 0.04 | DB36: 0.04 | DC36: 0.05 | DD36: =HLOOKUP($CI$6,$CY$4:$DC$145,DE36,TRUE) -> 0.04 | DE36: 33 | DF36: =IF($CI$5=CX36,DD36,0) -> 0.04 | DG36: =SUM(DF36:DF45) -> 0.04
J37: ㆍ자동이체 통장 사본 ※ 대표이사 연대보증 필수 (신분증/주민등록등본/인감증명서/소득,재산증빙 서류) | CE37: =IF(C3="",0,1)-1 -> 0 | CH37: 리스원금비율 | CI37: =ROUNDDOWN($CI$23*$BK$24,-3) -> 0 | CL37: 32 | CM37: =IF(CL37<$CQ$4,$CQ$28,IF(CL37=$CQ$4,$CQ$28+$CQ$24,0)) -> #N/A | CO37: 차세 | CX37: =견적관리자용!$S$9 -> 승용SUV(~5인) | CY37: 0 | CZ37: 0 | DA37: 0.04 | DB37: 0.04 | DC37: 0.05 | DD37: =HLOOKUP($CI$6,$CY$4:$DC$145,DE37,TRUE) -> 0.04 | DE37: 34 | DF37: =IF($CI$5=CX37,DD37,0) -> 0
CE38: =IF(X3="",0,1) -> 0 | CH38: 금액입력 | CI38: =$BQ$24 -> 0 | CL38: 33 | CM38: =IF(CL38<$CQ$4,$CQ$28,IF(CL38=$CQ$4,$CQ$28+$CQ$24,0)) -> #N/A | CO38: 0 | CP38: 104 | CX38: =견적관리자용!$S$10 -> 승용SUV(7~10인) | CY38: 0 | CZ38: 390000 | DA38: 390000 | DB38: 390000 | DC38: 390000 | DD38: =HLOOKUP($CI$6,$CY$4:$DC$145,DE38,TRUE) -> 390000 | DE38: 35 | DF38: =IF($CI$5=CX38,DD38,0) -> 0
CD39: 금리표시체크 | CE39: TRUE | CL39: 34 | CM39: =IF(CL39<$CQ$4,$CQ$28,IF(CL39=$CQ$4,$CQ$28+$CQ$24,0)) -> #N/A | CO39: 801 | CP39: 182 | CX39: =견적관리자용!$S$11 -> 승합(11~15인) | CY39: 0 | CZ39: 0.015 | DA39: 0.015 | DB39: 0.015 | DC39: 0.015 | DD39: =HLOOKUP($CI$6,$CY$4:$DC$145,DE39,TRUE) -> 0.015 | DE39: 36 | DF39: =IF($CI$5=CX39,DD39,0) -> 0
CL40: 35 | CM40: =IF(CL40<$CQ$4,$CQ$28,IF(CL40=$CQ$4,$CQ$28+$CQ$24,0)) -> #N/A | CO40: 1001 | CP40: 260 | CX40: =견적관리자용!$S$12 -> 화물(1000cc 미만) | CY40: 0 | CZ40: 0 | DA40: 0 | DB40: 0 | DC40: 0 | DD40: =HLOOKUP($CI$6,$CY$4:$DC$145,DE40,TRUE) -> 0 | DE40: 37 | DF40: =IF($CI$5=CX40,DD40,0) -> 0
CD41: 설정금액표시체크 | CE41: TRUE | CL41: 36 | CM41: =IF(CL41<$CQ$4,$CQ$28,IF(CL41=$CQ$4,$CQ$28+$CQ$24,0)) -> #N/A | CO41: 1601 | CP41: 260 | CX41: =견적관리자용!$S$13 -> 화물(0.6톤 미만) | CY41: 0 | CZ41: 0.015 | DA41: 0.015 | DB41: 0.015 | DC41: 0.015 | DD41: =HLOOKUP($CI$6,$CY$4:$DC$145,DE41,TRUE) -> 0.015 | DE41: 38 | DF41: =IF($CI$5=CX41,DD41,0) -> 0
CL42: 37 | CM42: =IF(CL42<$CQ$4,$CQ$28,IF(CL42=$CQ$4,$CQ$28+$CQ$24,0)) -> 0 | CP42: =VLOOKUP($CI$6,$CO$38:$CP$41,2,TRUE) -> 260 | CX42: =견적관리자용!$S$14 -> 화물(0.6~1톤 미만) | CY42: 0 | CZ42: 0.015 | DA42: 0.015 | DB42: 0.015 | DC42: 0.015 | DD42: =HLOOKUP($CI$6,$CY$4:$DC$145,DE42,TRUE) -> 0.015 | DE42: 39 | DF42: =IF($CI$5=CX42,DD42,0) -> 0
...

Sheet 할부오토론
C2: 할부/오토론 견적서
AJ3: =운용리스!AJ4 -> 0 | CW3: 공채 (비사업용)
D4: =IF($BD$4="","VVIP 고객님",$BD$4&" 고객님") -> VVIP 고객님 | Z4: 견적발행일 | AI4: =TODAY() -> 45946 | AT4: 고객명 | BD4: VVIP | CH4: 등록지 | CI4: =IF($BD$15="할부사명의(부산등록)","부산",$BN$15) -> 서울 | CL4: 실제IRR | CM4: =IRR($CM$5:$CM$65,0)*12 -> #VALUE! | CO4: 할부기간 | CP4: =$CI$24 -> 48 | CQ4: =$CP$4 -> 48 | CW4: 배기량 → | CY4: 0 | CZ4: 1000 | DA4: 1500 | DB4: 1600 | DC4: 2000 | DE4: 1
Z5: 견적유효기간 | AI5: =AI4+7 -> 45953 | AT5: Brand | BD5: Rolls_Royce | BY5: 비제휴사 | CH5: 차종구분 | CI5: =IF($BQ$7="DB자동연결",$BD$7,$BQ$7) -> 승용일반 | CL5: 0 | CM5: =-$CP$17+$CP$22 -> #N/A | CO5: IRR | CP5: =$CI$25 -> 0.065 | CQ5: =$CP$5 -> 0.065 | DE5: 2 | DG5: =IF($CI$4="서울",$DG$6,IF($CI$4="부산",$DG$16,IF($CI$4="대구",$DG$26,IF($CI$4="인천",$DG$36,IF($CI$4="대전",$DG$46,IF($CI$4="광주",$DG$56,IF($CI$4="울산/강원/전남",$DG$66,IF($CI$4="제주",$DG$76,IF($CI$4="세종/경북",$DG$86,IF($CI$4="경기",$DG$96,IF($CI$4="충남",$DG$106,IF($CI$4="충북",$DG$116,IF($CI$4="전북",$DG$126,IF($CI$4="경남",$DG$136,0)))))))))))))) -> 0
Z6: 영업담당자 | AF6: =BD29 -> OOO | AJ6: =BM29 -> 010-000-0000 | AT6: Model | BD6: SPECTRE | BY6: ↑ KCC오토 진행시 필수 선택 | CD6: 모델명수기입력 | CE6: FALSE | CH6: 배기량 | CI6: =IF($BQ$8>0,$BQ$8,$BD$8) -> 1 | CL6: 1 | CM6: =IF(CL6<$CQ$4,$CQ$28,IF(CL6=$CQ$4,$CQ$28+$CQ$24,0)) -> #N/A | CW6: 서울 | CX6: =견적관리자용!$S$8 -> 승용일반 | CY6: 0 | CZ6: 0.09 | DA6: 0.09 | DB6: 0.12 | DC6: 0.2 | DD6: =HLOOKUP($CI$6,$CY$4:$DC$145,DE6,TRUE) -> 0 | DE6: 3 | DF6: =IF($CI$5=CX6,DD6,0) -> 0 | DG6: =SUM(DF6:DF15) -> 0
AT7: 차종구분 | BD7: =VLOOKUP($BD$6,차량DB!$F$5:$P$88845,3,FALSE) -> 승용일반 | BK7: 직접선택→ | BQ7: DB자동연결 | BY7: 차종직접입력 | CD7: 제휴수수료면제여부 | CE7: FALSE | CH7: 하이브리드여부 | CI7: =+VLOOKUP(BD6,차량DB!F:Q,12,0) -> 0 | CL7: 2 | CM7: =IF(CL7<$CQ$4,$CQ$28,IF(CL7=$CQ$4,$CQ$28+$CQ$24,0)) -> #N/A | CP7: 실제값 | CQ7: IRR 반영값 | CX7: =견적관리자용!$S$9 -> 승용SUV(~5인) | CY7: 0 | CZ7: 0.05 | DA7: 0.05 | DB7: 0.05 | DC7: 0.05 | DD7: =HLOOKUP($CI$6,$CY$4:$DC$145,DE7,TRUE) -> 0 | DE7: 4 | DF7: =IF($CI$5=CX7,DD7,0) -> 0
D8: =IF(CE6=FALSE,$BD$6,BZ7) -> SPECTRE | AT8: 배기량 | BD8: =VLOOKUP($BD$6,차량DB!$F$5:$P$88845,2,FALSE) -> 1 | BK8: 직접입력→ | BQ8: 0 | BY8: ↑ 모델 없을시 직접입력(잔가군 문의 요망) | CH8: 고잔가가능 | CI8: =IFERROR(IF($CJ$8="모두가능","Y",IF($CJ$8="모두불가","",VLOOKUP($BD$6,차량DB!$F$5:$P$88845,11,FALSE))),"") -> Y | CJ8: =견적관리자용!$Q$30 -> DB적용 | CL8: 3 | CM8: =IF(CL8<$CQ$4,$CQ$28,IF(CL8=$CQ$4,$CQ$28+$CQ$24,0)) -> #N/A | CO8: 할부원금 | CP8: =$CI$23 -> 74130000 | CQ8: =$CP$8 -> 74130000 | CX8: =견적관리자용!$S$10 -> 승용SUV(7~10인) | CY8: 0 | CZ8: 390000 | DA8: 390000 | DB8: 390000 | DC8: 390000 | DD8: =HLOOKUP($CI$6,$CY$4:$DC$145,DE8,TRUE) -> 0 | DE8: 5 | DF8: =IF($CI$5=CX8,DD8,0) -> 0
D9: 배기량 | K9: =$CI$6 -> 1 | Z9: 할부원금 | AG9: =$CI$23 -> 74130000 | AT9: 기본차량가(직접입력) | BD9: 70400000 | CH9: 차량가격(계산서가) | CI9: =$BD$14 -> 70400000 | CL9: 4 | CM9: =IF(CL9<$CQ$4,$CQ$28,IF(CL9=$CQ$4,$CQ$28+$CQ$24,0)) -> #N/A | CO9: AG수수료 | CP9: =$CI$56 -> #N/A | CQ9: =$CP$9 -> #N/A | CX9: =견적관리자용!$S$11 -> 승합(11~15인) | CY9: 0 | CZ9: 390000 | DA9: 390000 | DB9: 390000 | DC9: 390000 | DD9: =HLOOKUP($CI$6,$CY$4:$DC$145,DE9,TRUE) -> 0 | DE9: 6 | DF9: =IF($CI$5=CX9,DD9,0) -> 0
F10: 기본 | K10: =$BD$10 -> 70400000 | Z10: 할부기간 | AG10: =$CI$24 -> 48 | AU10: 기본차량가 | BD10: =BD9 -> 70400000 | CH10: 공채매입액 | CI10: =IF($DG$5>1,$DG$5,$CI$9/1.1*$DG$5) -> 0 | CL10: 5 | CM10: =IF(CL10<$CQ$4,$CQ$28,IF(CL10=$CQ$4,$CQ$28+$CQ$24,0)) -> #N/A | CO10: CM수수료 | CP10: =$CI$61 -> 0 | CQ10: =$CP$10 -> 0 | CX10: =견적관리자용!$S$12 -> 화물(1000cc 미만) | CY10: 0 | CZ10: 0 | DA10: 0 | DB10: 0 | DC10: 0 | DD10: =HLOOKUP($CI$6,$CY$4:$DC$145,DE10,TRUE) -> 0 | DE10: 7 | DF10: =IF($CI$5=CX10,DD10,0) -> 0
F11: 옵션 | K11: =$BD$11 -> 0 | Z11: 月납입금 | AG11: =IF(BD30>19.5%,"금리기준초과",ROUNDUP(IF($CE$34>0,"ERROR",$CQ$28),-2)) -> #N/A | AU11: 옵션 | BD11: 0 | CD11: 할인비율 | CE11: =IF($BD$12="비율입력",TRUE,FALSE) -> FALSE | CH11: 공채비용 | CI11: =IF($BQ$16>0,$BQ$16,ROUNDDOWN($CI$10*$BD$16,-2)) -> 0 | CL11: 6 | CM11: =IF(CL11<$CQ$4,$CQ$28,IF(CL11=$CQ$4,$CQ$28+$CQ$24,0)) -> #N/A | CO11: 제휴수수료 | CP11: =$CI$70 -> 0 | CQ11: =IF(견적관리자용!$O$9="반영",$CP$11,0) -> 0 | CX11: =견적관리자용!$S$13 -> 화물(0.6톤 미만) | CY11: 0 | CZ11: 195000 | DA11: 195000 | DB11: 195000 | DC11: 195000 | DD11: =HLOOKUP($CI$6,$CY$4:$DC$145,DE11,TRUE) -> 0 | DE11: 8 | DF11: =IF($CI$5=CX11,DD11,0) -> 0
F12: 할인 | K12: =-$CE$13 -> 0 | Z12: 만기유예금 | AG12: =CI36 -> 0 | AU12: 할인 | BD12: 금액입력 | BK12: 0 | BQ12: 0 | CD12: 할인금액 | CE12: =IF($BD$12="금액입력",TRUE,FALSE) -> TRUE | CH12: 차종구분(대) | CI12: =LEFT($CI$5,2) -> 승용 | CL12: 7 | CM12: =IF(CL12<$CQ$4,$CQ$28,IF(CL12=$CQ$4,$CQ$28+$CQ$24,0)) -> #N/A | CO12: 기타비용 | CP12: =$CI$79 -> 0 | CQ12: =IF(견적관리자용!$O$17="반영",$CP$12,0) -> 0 | CX12: =견적관리자용!$S$14 -> 화물(0.6~1톤 미만) | CY12: 0 | CZ12: 195000 | DA12: 195000 | DB12: 195000 | DC12: 195000 | DD12: =HLOOKUP($CI$6,$CY$4:$DC$145,DE12,TRUE) -> 0 | DE12: 9 | DF12: =IF($CI$5=CX12,DD12,0) -> 0
F13: =IF($BD$13>0,"탁송료","") | K13: =IF($BD$13>0,$BD$13,"") | AA13: 선수금 | AG13: =$CI$31 -> 0 | AU13: (계산서포함)탁송료 | BD13: 0 | CD13: 최종할인금액 | CE13: =IF($BD$12="금액입력",$BQ$12,TRUNC(($BD$10+$BD$11)*$BK$12,-1)) -> 0 | CH13: 취득세율 | CI13: =IF($CI$12="승용",7%,IF($CI$12="승합",5%,IF($CI$12="화물",5%,7%))) -> 0.07 | CL13: 8 | CM13: =IF(CL13<$CQ$4,$CQ$28,IF(CL13=$CQ$4,$CQ$28+$CQ$24,0)) -> #N/A | CO13: 용품/서비스비용 | CP13: =$CI$84 -> 0 | CQ13: =$CP$13 -> 0 | CX13: =견적관리자용!$S$15 -> 화물(1~2.5톤 미만) | CY13: 0 | CZ13: 390000 | DA13: 390000 | DB13: 390000 | DC13: 390000 | DD13: =HLOOKUP($CI$6,$CY$4:$DC$145,DE13,TRUE) -> 0 | DE13: 10 | DF13: =IF($CI$5=CX13,DD13,0) -> 0
E14: 차량가격 | K14: =$CI$9 -> 70400000 | AA14: 인지대 | AG14: =CI80 -> 35000 | AT14: 차량가격(계산서가) | BD14: =$BD$10+$BD$11-$CE$13+$BD$13 -> 70400000 | CH14: 자동반영(1) | CI14: =ROUNDDOWN($CI$9/1.1*$CI$13,-1) -> 4480000 | CL14: 9 | CM14: =IF(CL14<$CQ$4,$CQ$28,IF(CL14=$CQ$4,$CQ$28+$CQ$24,0)) -> #N/A | CX14: =견적관리자용!$S$16 -> 화물(2.5~4.6톤 미만) | CY14: 0 | CZ14: 390000 | DA14: 390000 | DB14: 390000 | DC14: 390000 | DD14: =HLOOKUP($CI$6,$CY$4:$DC$145,DE14,TRUE) -> 0 | DE14: 11 | DF14: =IF($CI$5=CX14,DD14,0) -> 0
E15: 취득세 | K15: =$CI$21 -> 3730000 | Z15: 초기납입금 | AG15: =AG13+AG14 -> 35000 | AT15: 차량명의/등록지 | BD15: 이용자명의 | BN15: 서울 | CD15: 이용자명의 | CE15: =IF($BD$15="이용자명의",TRUE,FALSE) -> TRUE | CH15: 경차 75만초과분 부담 | CI15: =IF($CI$14<750000,0,$CI$14-750000) -> 3730000 | CL15: 10 | CM15: =IF(CL15<$CQ$4,$CQ$28,IF(CL15=$CQ$4,$CQ$28+$CQ$24,0)) -> #N/A | CO15: 이용자명의할부설정료 | CP15: =$CI$83 -> 444780 | CQ15: =IF(견적관리자용!$Q$26="반영",$CP$15,0) -> 444780 | CX15: =견적관리자용!$S$17 -> 화물(4.6톤 이상) | CY15: 0 | CZ15: 650000 | DA15: 650000 | DB15: 650000 | DC15: 650000 | DD15: =HLOOKUP($CI$6,$CY$4:$DC$145,DE15,TRUE) -> 0 | DE15: 12 | DF15: =IF($CI$5=CX15,DD15,0) -> 0
E16: 공채비용 | K16: =$CI$11 -> 0 | AE16: =IF(BD28="신차보상보험(1년)","※ 신차보상보험 1년 제공",IF(BD28="신차보상보험(3년)","※ 신차보상보험 3년 제공","")) | AT16: 공채 | BD16: 0.05 | BK16: 직접입력→ | BQ16: 0 | CH16: 자동반영 (하이브리드) | CI16: =+IF(AND(CI7="하이브리드",CI14>=400000),CI14-400000,0) -> 0 | CL16: 11 | CM16: =IF(CL16<$CQ$4,$CQ$28,IF(CL16=$CQ$4,$CQ$28+$CQ$24,0)) -> #N/A | CO16: 인지세 | CP16: =$CI$80 -> 35000 | CQ16: =IF(견적관리자용!$Q$24="반영",$CP$16,0) -> 35000 | CW16: 부산 | CX16: =견적관리자용!$S$8 -> 승용일반 | CY16: 0 | CZ16: 0 | DA16: 0 | DB16: 0 | DC16: 0.05 | DD16: =HLOOKUP($CI$6,$CY$4:$DC$145,DE16,TRUE) -> 0 | DE16: 13 | DF16: =IF($CI$5=CX16,DD16,0) -> 0 | DG16: =SUM(DF16:DF25) -> 0
E17: 기타부대비 | K17: =$BD$17 -> 0 | AT17: 기타부대비 | BD17: 0 | BN17: ≤ | BP17: =견적관리자용!$T$35 -> 0 | CH17: 자동반영 | CI17: =IF($CI$6<1000,$CI$15,IF(CI7="하이브리드",CI16,$CI$14)) -> 3730000 | CL17: 12 | CM17: =IF(CL17<$CQ$4,$CQ$28,IF(CL17=$CQ$4,$CQ$28+$CQ$24,0)) -> #N/A | CO17: MINUS | CP17: =SUM($CP$8:$CP$16) -> #N/A | CQ17: =SUM($CQ$8:$CQ$16) -> #N/A | CX17: =견적관리자용!$S$9 -> 승용SUV(~5인) | CY17: 0 | CZ17: 0 | DA17: 0 | DB17: 0 | DC17: 0 | DD17: =HLOOKUP($CI$6,$CY$4:$DC$145,DE17,TRUE) -> 0 | DE17: 14 | DF17: =IF($CI$5=CX17,DD17,0) -> 0
E18: =IF($BD$18>0,"탁송료","") | K18: =IF($BD$18>0,$BD$18,"") | AT18: 탁송료 | BD18: 0 | BN18: ≤ | BP18: =견적관리자용!$T$36 -> 500000 | CD18: 취득세 비율입력 | CE18: =IF($BD$19="비율입력",TRUE,FALSE) -> FALSE | CH18: 비율입력 | CI18: =ROUNDDOWN($CI$9/1.1*$BK$19,-1) -> 4480000 | CL18: 13 | CM18: =IF(CL18<$CQ$4,$CQ$28,IF(CL18=$CQ$4,$CQ$28+$CQ$24,0)) -> #N/A | CX18: =견적관리자용!$S$10 -> 승용SUV(7~10인) | CY18: 0 | CZ18: 0 | DA18: 0 | DB18: 0 | DC18: 0 | DD18: =HLOOKUP($CI$6,$CY$4:$DC$145,DE18,TRUE) -> 0 | DE18: 15 | DF18: =IF($CI$5=CX18,DD18,0) -> 0
D19: 총구매비용 | K19: =$CI$22 -> 74130000 | AT19: 취득세 (직접입력시만 사용) | BD19: 자동반영 | BK19: 0.07 | BQ19: 0 | BY19: - 하이브리드, 전기차, 경차 등 특례해당건 취득세 재확인 요망 | CD19: 취득세 감면액입력 | CE19: =IF($BD$19="감면액입력",TRUE,FALSE) -> FALSE | CH19: 감면액입력 | CI19: =$CI$17-$BQ$19 -> 3730000 | CL19: 14 | CM19: =IF(CL19<$CQ$4,$CQ$28,IF(CL19=$CQ$4,$CQ$28+$CQ$24,0)) -> #N/A | CX19: =견적관리자용!$S$11 -> 승합(11~15인) | CY19: 0 | CZ19: 0 | DA19: 0 | DB19: 0 | DC19: 0 | DD19: =HLOOKUP($CI$6,$CY$4:$DC$145,DE19,TRUE) -> 0 | DE19: 16 | DF19: =IF($CI$5=CX19,DD19,0) -> 0
BK20: 0 | CD20: 취득세 금액입력 | CE20: =IF($BD$19="금액입력",TRUE,FALSE) -> FALSE | CH20: 금액입력 | CI20: =$BK$20 -> 0 | CL20: 15 | CM20: =IF(CL20<$CQ$4,$CQ$28,IF(CL20=$CQ$4,$CQ$28+$CQ$24,0)) -> #N/A | CX20: =견적관리자용!$S$12 -> 화물(1000cc 미만) | CY20: 0 | CZ20: 0 | DA20: 0 | DB20: 0 | DC20: 0 | DD20: =HLOOKUP($CI$6,$CY$4:$DC$145,DE20,TRUE) -> 0 | DE20: 17 | DF20: =IF($CI$5=CX20,DD20,0) -> 0
CH21: 최종 취득세 | CI21: =VLOOKUP($BD$19,$CH$17:$CI$20,2,FALSE) -> 3730000 | CL21: 16 | CM21: =IF(CL21<$CQ$4,$CQ$28,IF(CL21=$CQ$4,$CQ$28+$CQ$24,0)) -> #N/A | CO21: 이손액 | CP21: =$CI$87 -> 0 | CQ21: =$CP$21 -> 0 | CX21: =견적관리자용!$S$13 -> 화물(0.6톤 미만) | CY21: 0 | CZ21: 0 | DA21: 0 | DB21: 0 | DC21: 0 | DD21: =HLOOKUP($CI$6,$CY$4:$DC$145,DE21,TRUE) -> 0 | DE21: 18 | DF21: =IF($CI$5=CX21,DD21,0) -> 0
